Workbook

Sheet KeyIn
B1: 挑战赛 | G1: 比赛项目：
A3: 裁判一： | G3: 选手名称 | N3: 裁判（一） | T3: 裁判（二） | Z3: 裁判（三） | AA3: 裁判平均 | AB3: 总分法名次 | AC3: 席次法名次 | AD3: 选手名称
A4: 裁判二： | G4: =A30 -> 个人评分标准 | H4: 扣分 | I4: =IF($G$4=$A$22,$A$23,$A$31) -> 动作难度 | J4: =IF($G$4=$A$22,$A$24,$A$32) -> 动作创意 | K4: =IF($G$4=$A$22,$A$25,$A$33) -> 动作流畅 | L4: =IF($G$4=$A$22,$A$26,$A$34) -> 0 | M4: =IF($G$4=$A$22,$A$27,$A$35) -> 0 | N4: 裁判总分 | O4: =I4 -> 动作难度 | P4: =J4 -> 动作创意 | Q4: =K4 -> 动作流畅 | R4: =L4 -> 0 | S4: =M4 -> 0 | T4: 裁判总分 | U4: =I4 -> 动作难度 | V4: =J4 -> 动作创意 | W4: =K4 -> 动作流畅 | X4: =L4 -> 0 | Y4: =M4 -> 0 | Z4: 裁判总分 | AA4: =SUM(IF(T6>0,1,0)+IF(N6>0,1,0)+IF(Z6>0,1,0)) -> 0
A5: 裁判三： | I5: =IF($G$4=$A$22,$B$23,$B$31) -> 0.5 | J5: =IF($G$4=$A$22,$B$24,$B$32) -> 0.3 | K5: =IF($G$4=$A$22,$B$25,$B$33) -> 0.2 | L5: =IF($G$4=$A$22,$B$26,$B$34) -> 0 | M5: =IF($G$4=$A$22,$B$27,$B$35) -> 0 | O5: =I5 -> 0.5 | P5: =J5 -> 0.3 | Q5: =K5 -> 0.2 | R5: =L5 -> 0 | S5: =M5 -> 0 | U5: =I5 -> 0.5 | V5: =J5 -> 0.3 | W5: =K5 -> 0.2 | X5: =L5 -> 0 | Y5: =M5 -> 0 | AA5: 人
E6: 1 | N6: =SUM(I6:M6)-H6 -> 0 | T6: =SUM(O6:S6)-H6 -> 0 | Z6: =SUM(U6:Y6)-H6 -> 0 | AA6: =((SUM(Z6,T6,N6))/AA$4) -> #DIV/0! | AB6: =RANK(AA6,$AA$6:$AA$55,0) -> #DIV/0! | AC6: =Calculation!DE60 -> 1 | AD6: =G6 -> 0
E7: 2 | N7: =SUM(I7:M7)-H7 -> 0 | T7: =SUM(O7:S7)-H7 -> 0 | Z7: =SUM(U7:Y7)-H7 -> 0 | AA7: =((SUM(Z7,T7,N7))/AA$4) -> #DIV/0! | AB7: =RANK(AA7,$AA$6:$AA$55,0) -> #DIV/0! | AC7: =Calculation!DE61 -> 1 | AD7: =G7 -> 0
E8: 3 | N8: =SUM(I8:M8)-H8 -> 0 | T8: =SUM(O8:S8)-H8 -> 0 | Z8: =SUM(U8:Y8)-H8 -> 0 | AA8: =((SUM(Z8,T8,N8))/AA$4) -> #DIV/0! | AB8: =RANK(AA8,$AA$6:$AA$55,0) -> #DIV/0! | AC8: =Calculation!DE62 -> 1 | AD8: =G8 -> 0
E9: 4 | N9: =SUM(I9:M9)-H9 -> 0 | T9: =SUM(O9:S9)-H9 -> 0 | Z9: =SUM(U9:Y9)-H9 -> 0 | AA9: =((SUM(Z9,T9,N9))/AA$4) -> #DIV/0! | AB9: =RANK(AA9,$AA$6:$AA$55,0) -> #DIV/0! | AC9: =Calculation!DE63 -> 1 | AD9: =G9 -> 0
E10: 5 | N10: =SUM(I10:M10)-H10 -> 0 | T10: =SUM(O10:S10)-H10 -> 0 | Z10: =SUM(U10:Y10)-H10 -> 0 | AA10: =((SUM(Z10,T10,N10))/AA$4) -> #DIV/0! | AB10: =RANK(AA10,$AA$6:$AA$55,0) -> #DIV/0! | AC10: =Calculation!DE64 -> 1 | AD10: =G10 -> 0
E11: 6 | N11: =SUM(I11:M11)-H11 -> 0 | T11: =SUM(O11:S11)-H11 -> 0 | Z11: =SUM(U11:Y11)-H11 -> 0 | AA11: =((SUM(Z11,T11,N11))/AA$4) -> #DIV/0! | AB11: =RANK(AA11,$AA$6:$AA$55,0) -> #DIV/0! | AC11: =Calculation!DE65 -> 1 | AD11: =G11 -> 0
E12: 7 | N12: =SUM(I12:M12)-H12 -> 0 | T12: =SUM(O12:S12)-H12 -> 0 | Z12: =SUM(U12:Y12)-H12 -> 0 | AA12: =((SUM(Z12,T12,N12))/AA$4) -> #DIV/0! | AB12: =RANK(AA12,$AA$6:$AA$55,0) -> #DIV/0! | AC12: =Calculation!DE66 -> 1 | AD12: =G12 -> 0
E13: 8 | N13: =SUM(I13:M13)-H13 -> 0 | T13: =SUM(O13:S13)-H13 -> 0 | Z13: =SUM(U13:Y13)-H13 -> 0 | AA13: =((SUM(Z13,T13,N13))/AA$4) -> #DIV/0! | AB13: =RANK(AA13,$AA$6:$AA$55,0) -> #DIV/0! | AC13: =Calculation!DE67 -> 1 | AD13: =G13 -> 0
E14: 9 | N14: =SUM(I14:M14)-H14 -> 0 | T14: =SUM(O14:S14)-H14 -> 0 | Z14: =SUM(U14:Y14)-H14 -> 0 | AA14: =((SUM(Z14,T14,N14))/AA$4) -> #DIV/0! | AB14: =RANK(AA14,$AA$6:$AA$55,0) -> #DIV/0! | AC14: =Calculation!DE68 -> 1 | AD14: =G14 -> 0
E15: 10 | N15: =SUM(I15:M15)-H15 -> 0 | T15: =SUM(O15:S15)-H15 -> 0 | Z15: =SUM(U15:Y15)-H15 -> 0 | AA15: =((SUM(Z15,T15,N15))/AA$4) -> #DIV/0! | AB15: =RANK(AA15,$AA$6:$AA$55,0) -> #DIV/0! | AC15: =Calculation!DE69 -> 1 | AD15: =G15 -> 0
E16: 11 | N16: =SUM(I16:M16)-H16 -> 0 | T16: =SUM(O16:S16)-H16 -> 0 | Z16: =SUM(U16:Y16)-H16 -> 0 | AA16: =((SUM(Z16,T16,N16))/AA$4) -> #DIV/0! | AB16: =RANK(AA16,$AA$6:$AA$55,0) -> #DIV/0! | AC16: =Calculation!DE70 -> 1 | AD16: =G16 -> 0
E17: 12 | N17: =SUM(I17:M17)-H17 -> 0 | T17: =SUM(O17:S17)-H17 -> 0 | Z17: =SUM(U17:Y17)-H17 -> 0 | AA17: =((SUM(Z17,T17,N17))/AA$4) -> #DIV/0! | AB17: =RANK(AA17,$AA$6:$AA$55,0) -> #DIV/0! | AC17: =Calculation!DE71 -> 1 | AD17: =G17 -> 0
... E21: 16 | N21: =SUM(I21:M21)-H21 -> 0 | T21: =SUM(O21:S21)-H21 -> 0 | Z21: =SUM(U21:Y21)-H21 -> 0 | AA21: =((SUM(Z21,T21,N21))/AA$4) -> #DIV/0! | AB21: =RANK(AA21,$AA$6:$AA$55,0) -> #DIV/0! | AC21: =Calculation!DE75 -> 1 | AD21: =G21 -> 0
A22: 团体评分标准 | E22: 17 | N22: =SUM(I22:M22)-H22 -> 0 | T22: =SUM(O22:S22)-H22 -> 0 | Z22: =SUM(U22:Y22)-H22 -> 0 | AA22: =((SUM(Z22,T22,N22))/AA$4) -> #DIV/0! | AB22: =RANK(AA22,$AA$6:$AA$55,0) -> #DIV/0! | AC22: =Calculation!DE76 -> 1 | AD22: =G22 -> 0
A23: 动作难度 | B23: 0.4 | E23: 18 | N23: =SUM(I23:M23)-H23 -> 0 | T23: =SUM(O23:S23)-H23 -> 0 | Z23: =SUM(U23:Y23)-H23 -> 0 | AA23: =((SUM(Z23,T23,N23))/AA$4) -> #DIV/0! | AB23: =RANK(AA23,$AA$6:$AA$55,0) -> #DIV/0! | AC23: =Calculation!DE77 -> 1 | AD23: =G23 -> 0
A24: 舞台艺术 | B24: 0.2 | E24: 19 | N24: =SUM(I24:M24)-H24 -> 0 | T24: =SUM(O24:S24)-H24 -> 0 | Z24: =SUM(U24:Y24)-H24 -> 0 | AA24: =((SUM(Z24,T24,N24))/AA$4) -> #DIV/0! | AB24: =RANK(AA24,$AA$6:$AA$55,0) -> #DIV/0! | AC24: =Calculation!DE78 -> 1 | AD24: =G24 -> 0
A25: 动作创意 | B25: 0.2 | E25: 20 | N25: =SUM(I25:M25)-H25 -> 0 | T25: =SUM(O25:S25)-H25 -> 0 | Z25: =SUM(U25:Y25)-H25 -> 0 | AA25: =((SUM(Z25,T25,N25))/AA$4) -> #DIV/0! | AB25: =RANK(AA25,$AA$6:$AA$55,0) -> #DIV/0! | AC25: =Calculation!DE79 -> 1 | AD25: =G25 -> 0
A26: 团体互动 | B26: 0.1 | E26: 21 | N26: =SUM(I26:M26)-H26 -> 0 | T26: =SUM(O26:S26)-H26 -> 0 | Z26: =SUM(U26:Y26)-H26 -> 0 | AA26: =((SUM(Z26,T26,N26))/AA$4) -> #DIV/0! | AB26: =RANK(AA26,$AA$6:$AA$55,0) -> #DIV/0! | AC26: =Calculation!DE80 -> 1 | AD26: =G26 -> 0
A27: 服装造型 | B27: 0.1 | E27: 22 | N27: =SUM(I27:M27)-H27 -> 0 | T27: =SUM(O27:S27)-H27 -> 0 | Z27: =SUM(U27:Y27)-H27 -> 0 | AA27: =((SUM(Z27,T27,N27))/AA$4) -> #DIV/0! | AB27: =RANK(AA27,$AA$6:$AA$55,0) -> #DIV/0! | AC27: =Calculation!DE81 -> 1 | AD27: =G27 -> 0
A28: （失误1次扣1分） | E28: 23 | N28: =SUM(I28:M28)-H28 -> 0 | T28: =SUM(O28:S28)-H28 -> 0 | Z28: =SUM(U28:Y28)-H28 -> 0 | AA28: =((SUM(Z28,T28,N28))/AA$4) -> #DIV/0! | AB28: =RANK(AA28,$AA$6:$AA$55,0) -> #DIV/0! | AC28: =Calculation!DE82 -> 1 | AD28: =G28 -> 0
E29: 24 | N29: =SUM(I29:M29)-H29 -> 0 | T29: =SUM(O29:S29)-H29 -> 0 | Z29: =SUM(U29:Y29)-H29 -> 0 | AA29: =((SUM(Z29,T29,N29))/AA$4) -> #DIV/0! | AB29: =RANK(AA29,$AA$6:$AA$55,0) -> #DIV/0! | AC29: =Calculation!DE83 -> 1 | AD29: =G29 -> 0
A30: 个人评分标准 | E30: 25 | N30: =SUM(I30:M30)-H30 -> 0 | T30: =SUM(O30:S30)-H30 -> 0 | Z30: =SUM(U30:Y30)-H30 -> 0 | AA30: =((SUM(Z30,T30,N30))/AA$4) -> #DIV/0! | AB30: =RANK(AA30,$AA$6:$AA$55,0) -> #DIV/0! | AC30: =Calculation!DE84 -> 1 | AD30: =G30 -> 0
A31: 动作难度 | B31: 0.5 | E31: 26 | N31: =SUM(I31:M31)-H31 -> 0 | T31: =SUM(O31:S31)-H31 -> 0 | Z31: =SUM(U31:Y31)-H31 -> 0 | AA31: =((SUM(Z31,T31,N31))/AA$4) -> #DIV/0! | AB31: =RANK(AA31,$AA$6:$AA$55,0) -> #DIV/0! | AC31: =Calculation!DE85 -> 1 | AD31: =G31 -> 0
A32: 动作创意 | B32: 0.3 | E32: 27 | N32: =SUM(I32:M32)-H32 -> 0 | T32: =SUM(O32:S32)-H32 -> 0 | Z32: =SUM(U32:Y32)-H32 -> 0 | AA32: =((SUM(Z32,T32,N32))/AA$4) -> #DIV/0! | AB32: =RANK(AA32,$AA$6:$AA$55,0) -> #DIV/0! | AC32: =Calculation!DE86 -> 1 | AD32: =G32 -> 0
A33: 动作流畅 | B33: 0.2 | E33: 28 | N33: =SUM(I33:M33)-H33 -> 0 | T33: =SUM(O33:S33)-H33 -> 0 | Z33: =SUM(U33:Y33)-H33 -> 0 | AA33: =((SUM(Z33,T33,N33))/AA$4) -> #DIV/0! | AB33: =RANK(AA33,$AA$6:$AA$55,0) -> #DIV/0! | AC33: =Calculation!DE87 -> 1 | AD33: =G33 -> 0
E34: 29 | N34: =SUM(I34:M34)-H34 -> 0 | T34: =SUM(O34:S34)-H34 -> 0 | Z34: =SUM(U34:Y34)-H34 -> 0 | AA34: =((SUM(Z34,T34,N34))/AA$4) -> #DIV/0! | AB34: =RANK(AA34,$AA$6:$AA$55,0) -> #DIV/0! | AC34: =Calculation!DE88 -> 1 | AD34: =G34 -> 0
E35: 30 | N35: =SUM(I35:M35)-H35 -> 0 | T35: =SUM(O35:S35)-H35 -> 0 | Z35: =SUM(U35:Y35)-H35 -> 0 | AA35: =((SUM(Z35,T35,N35))/AA$4) -> #DIV/0! | AB35: =RANK(AA35,$AA$6:$AA$55,0) -> #DIV/0! | AC35: =Calculation!DE89 -> 1 | AD35: =G35 -> 0
A36: （失误1次扣2分） | E36: 31 | N36: =SUM(I36:M36)-H36 -> 0 | T36: =SUM(O36:S36)-H36 -> 0 | Z36: =SUM(U36:Y36)-H36 -> 0 | AA36: =((SUM(Z36,T36,N36))/AA$4) -> #DIV/0! | AB36: =RANK(AA36,$AA$6:$AA$55,0) -> #DIV/0! | AC36: =Calculation!DE90 -> 1 | AD36: =G36 -> 0
E37: 32 | N37: =SUM(I37:M37)-H37 -> 0 | T37: =SUM(O37:S37)-H37 -> 0 | Z37: =SUM(U37:Y37)-H37 -> 0 | AA37: =((SUM(Z37,T37,N37))/AA$4) -> #DIV/0! | AB37: =RANK(AA37,$AA$6:$AA$55,0) -> #DIV/0! | AC37: =Calculation!DE91 -> 1 | AD37: =G37 -> 0
E38: 33 | N38: =SUM(I38:M38)-H38 -> 0 | T38: =SUM(O38:S38)-H38 -> 0 | Z38: =SUM(U38:Y38)-H38 -> 0 | AA38: =((SUM(Z38,T38,N38))/AA$4) -> #DIV/0! | AB38: =RANK(AA38,$AA$6:$AA$55,0) -> #DIV/0! | AC38: =Calculation!DE92 -> 1 | AD38: =G38 -> 0
E39: 34 | N39: =SUM(I39:M39)-H39 -> 0 | T39: =SUM(O39:S39)-H39 -> 0 | Z39: =SUM(U39:Y39)-H39 -> 0 | AA39: =((SUM(Z39,T39,N39))/AA$4) -> #DIV/0! | AB39: =RANK(AA39,$AA$6:$AA$55,0) -> #DIV/0! | AC39: =Calculation!DE93 -> 1 | AD39: =G39 -> 0
E40: 35 | N40: =SUM(I40:M40)-H40 -> 0 | T40: =SUM(O40:S40)-H40 -> 0 | Z40: =SUM(U40:Y40)-H40 -> 0 | AA40: =((SUM(Z40,T40,N40))/AA$4) -> #DIV/0! | AB40: =RANK(AA40,$AA$6:$AA$55,0) -> #DIV/0! | AC40: =Calculation!DE94 -> 1 | AD40: =G40 -> 0
E41: 36 | N41: =SUM(I41:M41)-H41 -> 0 | T41: =SUM(O41:S41)-H41 -> 0 | Z41: =SUM(U41:Y41)-H41 -> 0 | AA41: =((SUM(Z41,T41,N41))/AA$4) -> #DIV/0! | AB41: =RANK(AA41,$AA$6:$AA$55,0) -> #DIV/0! | AC41: =Calculation!DE95 -> 1 | AD41: =G41 -> 0
E42: 37 | N42: =SUM(I42:M42)-H42 -> 0 | T42: =SUM(O42:S42)-H42 -> 0 | Z42: =SUM(U42:Y42)-H42 -> 0 | AA42: =((SUM(Z42,T42,N42))/AA$4) -> #DIV/0! | AB42: =RANK(AA42,$AA$6:$AA$55,0) -> #DIV/0! | AC42: =Calculation!DE96 -> 1 | AD42: =G42 -> 0
E43: 38 | N43: =SUM(I43:M43)-H43 -> 0 | T43: =SUM(O43:S43)-H43 -> 0 | Z43: =SUM(U43:Y43)-H43 -> 0 | AA43: =((SUM(Z43,T43,N43))/AA$4) -> #DIV/0! | AB43: =RANK(AA43,$AA$6:$AA$55,0) -> #DIV/0! | AC43: =Calculation!DE97 -> 1 | AD43: =G43 -> 0
E44: 39 | N44: =SUM(I44:M44)-H44 -> 0 | T44: =SUM(O44:S44)-H44 -> 0 | Z44: =SUM(U44:Y44)-H44 -> 0 | AA44: =((SUM(Z44,T44,N44))/AA$4) -> #DIV/0! | AB44: =RANK(AA44,$AA$6:$AA$55,0) -> #DIV/0! | AC44: =Calculation!DE98 -> 1 | AD44: =G44 -> 0
...

Sheet Calculation
A1: =KeyIn!N6 -> 0 | B1: =KeyIn!T6 -> 0 | C1: =KeyIn!Z6 -> 0 | D1: 0 | E1: 0 | F1: 0 | G1: 0
A2: =KeyIn!N7 -> 0 | B2: =KeyIn!T7 -> 0 | C2: =KeyIn!Z7 -> 0 | D2: 0 | E2: 0 | F2: 0 | G2: 0 | I2: =IF($A$1=A2,0.5,IF($A$1>A2,1,0)) -> 0.5 | J2: =IF($B$1=B2,0.5,IF($B$1>B2,1,0)) -> 0.5 | K2: =IF($C$1=C2,0.5,IF($C$1>C2,1,0)) -> 0.5 | L2: =IF($D$1=D2,0.5,IF($D$1>D2,1,0)) -> 0.5 | M2: =IF($E$1=E2,0.5,IF($E$1>E2,1,0)) -> 0.5 | N2: =IF($F$1=F2,0.5,IF($F$1>F2,1,0)) -> 0.5 | O2: =IF($G$1=G2,0.5,IF($G$1>G2,1,0)) -> 0.5 | P2: =SUM(I2:O2) -> 3.5 | Q2: =IF(P2=3.5,0.5,IF(P2>3.5,1,0)) -> 0.5
A3: =KeyIn!N8 -> 0 | B3: =KeyIn!T8 -> 0 | C3: =KeyIn!Z8 -> 0 | D3: 0 | E3: 0 | F3: 0 | G3: 0 | I3: =IF($A$1=A3,0.5,IF($A$1>A3,1,0)) -> 0.5 | J3: =IF($B$1=B3,0.5,IF($B$1>B3,1,0)) -> 0.5 | K3: =IF($C$1=C3,0.5,IF($C$1>C3,1,0)) -> 0.5 | L3: =IF($D$1=D3,0.5,IF($D$1>D3,1,0)) -> 0.5 | M3: =IF($E$1=E3,0.5,IF($E$1>E3,1,0)) -> 0.5 | N3: =IF($F$1=F3,0.5,IF($F$1>F3,1,0)) -> 0.5 | O3: =IF($G$1=G3,0.5,IF($G$1>G3,1,0)) -> 0.5 | P3: =SUM(I3:O3) -> 3.5 | Q3: =IF(P3=3.5,0.5,IF(P3>3.5,1,0)) -> 0.5 | S3: =IF(A2=A3,0.5,IF(A2>A3,1,0)) -> 0.5 | T3: =IF($B$2=B3,0.5,IF($B$2>B3,1,0)) -> 0.5 | U3: =IF($C$2=C3,0.5,IF($C$2>C3,1,0)) -> 0.5 | V3: =IF($D$2=D3,0.5,IF($D$2>D3,1,0)) -> 0.5 | W3: =IF($E$2=E3,0.5,IF($E$2>E3,1,0)) -> 0.5 | X3: =IF($F$2=F3,0.5,IF($F$2>F3,1,0)) -> 0.5 | Y3: =IF($G$2=G3,0.5,IF($G$2>G3,1,0)) -> 0.5 | Z3: =SUM(S3:Y3) -> 3.5 | AA3: =IF(Z3=3.5,0.5,IF(Z3>3.5,1,0)) -> 0.5
A4: =KeyIn!N9 -> 0 | B4: =KeyIn!T9 -> 0 | C4: =KeyIn!Z9 -> 0 | D4: 0 | E4: 0 | F4: 0 | G4: 0 | I4: =IF($A$1=A4,0.5,IF($A$1>A4,1,0)) -> 0.5 | J4: =IF($B$1=B4,0.5,IF($B$1>B4,1,0)) -> 0.5 | K4: =IF($C$1=C4,0.5,IF($C$1>C4,1,0)) -> 0.5 | L4: =IF($D$1=D4,0.5,IF($D$1>D4,1,0)) -> 0.5 | M4: =IF($E$1=E4,0.5,IF($E$1>E4,1,0)) -> 0.5 | N4: =IF($F$1=F4,0.5,IF($F$1>F4,1,0)) -> 0.5 | O4: =IF($G$1=G4,0.5,IF($G$1>G4,1,0)) -> 0.5 | P4: =SUM(I4:O4) -> 3.5 | Q4: =IF(P4=3.5,0.5,IF(P4>3.5,1,0)) -> 0.5 | S4: =IF($A$2=A4,0.5,IF($A$2>A4,1,0)) -> 0.5 | T4: =IF($B$2=B4,0.5,IF($B$2>B4,1,0)) -> 0.5 | U4: =IF($C$2=C4,0.5,IF($C$2>C4,1,0)) -> 0.5 | V4: =IF($D$2=D4,0.5,IF($D$2>D4,1,0)) -> 0.5 | W4: =IF($E$2=E4,0.5,IF($E$2>E4,1,0)) -> 0.5 | X4: =IF($F$2=F4,0.5,IF($F$2>F4,1,0)) -> 0.5 | Y4: =IF($G$2=G4,0.5,IF($G$2>G4,1,0)) -> 0.5 | Z4: =SUM(S4:Y4) -> 3.5 | AA4: =IF(Z4=3.5,0.5,IF(Z4>3.5,1,0)) -> 0.5 | AC4: =IF(A3=A4,0.5,IF(A3>A4,1,0)) -> 0.5 | AD4: =IF($B$3=B4,0.5,IF($B$3>B4,1,0)) -> 0.5 | AE4: =IF($C$3=C4,0.5,IF($C$3>C4,1,0)) -> 0.5 | AF4: =IF($D$3=D4,0.5,IF($D$3>D4,1,0)) -> 0.5 | AG4: =IF($E$3=E4,0.5,IF($E$3>E4,1,0)) -> 0.5 | AH4: =IF($F$3=F4,0.5,IF($F$3>F4,1,0)) -> 0.5 | AI4: =IF($G$3=G4,0.5,IF($G$3>G4,1,0)) -> 0.5 | AJ4: =SUM(AC4:AI4) -> 3.5 | AK4: =IF(AJ4=3.5,0.5,IF(AJ4>3.5,1,0)) -> 0.5
A5: =KeyIn!N10 -> 0 | B5: =KeyIn!T10 -> 0 | C5: =KeyIn!Z10 -> 0 | D5: 0 | E5: 0 | F5: 0 | G5: 0 | I5: =IF($A$1=A5,0.5,IF($A$1>A5,1,0)) -> 0.5 | J5: =IF($B$1=B5,0.5,IF($B$1>B5,1,0)) -> 0.5 | K5: =IF($C$1=C5,0.5,IF($C$1>C5,1,0)) -> 0.5 | L5: =IF($D$1=D5,0.5,IF($D$1>D5,1,0)) -> 0.5 | M5: =IF($E$1=E5,0.5,IF($E$1>E5,1,0)) -> 0.5 | N5: =IF($F$1=F5,0.5,IF($F$1>F5,1,0)) -> 0.5 | O5: =IF($G$1=G5,0.5,IF($G$1>G5,1,0)) -> 0.5 | P5: =SUM(I5:O5) -> 3.5 | Q5: =IF(P5=3.5,0.5,IF(P5>3.5,1,0)) -> 0.5 | S5: =IF($A$2=A5,0.5,IF($A$2>A5,1,0)) -> 0.5 | T5: =IF($B$2=B5,0.5,IF($B$2>B5,1,0)) -> 0.5 | U5: =IF($C$2=C5,0.5,IF($C$2>C5,1,0)) -> 0.5 | V5: =IF($D$2=D5,0.5,IF($D$2>D5,1,0)) -> 0.5 | W5: =IF($E$2=E5,0.5,IF($E$2>E5,1,0)) -> 0.5 | X5: =IF($F$2=F5,0.5,IF($F$2>F5,1,0)) -> 0.5 | Y5: =IF($G$2=G5,0.5,IF($G$2>G5,1,0)) -> 0.5 | Z5: =SUM(S5:Y5) -> 3.5 | AA5: =IF(Z5=3.5,0.5,IF(Z5>3.5,1,0)) -> 0.5 | AC5: =IF($A$3=A5,0.5,IF($A$3>A5,1,0)) -> 0.5 | AD5: =IF($B$3=B5,0.5,IF($B$3>B5,1,0)) -> 0.5 | AE5: =IF($C$3=C5,0.5,IF($C$3>C5,1,0)) -> 0.5 | AF5: =IF($D$3=D5,0.5,IF($D$3>D5,1,0)) -> 0.5 | AG5: =IF($E$3=E5,0.5,IF($E$3>E5,1,0)) -> 0.5 | AH5: =IF($F$3=F5,0.5,IF($F$3>F5,1,0)) -> 0.5 | AI5: =IF($G$3=G5,0.5,IF($G$3>G5,1,0)) -> 0.5 | AJ5: =SUM(AC5:AI5) -> 3.5 | AK5: =IF(AJ5=3.5,0.5,IF(AJ5>3.5,1,0)) -> 0.5 | AM5: =IF(A4=A5,0.5,IF(A4>A5,1,0)) -> 0.5 | AN5: =IF($B$4=B5,0.5,IF($B$4>B5,1,0)) -> 0.5 | AO5: =IF($C$4=C5,0.5,IF($C$4>C5,1,0)) -> 0.5 | AP5: =IF($D$4=D5,0.5,IF($D$4>D5,1,0)) -> 0.5 | AQ5: =IF($E$4=E5,0.5,IF($E$4>E5,1,0)) -> 0.5 | AR5: =IF($F$4=F5,0.5,IF($F$4>F5,1,0)) -> 0.5 | AS5: =IF($G$4=G5,0.5,IF($G$4>G5,1,0)) -> 0.5 | AT5: =SUM(AM5:AS5) -> 3.5 | AU5: =IF(AT5=3.5,0.5,IF(AT5>3.5,1,0)) -> 0.5
A6: =KeyIn!N11 -> 0 | B6: =KeyIn!T11 -> 0 | C6: =KeyIn!Z11 -> 0 | D6: 0 | E6: 0 | F6: 0 | G6: 0 | I6: =IF($A$1=A6,0.5,IF($A$1>A6,1,0)) -> 0.5 | J6: =IF($B$1=B6,0.5,IF($B$1>B6,1,0)) -> 0.5 | K6: =IF($C$1=C6,0.5,IF($C$1>C6,1,0)) -> 0.5 | L6: =IF($D$1=D6,0.5,IF($D$1>D6,1,0)) -> 0.5 | M6: =IF($E$1=E6,0.5,IF($E$1>E6,1,0)) -> 0.5 | N6: =IF($F$1=F6,0.5,IF($F$1>F6,1,0)) -> 0.5 | O6: =IF($G$1=G6,0.5,IF($G$1>G6,1,0)) -> 0.5 | P6: =SUM(I6:O6) -> 3.5 | Q6: =IF(P6=3.5,0.5,IF(P6>3.5,1,0)) -> 0.5 | S6: =IF($A$2=A6,0.5,IF($A$2>A6,1,0)) -> 0.5 | T6: =IF($B$2=B6,0.5,IF($B$2>B6,1,0)) -> 0.5 | U6: =IF($C$2=C6,0.5,IF($C$2>C6,1,0)) -> 0.5 | V6: =IF($D$2=D6,0.5,IF($D$2>D6,1,0)) -> 0.5 | W6: =IF($E$2=E6,0.5,IF($E$2>E6,1,0)) -> 0.5 | X6: =IF($F$2=F6,0.5,IF($F$2>F6,1,0)) -> 0.5 | Y6: =IF($G$2=G6,0.5,IF($G$2>G6,1,0)) -> 0.5 | Z6: =SUM(S6:Y6) -> 3.5 | AA6: =IF(Z6=3.5,0.5,IF(Z6>3.5,1,0)) -> 0.5 | AC6: =IF($A$3=A6,0.5,IF($A$3>A6,1,0)) -> 0.5 | AD6: =IF($B$3=B6,0.5,IF($B$3>B6,1,0)) -> 0.5 | AE6: =IF($C$3=C6,0.5,IF($C$3>C6,1,0)) -> 0.5 | AF6: =IF($D$3=D6,0.5,IF($D$3>D6,1,0)) -> 0.5 | AG6: =IF($E$3=E6,0.5,IF($E$3>E6,1,0)) -> 0.5 | AH6: =IF($F$3=F6,0.5,IF($F$3>F6,1,0)) -> 0.5 | AI6: =IF($G$3=G6,0.5,IF($G$3>G6,1,0)) -> 0.5 | AJ6: =SUM(AC6:AI6) -> 3.5 | AK6: =IF(AJ6=3.5,0.5,IF(AJ6>3.5,1,0)) -> 0.5 | AM6: =IF($A$4=A6,0.5,IF($A$4>A6,1,0)) -> 0.5 | AN6: =IF($B$4=B6,0.5,IF($B$4>B6,1,0)) -> 0.5 | AO6: =IF($C$4=C6,0.5,IF($C$4>C6,1,0)) -> 0.5 | AP6: =IF($D$4=D6,0.5,IF($D$4>D6,1,0)) -> 0.5 | AQ6: =IF($E$4=E6,0.5,IF($E$4>E6,1,0)) -> 0.5 | AR6: =IF($F$4=F6,0.5,IF($F$4>F6,1,0)) -> 0.5 | AS6: =IF($G$4=G6,0.5,IF($G$4>G6,1,0)) -> 0.5 | AT6: =SUM(AM6:AS6) -> 3.5 | AU6: =IF(AT6=3.5,0.5,IF(AT6>3.5,1,0)) -> 0.5 | AW6: =IF(A5=A6,0.5,IF(A5>A6,1,0)) -> 0.5 | AX6: =IF($B$5=B6,0.5,IF($B$5>B6,1,0)) -> 0.5 | AY6: =IF($C$5=C6,0.5,IF($C$5>C6,1,0)) -> 0.5 | AZ6: =IF($D$5=D6,0.5,IF($D$5>D6,1,0)) -> 0.5 | BA6: =IF($E$5=E6,0.5,IF($E$5>E6,1,0)) -> 0.5 | BB6: =IF($F$5=F6,0.5,IF($F$5>F6,1,0)) -> 0.5 | BC6: =IF($G$5=G6,0.5,IF($G$5>G6,1,0)) -> 0.5 | BD6: =SUM(AW6:BC6) -> 3.5 | BE6: =IF(BD6=3.5,0.5,IF(BD6>3.5,1,0)) -> 0.5
A7: =KeyIn!N12 -> 0 | B7: =KeyIn!T12 -> 0 | C7: =KeyIn!Z12 -> 0 | D7: 0 | E7: 0 | F7: 0 | G7: 0 | I7: =IF($A$1=A7,0.5,IF($A$1>A7,1,0)) -> 0.5 | J7: =IF($B$1=B7,0.5,IF($B$1>B7,1,0)) -> 0.5 | K7: =IF($C$1=C7,0.5,IF($C$1>C7,1,0)) -> 0.5 | L7: =IF($D$1=D7,0.5,IF($D$1>D7,1,0)) -> 0.5 | M7: =IF($E$1=E7,0.5,IF($E$1>E7,1,0)) -> 0.5 | N7: =IF($F$1=F7,0.5,IF($F$1>F7,1,0)) -> 0.5 | O7: =IF($G$1=G7,0.5,IF($G$1>G7,1,0)) -> 0.5 | P7: =SUM(I7:O7) -> 3.5 | Q7: =IF(P7=3.5,0.5,IF(P7>3.5,1,0)) -> 0.5 | S7: =IF($A$2=A7,0.5,IF($A$2>A7,1,0)) -> 0.5 | T7: =IF($B$2=B7,0.5,IF($B$2>B7,1,0)) -> 0.5 | U7: =IF($C$2=C7,0.5,IF($C$2>C7,1,0)) -> 0.5 | V7: =IF($D$2=D7,0.5,IF($D$2>D7,1,0)) -> 0.5 | W7: =IF($E$2=E7,0.5,IF($E$2>E7,1,0)) -> 0.5 | X7: =IF($F$2=F7,0.5,IF($F$2>F7,1,0)) -> 0.5 | Y7: =IF($G$2=G7,0.5,IF($G$2>G7,1,0)) -> 0.5 | Z7: =SUM(S7:Y7) -> 3.5 | AA7: =IF(Z7=3.5,0.5,IF(Z7>3.5,1,0)) -> 0.5 | AC7: =IF($A$3=A7,0.5,IF($A$3>A7,1,0)) -> 0.5 | AD7: =IF($B$3=B7,0.5,IF($B$3>B7,1,0)) -> 0.5 | AE7: =IF($C$3=C7,0.5,IF($C$3>C7,1,0)) -> 0.5 | AF7: =IF($D$3=D7,0.5,IF($D$3>D7,1,0)) -> 0.5 | AG7: =IF($E$3=E7,0.5,IF($E$3>E7,1,0)) -> 0.5 | AH7: =IF($F$3=F7,0.5,IF($F$3>F7,1,0)) -> 0.5 | AI7: =IF($G$3=G7,0.5,IF($G$3>G7,1,0)) -> 0.5 | AJ7: =SUM(AC7:AI7) -> 3.5 | AK7: =IF(AJ7=3.5,0.5,IF(AJ7>3.5,1,0)) -> 0.5 | AM7: =IF($A$4=A7,0.5,IF($A$4>A7,1,0)) -> 0.5 | AN7: =IF($B$4=B7,0.5,IF($B$4>B7,1,0)) -> 0.5 | AO7: =IF($C$4=C7,0.5,IF($C$4>C7,1,0)) -> 0.5 | AP7: =IF($D$4=D7,0.5,IF($D$4>D7,1,0)) -> 0.5 | AQ7: =IF($E$4=E7,0.5,IF($E$4>E7,1,0)) -> 0.5 | AR7: =IF($F$4=F7,0.5,IF($F$4>F7,1,0)) -> 0.5 | AS7: =IF($G$4=G7,0.5,IF($G$4>G7,1,0)) -> 0.5 | AT7: =SUM(AM7:AS7) -> 3.5 | AU7: =IF(AT7=3.5,0.5,IF(AT7>3.5,1,0)) -> 0.5 | AW7: =IF($A$5=A7,0.5,IF($A$5>A7,1,0)) -> 0.5 | AX7: =IF($B$5=B7,0.5,IF($B$5>B7,1,0)) -> 0.5 | AY7: =IF($C$5=C7,0.5,IF($C$5>C7,1,0)) -> 0.5 | AZ7: =IF($D$5=D7,0.5,IF($D$5>D7,1,0)) -> 0.5 | BA7: =IF($E$5=E7,0.5,IF($E$5>E7,1,0)) -> 0.5 | BB7: =IF($F$5=F7,0.5,IF($F$5>F7,1,0)) -> 0.5 | BC7: =IF($G$5=G7,0.5,IF($G$5>G7,1,0)) -> 0.5 | BD7: =SUM(AW7:BC7) -> 3.5 | BE7: =IF(BD7=3.5,0.5,IF(BD7>3.5,1,0)) -> 0.5 | BG7: =IF($A$6=A7,0.5,IF($A$6>A7,1,0)) -> 0.5 | BH7: =IF($B$6=B7,0.5,IF($B$6>B7,1,0)) -> 0.5 | BI7: =IF($C$6=C7,0.5,IF($C$6>C7,1,0)) -> 0.5 | BJ7: =IF($D$6=D7,0.5,IF($D$6>D7,1,0)) -> 0.5 | BK7: =IF($E$6=E7,0.5,IF($E$6>E7,1,0)) -> 0.5 | BL7: =IF($F$6=F7,0.5,IF($F$6>F7,1,0)) -> 0.5 | BM7: =IF($G$6=G7,0.5,IF($G$6>G7,1,0)) -> 0.5 | BN7: =SUM(BG7:BM7) -> 3.5 | BO7: =IF(BN7=3.5,0.5,IF(BN7>3.5,1,0)) -> 0.5
A8: =KeyIn!N13 -> 0 | B8: =KeyIn!T13 -> 0 | C8: =KeyIn!Z13 -> 0 | D8: 0 | E8: 0 | F8: 0 | G8: 0 | I8: =IF($A$1=A8,0.5,IF($A$1>A8,1,0)) -> 0.5 | J8: =IF($B$1=B8,0.5,IF($B$1>B8,1,0)) -> 0.5 | K8: =IF($C$1=C8,0.5,IF($C$1>C8,1,0)) -> 0.5 | L8: =IF($D$1=D8,0.5,IF($D$1>D8,1,0)) -> 0.5 | M8: =IF($E$1=E8,0.5,IF($E$1>E8,1,0)) -> 0.5 | N8: =IF($F$1=F8,0.5,IF($F$1>F8,1,0)) -> 0.5 | O8: =IF($G$1=G8,0.5,IF($G$1>G8,1,0)) -> 0.5 | P8: =SUM(I8:O8) -> 3.5 | Q8: =IF(P8=3.5,0.5,IF(P8>3.5,1,0)) -> 0.5 | S8: =IF($A$2=A8,0.5,IF($A$2>A8,1,0)) -> 0.5 | T8: =IF($B$2=B8,0.5,IF($B$2>B8,1,0)) -> 0.5 | U8: =IF($C$2=C8,0.5,IF($C$2>C8,1,0)) -> 0.5 | V8: =IF($D$2=D8,0.5,IF($D$2>D8,1,0)) -> 0.5 | W8: =IF($E$2=E8,0.5,IF($E$2>E8,1,0)) -> 0.5 | X8: =IF($F$2=F8,0.5,IF($F$2>F8,1,0)) -> 0.5 | Y8: =IF($G$2=G8,0.5,IF($G$2>G8,1,0)) -> 0.5 | Z8: =SUM(S8:Y8) -> 3.5 | AA8: =IF(Z8=3.5,0.5,IF(Z8>3.5,1,0)) -> 0.5 | AC8: =IF($A$3=A8,0.5,IF($A$3>A8,1,0)) -> 0.5 | AD8: =IF($B$3=B8,0.5,IF($B$3>B8,1,0)) -> 0.5 | AE8: =IF($C$3=C8,0.5,IF($C$3>C8,1,0)) -> 0.5 | AF8: =IF($D$3=D8,0.5,IF($D$3>D8,1,0)) -> 0.5 | AG8: =IF($E$3=E8,0.5,IF($E$3>E8,1,0)) -> 0.5 | AH8: =IF($F$3=F8,0.5,IF($F$3>F8,1,0)) -> 0.5 | AI8: =IF($G$3=G8,0.5,IF($G$3>G8,1,0)) -> 0.5 | AJ8: =SUM(AC8:AI8) -> 3.5 | AK8: =IF(AJ8=3.5,0.5,IF(AJ8>3.5,1,0)) -> 0.5 | AM8: =IF($A$4=A8,0.5,IF($A$4>A8,1,0)) -> 0.5 | AN8: =IF($B$4=B8,0.5,IF($B$4>B8,1,0)) -> 0.5 | AO8: =IF($C$4=C8,0.5,IF($C$4>C8,1,0)) -> 0.5 | AP8: =IF($D$4=D8,0.5,IF($D$4>D8,1,0)) -> 0.5 | AQ8: =IF($E$4=E8,0.5,IF($E$4>E8,1,0)) -> 0.5 | AR8: =IF($F$4=F8,0.5,IF($F$4>F8,1,0)) -> 0.5 | AS8: =IF($G$4=G8,0.5,IF($G$4>G8,1,0)) -> 0.5 | AT8: =SUM(AM8:AS8) -> 3.5 | AU8: =IF(AT8=3.5,0.5,IF(AT8>3.5,1,0)) -> 0.5 | AW8: =IF($A$5=A8,0.5,IF($A$5>A8,1,0)) -> 0.5 | AX8: =IF($B$5=B8,0.5,IF($B$5>B8,1,0)) -> 0.5 | AY8: =IF($C$5=C8,0.5,IF($C$5>C8,1,0)) -> 0.5 | AZ8: =IF($D$5=D8,0.5,IF($D$5>D8,1,0)) -> 0.5 | BA8: =IF($E$5=E8,0.5,IF($E$5>E8,1,0)) -> 0.5 | BB8: =IF($F$5=F8,0.5,IF($F$5>F8,1,0)) -> 0.5 | BC8: =IF($G$5=G8,0.5,IF($G$5>G8,1,0)) -> 0.5 | BD8: =SUM(AW8:BC8) -> 3.5 | BE8: =IF(BD8=3.5,0.5,IF(BD8>3.5,1,0)) -> 0.5 | BG8: =IF($A$6=A8,0.5,IF($A$6>A8,1,0)) -> 0.5 | BH8: =IF($B$6=B8,0.5,IF($B$6>B8,1,0)) -> 0.5 | BI8: =IF($C$6=C8,0.5,IF($C$6>C8,1,0)) -> 0.5 | BJ8: =IF($D$6=D8,0.5,IF($D$6>D8,1,0)) -> 0.5 | BK8: =IF($E$6=E8,0.5,IF($E$6>E8,1,0)) -> 0.5 | BL8: =IF($F$6=F8,0.5,IF($F$6>F8,1,0)) -> 0.5 | BM8: =IF($G$6=G8,0.5,IF($G$6>G8,1,0)) -> 0.5 | BN8: =SUM(BG8:BM8) -> 3.5 | BO8: =IF(BN8=3.5,0.5,IF(BN8>3.5,1,0)) -> 0.5 | BQ8: =IF($A$7=A8,0.5,IF($A$7>A8,1,0)) -> 0.5 | BR8: =IF($B$7=B8,0.5,IF($B$7>B8,1,0)) -> 0.5 | BS8: =IF($C$7=C8,0.5,IF($C$7>C8,1,0)) -> 0.5 | BT8: =IF($D$7=D8,0.5,IF($D$7>D8,1,0)) -> 0.5 | BU8: =IF($E$7=E8,0.5,IF($E$7>E8,1,0)) -> 0.5 | BV8: =IF($F$7=F8,0.5,IF($F$7>F8,1,0)) -> 0.5 | BW8: =IF($G$7=G8,0.5,IF($G$7>G8,1,0)) -> 0.5 | BX8: =SUM(BQ8:BW8) -> 3.5 | BY8: =IF(BX8=3.5,0.5,IF(BX8>3.5,1,0)) -> 0.5
A9: =KeyIn!N14 -> 0 | B9: =KeyIn!T14 -> 0 | C9: =KeyIn!Z14 -> 0 | D9: 0 | E9: 0 | F9: 0 | G9: 0 | I9: =IF($A$1=A9,0.5,IF($A$1>A9,1,0)) -> 0.5 | J9: =IF($B$1=B9,0.5,IF($B$1>B9,1,0)) -> 0.5 | K9: =IF($C$1=C9,0.5,IF($C$1>C9,1,0)) -> 0.5 | L9: =IF($D$1=D9,0.5,IF($D$1>D9,1,0)) -> 0.5 | M9: =IF($E$1=E9,0.5,IF($E$1>E9,1,0)) -> 0.5 | N9: =IF($F$1=F9,0.5,IF($F$1>F9,1,0)) -> 0.5 | O9: =IF($G$1=G9,0.5,IF($G$1>G9,1,0)) -> 0.5 | P9: =SUM(I9:O9) -> 3.5 | Q9: =IF(P9=3.5,0.5,IF(P9>3.5,1,0)) -> 0.5 | S9: =IF($A$2=A9,0.5,IF($A$2>A9,1,0)) -> 0.5 | T9: =IF($B$2=B9,0.5,IF($B$2>B9,1,0)) -> 0.5 | U9: =IF($C$2=C9,0.5,IF($C$2>C9,1,0)) -> 0.5 | V9: =IF($D$2=D9,0.5,IF($D$2>D9,1,0)) -> 0.5 | W9: =IF($E$2=E9,0.5,IF($E$2>E9,1,0)) -> 0.5 | X9: =IF($F$2=F9,0.5,IF($F$2>F9,1,0)) -> 0.5 | Y9: =IF($G$2=G9,0.5,IF($G$2>G9,1,0)) -> 0.5 | Z9: =SUM(S9:Y9) -> 3.5 | AA9: =IF(Z9=3.5,0.5,IF(Z9>3.5,1,0)) -> 0.5 | AC9: =IF($A$3=A9,0.5,IF($A$3>A9,1,0)) -> 0.5 | AD9: =IF($B$3=B9,0.5,IF($B$3>B9,1,0)) -> 0.5 | AE9: =IF($C$3=C9,0.5,IF($C$3>C9,1,0)) -> 0.5 | AF9: =IF($D$3=D9,0.5,IF($D$3>D9,1,0)) -> 0.5 | AG9: =IF($E$3=E9,0.5,IF($E$3>E9,1,0)) -> 0.5 | AH9: =IF($F$3=F9,0.5,IF($F$3>F9,1,0)) -> 0.5 | AI9: =IF($G$3=G9,0.5,IF($G$3>G9,1,0)) -> 0.5 | AJ9: =SUM(AC9:AI9) -> 3.5 | AK9: =IF(AJ9=3.5,0.5,IF(AJ9>3.5,1,0)) -> 0.5 | AM9: =IF($A$4=A9,0.5,IF($A$4>A9,1,0)) -> 0.5 | AN9: =IF($B$4=B9,0.5,IF($B$4>B9,1,0)) -> 0.5 | AO9: =IF($C$4=C9,0.5,IF($C$4>C9,1,0)) -> 0.5 | AP9: =IF($D$4=D9,0.5,IF($D$4>D9,1,0)) -> 0.5 | AQ9: =IF($E$4=E9,0.5,IF($E$4>E9,1,0)) -> 0.5 | AR9: =IF($F$4=F9,0.5,IF($F$4>F9,1,0)) -> 0.5 | AS9: =IF($G$4=G9,0.5,IF($G$4>G9,1,0)) -> 0.5 | AT9: =SUM(AM9:AS9) -> 3.5 | AU9: =IF(AT9=3.5,0.5,IF(AT9>3.5,1,0)) -> 0.5 | AW9: =IF($A$5=A9,0.5,IF($A$5>A9,1,0)) -> 0.5 | AX9: =IF($B$5=B9,0.5,IF($B$5>B9,1,0)) -> 0.5 | AY9: =IF($C$5=C9,0.5,IF($C$5>C9,1,0)) -> 0.5 | AZ9: =IF($D$5=D9,0.5,IF($D$5>D9,1,0)) -> 0.5 | BA9: =IF($E$5=E9,0.5,IF($E$5>E9,1,0)) -> 0.5 | BB9: =IF($F$5=F9,0.5,IF($F$5>F9,1,0)) -> 0.5 | BC9: =IF($G$5=G9,0.5,IF($G$5>G9,1,0)) -> 0.5 | BD9: =SUM(AW9:BC9) -> 3.5 | BE9: =IF(BD9=3.5,0.5,IF(BD9>3.5,1,0)) -> 0.5 | BG9: =IF($A$6=A9,0.5,IF($A$6>A9,1,0)) -> 0.5 | BH9: =IF($B$6=B9,0.5,IF($B$6>B9,1,0)) -> 0.5 | BI9: =IF($C$6=C9,0.5,IF($C$6>C9,1,0)) -> 0.5 | BJ9: =IF($D$6=D9,0.5,IF($D$6>D9,1,0)) -> 0.5 | BK9: =IF($E$6=E9,0.5,IF($E$6>E9,1,0)) -> 0.5 | BL9: =IF($F$6=F9,0.5,IF($F$6>F9,1,0)) -> 0.5 | BM9: =IF($G$6=G9,0.5,IF($G$6>G9,1,0)) -> 0.5 | BN9: =SUM(BG9:BM9) -> 3.5 | BO9: =IF(BN9=3.5,0.5,IF(BN9>3.5,1,0)) -> 0.5 | BQ9: =IF($A$7=A9,0.5,IF($A$7>A9,1,0)) -> 0.5 | BR9: =IF($B$7=B9,0.5,IF($B$7>B9,1,0)) -> 0.5 | BS9: =IF($C$7=C9,0.5,IF($C$7>C9,1,0)) -> 0.5 | BT9: =IF($D$7=D9,0.5,IF($D$7>D9,1,0)) -> 0.5 | BU9: =IF($E$7=E9,0.5,IF($E$7>E9,1,0)) -> 0.5 | BV9: =IF($F$7=F9,0.5,IF($F$7>F9,1,0)) -> 0.5 | BW9: =IF($G$7=G9,0.5,IF($G$7>G9,1,0)) -> 0.5 | BX9: =SUM(BQ9:BW9) -> 3.5 | BY9: =IF(BX9=3.5,0.5,IF(BX9>3.5,1,0)) -> 0.5 | CA9: =IF($A$8=A9,0.5,IF($A$8>A9,1,0)) -> 0.5 | CB9: =IF($B$8=B9,0.5,IF($B$8>B9,1,0)) -> 0.5 | CC9: =IF($C$8=C9,0.5,IF($C$8>C9,1,0)) -> 0.5 | CD9: =IF($D$8=D9,0.5,IF($D$8>D9,1,0)) -> 0.5 | CE9: =IF($E$8=E9,0.5,IF($E$8>E9,1,0)) -> 0.5 | CF9: =IF($F$8=F9,0.5,IF($F$8>F9,1,0)) -> 0.5 | CG9: =IF($G$8=G9,0.5,IF($G$8>G9,1,0)) -> 0.5 | CH9: =SUM(CA9:CG9) -> 3.5 | CI9: =IF(CH9=3.5,0.5,IF(CH9>3.5,1,0)) -> 0.5
A10: =KeyIn!N15 -> 0 | B10: =KeyIn!T15 -> 0 | C10: =KeyIn!Z15 -> 0 | D10: 0 | E10: 0 | F10: 0 | G10: 0 | I10: =IF($A$1=A10,0.5,IF($A$1>A10,1,0)) -> 0.5 | J10: =IF($B$1=B10,0.5,IF($B$1>B10,1,0)) -> 0.5 | K10: =IF($C$1=C10,0.5,IF($C$1>C10,1,0)) -> 0.5 | L10: =IF($D$1=D10,0.5,IF($D$1>D10,1,0)) -> 0.5 | M10: =IF($E$1=E10,0.5,IF($E$1>E10,1,0)) -> 0.5 | N10: =IF($F$1=F10,0.5,IF($F$1>F10,1,0)) -> 0.5 | O10: =IF($G$1=G10,0.5,IF($G$1>G10,1,0)) -> 0.5 | P10: =SUM(I10:O10) -> 3.5 | Q10: =IF(P10=3.5,0.5,IF(P10>3.5,1,0)) -> 0.5 | S10: =IF($A$2=A10,0.5,IF($A$2>A10,1,0)) -> 0.5 | T10: =IF($B$2=B10,0.5,IF($B$2>B10,1,0)) -> 0.5 | U10: =IF($C$2=C10,0.5,IF($C$2>C10,1,0)) -> 0.5 | V10: =IF($D$2=D10,0.5,IF($D$2>D10,1,0)) -> 0.5 | W10: =IF($E$2=E10,0.5,IF($E$2>E10,1,0)) -> 0.5 | X10: =IF($F$2=F10,0.5,IF($F$2>F10,1,0)) -> 0.5 | Y10: =IF($G$2=G10,0.5,IF($G$2>G10,1,0)) -> 0.5 | Z10: =SUM(S10:Y10) -> 3.5 | AA10: =IF(Z10=3.5,0.5,IF(Z10>3.5,1,0)) -> 0.5 | AC10: =IF($A$3=A10,0.5,IF($A$3>A10,1,0)) -> 0.5 | AD10: =IF($B$3=B10,0.5,IF($B$3>B10,1,0)) -> 0.5 | AE10: =IF($C$3=C10,0.5,IF($C$3>C10,1,0)) -> 0.5 | AF10: =IF($D$3=D10,0.5,IF($D$3>D10,1,0)) -> 0.5 | AG10: =IF($E$3=E10,0.5,IF($E$3>E10,1,0)) -> 0.5 | AH10: =IF($F$3=F10,0.5,IF($F$3>F10,1,0)) -> 0.5 | AI10: =IF($G$3=G10,0.5,IF($G$3>G10,1,0)) -> 0.5 | AJ10: =SUM(AC10:AI10) -> 3.5 | AK10: =IF(AJ10=3.5,0.5,IF(AJ10>3.5,1,0)) -> 0.5 | AM10: =IF($A$4=A10,0.5,IF($A$4>A10,1,0)) -> 0.5 | AN10: =IF($B$4=B10,0.5,IF($B$4>B10,1,0)) -> 0.5 | AO10: =IF($C$4=C10,0.5,IF($C$4>C10,1,0)) -> 0.5 | AP10: =IF($D$4=D10,0.5,IF($D$4>D10,1,0)) -> 0.5 | AQ10: =IF($E$4=E10,0.5,IF($E$4>E10,1,0)) -> 0.5 | AR10: =IF($F$4=F10,0.5,IF($F$4>F10,1,0)) -> 0.5 | AS10: =IF($G$4=G10,0.5,IF($G$4>G10,1,0)) -> 0.5 | AT10: =SUM(AM10:AS10) -> 3.5 | AU10: =IF(AT10=3.5,0.5,IF(AT10>3.5,1,0)) -> 0.5 | AW10: =IF($A$5=A10,0.5,IF($A$5>A10,1,0)) -> 0.5 | AX10: =IF($B$5=B10,0.5,IF($B$5>B10,1,0)) -> 0.5 | AY10: =IF($C$5=C10,0.5,IF($C$5>C10,1,0)) -> 0.5 | AZ10: =IF($D$5=D10,0.5,IF($D$5>D10,1,0)) -> 0.5 | BA10: =IF($E$5=E10,0.5,IF($E$5>E10,1,0)) -> 0.5 | BB10: =IF($F$5=F10,0.5,IF($F$5>F10,1,0)) -> 0.5 | BC10: =IF($G$5=G10,0.5,IF($G$5>G10,1,0)) -> 0.5 | BD10: =SUM(AW10:BC10) -> 3.5 | BE10: =IF(BD10=3.5,0.5,IF(BD10>3.5,1,0)) -> 0.5 | BG10: =IF($A$6=A10,0.5,IF($A$6>A10,1,0)) -> 0.5 | BH10: =IF($B$6=B10,0.5,IF($B$6>B10,1,0)) -> 0.5 | BI10: =IF($C$6=C10,0.5,IF($C$6>C10,1,0)) -> 0.5 | BJ10: =IF($D$6=D10,0.5,IF($D$6>D10,1,0)) -> 0.5 | BK10: =IF($E$6=E10,0.5,IF($E$6>E10,1,0)) -> 0.5 | BL10: =IF($F$6=F10,0.5,IF($F$6>F10,1,0)) -> 0.5 | BM10: =IF($G$6=G10,0.5,IF($G$6>G10,1,0)) -> 0.5 | BN10: =SUM(BG10:BM10) -> 3.5 | BO10: =IF(BN10=3.5,0.5,IF(BN10>3.5,1,0)) -> 0.5 | BQ10: =IF($A$7=A10,0.5,IF($A$7>A10,1,0)) -> 0.5 | BR10: =IF($B$7=B10,0.5,IF($B$7>B10,1,0)) -> 0.5 | BS10: =IF($C$7=C10,0.5,IF($C$7>C10,1,0)) -> 0.5 | BT10: =IF($D$7=D10,0.5,IF($D$7>D10,1,0)) -> 0.5 | BU10: =IF($E$7=E10,0.5,IF($E$7>E10,1,0)) -> 0.5 | BV10: =IF($F$7=F10,0.5,IF($F$7>F10,1,0)) -> 0.5 | BW10: =IF($G$7=G10,0.5,IF($G$7>G10,1,0)) -> 0.5 | BX10: =SUM(BQ10:BW10) -> 3.5 | BY10: =IF(BX10=3.5,0.5,IF(BX10>3.5,1,0)) -> 0.5 | CA10: =IF($A$8=A10,0.5,IF($A$8>A10,1,0)) -> 0.5 | CB10: =IF($B$8=B10,0.5,IF($B$8>B10,1,0)) -> 0.5 | CC10: =IF($C$8=C10,0.5,IF($C$8>C10,1,0)) -> 0.5 | CD10: =IF($D$8=D10,0.5,IF($D$8>D10,1,0)) -> 0.5 | CE10: =IF($E$8=E10,0.5,IF($E$8>E10,1,0)) -> 0.5 | CF10: =IF($F$8=F10,0.5,IF($F$8>F10,1,0)) -> 0.5 | CG10: =IF($G$8=G10,0.5,IF($G$8>G10,1,0)) -> 0.5 | CH10: =SUM(CA10:CG10) -> 3.5 | CI10: =IF(CH10=3.5,0.5,IF(CH10>3.5,1,0)) -> 0.5 | CK10: =IF($A$9=A10,0.5,IF($A$9>A10,1,0)) -> 0.5 | CL10: =IF($B$9=B10,0.5,IF($B$9>B10,1,0)) -> 0.5 | CM10: =IF($C$9=C10,0.5,IF($C$9>C10,1,0)) -> 0.5 | CN10: =IF($D$9=D10,0.5,IF($D$9>D10,1,0)) -> 0.5 | CO10: =IF($E$9=E10,0.5,IF($E$9>E10,1,0)) -> 0.5 | CP10: =IF($F$9=F10,0.5,IF($F$9>F10,1,0)) -> 0.5 | CQ10: =IF($G$9=G10,0.5,IF($G$9>G10,1,0)) -> 0.5 | CR10: =SUM(CK10:CQ10) -> 3.5 | CS10: =IF(CR10=3.5,0.5,IF(CR10>3.5,1,0)) -> 0.5
A11: =KeyIn!N16 -> 0 | B11: =KeyIn!T16 -> 0 | C11: =KeyIn!Z16 -> 0 | D11: 0 | E11: 0 | F11: 0 | G11: 0 | I11: =IF($A$1=A11,0.5,IF($A$1>A11,1,0)) -> 0.5 | J11: =IF($B$1=B11,0.5,IF($B$1>B11,1,0)) -> 0.5 | K11: =IF($C$1=C11,0.5,IF($C$1>C11,1,0)) -> 0.5 | L11: =IF($D$1=D11,0.5,IF($D$1>D11,1,0)) -> 0.5 | M11: =IF($E$1=E11,0.5,IF($E$1>E11,1,0)) -> 0.5 | N11: =IF($F$1=F11,0.5,IF($F$1>F11,1,0)) -> 0.5 | O11: =IF($G$1=G11,0.5,IF($G$1>G11,1,0)) -> 0.5 | P11: =SUM(I11:O11) -> 3.5 | Q11: =IF(P11=3.5,0.5,IF(P11>3.5,1,0)) -> 0.5 | S11: =IF($A$2=A11,0.5,IF($A$2>A11,1,0)) -> 0.5 | T11: =IF($B$2=B11,0.5,IF($B$2>B11,1,0)) -> 0.5 | U11: =IF($C$2=C11,0.5,IF($C$2>C11,1,0)) -> 0.5 | V11: =IF($D$2=D11,0.5,IF($D$2>D11,1,0)) -> 0.5 | W11: =IF($E$2=E11,0.5,IF($E$2>E11,1,0)) -> 0.5 | X11: =IF($F$2=F11,0.5,IF($F$2>F11,1,0)) -> 0.5 | Y11: =IF($G$2=G11,0.5,IF($G$2>G11,1,0)) -> 0.5 | Z11: =SUM(S11:Y11) -> 3.5 | AA11: =IF(Z11=3.5,0.5,IF(Z11>3.5,1,0)) -> 0.5 | AC11: =IF($A$3=A11,0.5,IF($A$3>A11,1,0)) -> 0.5 | AD11: =IF($B$3=B11,0.5,IF($B$3>B11,1,0)) -> 0.5 | AE11: =IF($C$3=C11,0.5,IF($C$3>C11,1,0)) -> 0.5 | AF11: =IF($D$3=D11,0.5,IF($D$3>D11,1,0)) -> 0.5 | AG11: =IF($E$3=E11,0.5,IF($E$3>E11,1,0)) -> 0.5 | AH11: =IF($F$3=F11,0.5,IF($F$3>F11,1,0)) -> 0.5 | AI11: =IF($G$3=G11,0.5,IF($G$3>G11,1,0)) -> 0.5 | AJ11: =SUM(AC11:AI11) -> 3.5 | AK11: =IF(AJ11=3.5,0.5,IF(AJ11>3.5,1,0)) -> 0.5 | AM11: =IF($A$4=A11,0.5,IF($A$4>A11,1,0)) -> 0.5 | AN11: =IF($B$4=B11,0.5,IF($B$4>B11,1,0)) -> 0.5 | AO11: =IF($C$4=C11,0.5,IF($C$4>C11,1,0)) -> 0.5 | AP11: =IF($D$4=D11,0.5,IF($D$4>D11,1,0)) -> 0.5 | AQ11: =IF($E$4=E11,0.5,IF($E$4>E11,1,0)) -> 0.5 | AR11: =IF($F$4=F11,0.5,IF($F$4>F11,1,0)) -> 0.5 | AS11: =IF($G$4=G11,0.5,IF($G$4>G11,1,0)) -> 0.5 | AT11: =SUM(AM11:AS11) -> 3.5 | AU11: =IF(AT11=3.5,0.5,IF(AT11>3.5,1,0)) -> 0.5 | AW11: =IF($A$5=A11,0.5,IF($A$5>A11,1,0)) -> 0.5 | AX11: =IF($B$5=B11,0.5,IF($B$5>B11,1,0)) -> 0.5 | AY11: =IF($C$5=C11,0.5,IF($C$5>C11,1,0)) -> 0.5 | AZ11: =IF($D$5=D11,0.5,IF($D$5>D11,1,0)) -> 0.5 | BA11: =IF($E$5=E11,0.5,IF($E$5>E11,1,0)) -> 0.5 | BB11: =IF($F$5=F11,0.5,IF($F$5>F11,1,0)) -> 0.5 | BC11: =IF($G$5=G11,0.5,IF($G$5>G11,1,0)) -> 0.5 | BD11: =SUM(AW11:BC11) -> 3.5 | BE11: =IF(BD11=3.5,0.5,IF(BD11>3.5,1,0)) -> 0.5 | BG11: =IF($A$6=A11,0.5,IF($A$6>A11,1,0)) -> 0.5 | BH11: =IF($B$6=B11,0.5,IF($B$6>B11,1,0)) -> 0.5 | BI11: =IF($C$6=C11,0.5,IF($C$6>C11,1,0)) -> 0.5 | BJ11: =IF($D$6=D11,0.5,IF($D$6>D11,1,0)) -> 0.5 | BK11: =IF($E$6=E11,0.5,IF($E$6>E11,1,0)) -> 0.5 | BL11: =IF($F$6=F11,0.5,IF($F$6>F11,1,0)) -> 0.5 | BM11: =IF($G$6=G11,0.5,IF($G$6>G11,1,0)) -> 0.5 | BN11: =SUM(BG11:BM11) -> 3.5 | BO11: =IF(BN11=3.5,0.5,IF(BN11>3.5,1,0)) -> 0.5 | BQ11: =IF($A$7=A11,0.5,IF($A$7>A11,1,0)) -> 0.5 | BR11: =IF($B$7=B11,0.5,IF($B$7>B11,1,0)) -> 0.5 | BS11: =IF($C$7=C11,0.5,IF($C$7>C11,1,0)) -> 0.5 | BT11: =IF($D$7=D11,0.5,IF($D$7>D11,1,0)) -> 0.5 | BU11: =IF($E$7=E11,0.5,IF($E$7>E11,1,0)) -> 0.5 | BV11: =IF($F$7=F11,0.5,IF($F$7>F11,1,0)) -> 0.5 | BW11: =IF($G$7=G11,0.5,IF($G$7>G11,1,0)) -> 0.5 | BX11: =SUM(BQ11:BW11) -> 3.5 | BY11: =IF(BX11=3.5,0.5,IF(BX11>3.5,1,0)) -> 0.5 | CA11: =IF($A$8=A11,0.5,IF($A$8>A11,1,0)) -> 0.5 | CB11: =IF($B$8=B11,0.5,IF($B$8>B11,1,0)) -> 0.5 | CC11: =IF($C$8=C11,0.5,IF($C$8>C11,1,0)) -> 0.5 | CD11: =IF($D$8=D11,0.5,IF($D$8>D11,1,0)) -> 0.5 | CE11: =IF($E$8=E11,0.5,IF($E$8>E11,1,0)) -> 0.5 | CF11: =IF($F$8=F11,0.5,IF($F$8>F11,1,0)) -> 0.5 | CG11: =IF($G$8=G11,0.5,IF($G$8>G11,1,0)) -> 0.5 | CH11: =SUM(CA11:CG11) -> 3.5 | CI11: =IF(CH11=3.5,0.5,IF(CH11>3.5,1,0)) -> 0.5 | CK11: =IF($A$9=A11,0.5,IF($A$9>A11,1,0)) -> 0.5 | CL11: =IF($B$9=B11,0.5,IF($B$9>B11,1,0)) -> 0.5 | CM11: =IF($C$9=C11,0.5,IF($C$9>C11,1,0)) -> 0.5 | CN11: =IF($D$9=D11,0.5,IF($D$9>D11,1,0)) -> 0.5 | CO11: =IF($E$9=E11,0.5,IF($E$9>E11,1,0)) -> 0.5 | CP11: =IF($F$9=F11,0.5,IF($F$9>F11,1,0)) -> 0.5 | CQ11: =IF($G$9=G11,0.5,IF($G$9>G11,1,0)) -> 0.5 | CR11: =SUM(CK11:CQ11) -> 3.5 | CS11: =IF(CR11=3.5,0.5,IF(CR11>3.5,1,0)) -> 0.5 | CU11: =IF($A$10=A11,0.5,IF($A$10>A11,1,0)) -> 0.5 | CV11: =IF($B$10=B11,0.5,IF($B$10>B11,1,0)) -> 0.5 | CW11: =IF($C$10=C11,0.5,IF($C$10>C11,1,0)) -> 0.5 | CX11: =IF($D$10=D11,0.5,IF($D$10>D11,1,0)) -> 0.5 | CY11: =IF($E$10=E11,0.5,IF($E$10>E11,1,0)) -> 0.5 | CZ11: =IF($F$10=F11,0.5,IF($F$10>F11,1,0)) -> 0.5 | DA11: =IF($G$10=G11,0.5,IF($G$10>G11,1,0)) -> 0.5 | DB11: =SUM(CU11:DA11) -> 3.5 | DC11: =IF(DB11=3.5,0.5,IF(DB11>3.5,1,0)) -> 0.5
A12: =KeyIn!N17 -> 0 | B12: =KeyIn!T17 -> 0 | C12: =KeyIn!Z17 -> 0 | D12: 0 | E12: 0 | F12: 0 | G12: 0 | I12: =IF($A$1=A12,0.5,IF($A$1>A12,1,0)) -> 0.5 | J12: =IF($B$1=B12,0.5,IF($B$1>B12,1,0)) -> 0.5 | K12: =IF($C$1=C12,0.5,IF($C$1>C12,1,0)) -> 0.5 | L12: =IF($D$1=D12,0.5,IF($D$1>D12,1,0)) -> 0.5 | M12: =IF($E$1=E12,0.5,IF($E$1>E12,1,0)) -> 0.5 | N12: =IF($F$1=F12,0.5,IF($F$1>F12,1,0)) -> 0.5 | O12: =IF($G$1=G12,0.5,IF($G$1>G12,1,0)) -> 0.5 | P12: =SUM(I12:O12) -> 3.5 | Q12: =IF(P12=3.5,0.5,IF(P12>3.5,1,0)) -> 0.5 | S12: =IF($A$2=A12,0.5,IF($A$2>A12,1,0)) -> 0.5 | T12: =IF($B$2=B12,0.5,IF($B$2>B12,1,0)) -> 0.5 | U12: =IF($C$2=C12,0.5,IF($C$2>C12,1,0)) -> 0.5 | V12: =IF($D$2=D12,0.5,IF($D$2>D12,1,0)) -> 0.5 | W12: =IF($E$2=E12,0.5,IF($E$2>E12,1,0)) -> 0.5 | X12: =IF($F$2=F12,0.5,IF($F$2>F12,1,0)) -> 0.5 | Y12: =IF($G$2=G12,0.5,IF($G$2>G12,1,0)) -> 0.5 | Z12: =SUM(S12:Y12) -> 3.5 | AA12: =IF(Z12=3.5,0.5,IF(Z12>3.5,1,0)) -> 0.5 | AC12: =IF($A$3=A12,0.5,IF($A$3>A12,1,0)) -> 0.5 | AD12: =IF($B$3=B12,0.5,IF($B$3>B12,1,0)) -> 0.5 | AE12: =IF($C$3=C12,0.5,IF($C$3>C12,1,0)) -> 0.5 | AF12: =IF($D$3=D12,0.5,IF($D$3>D12,1,0)) -> 0.5 | AG12: =IF($E$3=E12,0.5,IF($E$3>E12,1,0)) -> 0.5 | AH12: =IF($F$3=F12,0.5,IF($F$3>F12,1,0)) -> 0.5 | AI12: =IF($G$3=G12,0.5,IF($G$3>G12,1,0)) -> 0.5 | AJ12: =SUM(AC12:AI12) -> 3.5 | AK12: =IF(AJ12=3.5,0.5,IF(AJ12>3.5,1,0)) -> 0.5 | AM12: =IF($A$4=A12,0.5,IF($A$4>A12,1,0)) -> 0.5 | AN12: =IF($B$4=B12,0.5,IF($B$4>B12,1,0)) -> 0.5 | AO12: =IF($C$4=C12,0.5,IF($C$4>C12,1,0)) -> 0.5 | AP12: =IF($D$4=D12,0.5,IF($D$4>D12,1,0)) -> 0.5 | AQ12: =IF($E$4=E12,0.5,IF($E$4>E12,1,0)) -> 0.5 | AR12: =IF($F$4=F12,0.5,IF($F$4>F12,1,0)) -> 0.5 | AS12: =IF($G$4=G12,0.5,IF($G$4>G12,1,0)) -> 0.5 | AT12: =SUM(AM12:AS12) -> 3.5 | AU12: =IF(AT12=3.5,0.5,IF(AT12>3.5,1,0)) -> 0.5 | AW12: =IF($A$5=A12,0.5,IF($A$5>A12,1,0)) -> 0.5 | AX12: =IF($B$5=B12,0.5,IF($B$5>B12,1,0)) -> 0.5 | AY12: =IF($C$5=C12,0.5,IF($C$5>C12,1,0)) -> 0.5 | AZ12: =IF($D$5=D12,0.5,IF($D$5>D12,1,0)) -> 0.5 | BA12: =IF($E$5=E12,0.5,IF($E$5>E12,1,0)) -> 0.5 | BB12: =IF($F$5=F12,0.5,IF($F$5>F12,1,0)) -> 0.5 | BC12: =IF($G$5=G12,0.5,IF($G$5>G12,1,0)) -> 0.5 | BD12: =SUM(AW12:BC12) -> 3.5 | BE12: =IF(BD12=3.5,0.5,IF(BD12>3.5,1,0)) -> 0.5 | BG12: =IF($A$6=A12,0.5,IF($A$6>A12,1,0)) -> 0.5 | BH12: =IF($B$6=B12,0.5,IF($B$6>B12,1,0)) -> 0.5 | BI12: =IF($C$6=C12,0.5,IF($C$6>C12,1,0)) -> 0.5 | BJ12: =IF($D$6=D12,0.5,IF($D$6>D12,1,0)) -> 0.5 | BK12: =IF($E$6=E12,0.5,IF($E$6>E12,1,0)) -> 0.5 | BL12: =IF($F$6=F12,0.5,IF($F$6>F12,1,0)) -> 0.5 | BM12: =IF($G$6=G12,0.5,IF($G$6>G12,1,0)) -> 0.5 | BN12: =SUM(BG12:BM12) -> 3.5 | BO12: =IF(BN12=3.5,0.5,IF(BN12>3.5,1,0)) -> 0.5 | BQ12: =IF($A$7=A12,0.5,IF($A$7>A12,1,0)) -> 0.5 | BR12: =IF($B$7=B12,0.5,IF($B$7>B12,1,0)) -> 0.5 | BS12: =IF($C$7=C12,0.5,IF($C$7>C12,1,0)) -> 0.5 | BT12: =IF($D$7=D12,0.5,IF($D$7>D12,1,0)) -> 0.5 | BU12: =IF($E$7=E12,0.5,IF($E$7>E12,1,0)) -> 0.5 | BV12: =IF($F$7=F12,0.5,IF($F$7>F12,1,0)) -> 0.5 | BW12: =IF($G$7=G12,0.5,IF($G$7>G12,1,0)) -> 0.5 | BX12: =SUM(BQ12:BW12) -> 3.5 | BY12: =IF(BX12=3.5,0.5,IF(BX12>3.5,1,0)) -> 0.5 | CA12: =IF($A$8=A12,0.5,IF($A$8>A12,1,0)) -> 0.5 | CB12: =IF($B$8=B12,0.5,IF($B$8>B12,1,0)) -> 0.5 | CC12: =IF($C$8=C12,0.5,IF($C$8>C12,1,0)) -> 0.5 | CD12: =IF($D$8=D12,0.5,IF($D$8>D12,1,0)) -> 0.5 | CE12: =IF($E$8=E12,0.5,IF($E$8>E12,1,0)) -> 0.5 | CF12: =IF($F$8=F12,0.5,IF($F$8>F12,1,0)) -> 0.5 | CG12: =IF($G$8=G12,0.5,IF($G$8>G12,1,0)) -> 0.5 | CH12: =SUM(CA12:CG12) -> 3.5 | CI12: =IF(CH12=3.5,0.5,IF(CH12>3.5,1,0)) -> 0.5 | CK12: =IF($A$9=A12,0.5,IF($A$9>A12,1,0)) -> 0.5 | CL12: =IF($B$9=B12,0.5,IF($B$9>B12,1,0)) -> 0.5 | CM12: =IF($C$9=C12,0.5,IF($C$9>C12,1,0)) -> 0.5 | CN12: =IF($D$9=D12,0.5,IF($D$9>D12,1,0)) -> 0.5 | CO12: =IF($E$9=E12,0.5,IF($E$9>E12,1,0)) -> 0.5 | CP12: =IF($F$9=F12,0.5,IF($F$9>F12,1,0)) -> 0.5 | CQ12: =IF($G$9=G12,0.5,IF($G$9>G12,1,0)) -> 0.5 | CR12: =SUM(CK12:CQ12) -> 3.5 | CS12: =IF(CR12=3.5,0.5,IF(CR12>3.5,1,0)) -> 0.5 | CU12: =IF($A$10=A12,0.5,IF($A$10>A12,1,0)) -> 0.5 | CV12: =IF($B$10=B12,0.5,IF($B$10>B12,1,0)) -> 0.5 | CW12: =IF($C$10=C12,0.5,IF($C$10>C12,1,0)) -> 0.5 | CX12: =IF($D$10=D12,0.5,IF($D$10>D12,1,0)) -> 0.5 | CY12: =IF($E$10=E12,0.5,IF($E$10>E12,1,0)) -> 0.5 | CZ12: =IF($F$10=F12,0.5,IF($F$10>F12,1,0)) -> 0.5 | DA12: =IF($G$10=G12,0.5,IF($G$10>G12,1,0)) -> 0.5 | DB12: =SUM(CU12:DA12) -> 3.5 | DC12: =IF(DB12=3.5,0.5,IF(DB12>3.5,1,0)) -> 0.5 | DE12: =IF($A$11=A12,0.5,IF($A$11>A12,1,0)) -> 0.5 | DF12: =IF($B$11=B12,0.5,IF($B$11>B12,1,0)) -> 0.5 | DG12: =IF($C$11=C12,0.5,IF($C$11>C12,1,0)) -> 0.5 | DH12: =IF($D$11=D12,0.5,IF($D$11>D12,1,0)) -> 0.5 | DI12: =IF($E$11=E12,0.5,IF($E11>$E$12,1,0)) -> 0.5 | DJ12: =IF($F$11=F12,0.5,IF($F$11>F12,1,0)) -> 0.5 | DK12: =IF($G$11=G12,0.5,IF($G$11>G12,1,0)) -> 0.5 | DL12: =SUM(DE12:DK12) -> 3.5 | DM12: =IF(DL12=3.5,0.5,IF(DL12>3.5,1,0)) -> 0.5
A13: =KeyIn!N18 -> 0 | B13: =KeyIn!T18 -> 0 | C13: =KeyIn!Z18 -> 0 | D13: 0 | E13: 0 | F13: 0 | G13: 0 | I13: =IF($A$1=A13,0.5,IF($A$1>A13,1,0)) -> 0.5 | J13: =IF($B$1=B13,0.5,IF($B$1>B13,1,0)) -> 0.5 | K13: =IF($C$1=C13,0.5,IF($C$1>C13,1,0)) -> 0.5 | L13: =IF($D$1=D13,0.5,IF($D$1>D13,1,0)) -> 0.5 | M13: =IF($E$1=E13,0.5,IF($E$1>E13,1,0)) -> 0.5 | N13: =IF($F$1=F13,0.5,IF($F$1>F13,1,0)) -> 0.5 | O13: =IF($G$1=G13,0.5,IF($G$1>G13,1,0)) -> 0.5 | P13: =SUM(I13:O13) -> 3.5 | Q13: =IF(P13=3.5,0.5,IF(P13>3.5,1,0)) -> 0.5 | S13: =IF($A$2=A13,0.5,IF($A$2>A13,1,0)) -> 0.5 | T13: =IF($B$2=B13,0.5,IF($B$2>B13,1,0)) -> 0.5 | U13: =IF($C$2=C13,0.5,IF($C$2>C13,1,0)) -> 0.5 | V13: =IF($D$2=D13,0.5,IF($D$2>D13,1,0)) -> 0.5 | W13: =IF($E$2=E13,0.5,IF($E$2>E13,1,0)) -> 0.5 | X13: =IF($F$2=F13,0.5,IF($F$2>F13,1,0)) -> 0.5 | Y13: =IF($G$2=G13,0.5,IF($G$2>G13,1,0)) -> 0.5 | Z13: =SUM(S13:Y13) -> 3.5 | AA13: =IF(Z13=3.5,0.5,IF(Z13>3.5,1,0)) -> 0.5 | AC13: =IF($A$3=A13,0.5,IF($A$3>A13,1,0)) -> 0.5 | AD13: =IF($B$3=B13,0.5,IF($B$3>B13,1,0)) -> 0.5 | AE13: =IF($C$3=C13,0.5,IF($C$3>C13,1,0)) -> 0.5 | AF13: =IF($D$3=D13,0.5,IF($D$3>D13,1,0)) -> 0.5 | AG13: =IF($E$3=E13,0.5,IF($E$3>E13,1,0)) -> 0.5 | AH13: =IF($F$3=F13,0.5,IF($F$3>F13,1,0)) -> 0.5 | AI13: =IF($G$3=G13,0.5,IF($G$3>G13,1,0)) -> 0.5 | AJ13: =SUM(AC13:AI13) -> 3.5 | AK13: =IF(AJ13=3.5,0.5,IF(AJ13>3.5,1,0)) -> 0.5 | AM13: =IF($A$4=A13,0.5,IF($A$4>A13,1,0)) -> 0.5 | AN13: =IF($B$4=B13,0.5,IF($B$4>B13,1,0)) -> 0.5 | AO13: =IF($C$4=C13,0.5,IF($C$4>C13,1,0)) -> 0.5 | AP13: =IF($D$4=D13,0.5,IF($D$4>D13,1,0)) -> 0.5 | AQ13: =IF($E$4=E13,0.5,IF($E$4>E13,1,0)) -> 0.5 | AR13: =IF($F$4=F13,0.5,IF($F$4>F13,1,0)) -> 0.5 | AS13: =IF($G$4=G13,0.5,IF($G$4>G13,1,0)) -> 0.5 | AT13: =SUM(AM13:AS13) -> 3.5 | AU13: =IF(AT13=3.5,0.5,IF(AT13>3.5,1,0)) -> 0.5 | AW13: =IF($A$5=A13,0.5,IF($A$5>A13,1,0)) -> 0.5 | AX13: =IF($B$5=B13,0.5,IF($B$5>B13,1,0)) -> 0.5 | AY13: =IF($C$5=C13,0.5,IF($C$5>C13,1,0)) -> 0.5 | AZ13: =IF($D$5=D13,0.5,IF($D$5>D13,1,0)) -> 0.5 | BA13: =IF($E$5=E13,0.5,IF($E$5>E13,1,0)) -> 0.5 | BB13: =IF($F$5=F13,0.5,IF($F$5>F13,1,0)) -> 0.5 | BC13: =IF($G$5=G13,0.5,IF($G$5>G13,1,0)) -> 0.5 | BD13: =SUM(AW13:BC13) -> 3.5 | BE13: =IF(BD13=3.5,0.5,IF(BD13>3.5,1,0)) -> 0.5 | BG13: =IF($A$6=A13,0.5,IF($A$6>A13,1,0)) -> 0.5 | BH13: =IF($B$6=B13,0.5,IF($B$6>B13,1,0)) -> 0.5 | BI13: =IF($C$6=C13,0.5,IF($C$6>C13,1,0)) -> 0.5 | BJ13: =IF($D$6=D13,0.5,IF($D$6>D13,1,0)) -> 0.5 | BK13: =IF($E$6=E13,0.5,IF($E$6>E13,1,0)) -> 0.5 | BL13: =IF($F$6=F13,0.5,IF($F$6>F13,1,0)) -> 0.5 | BM13: =IF($G$6=G13,0.5,IF($G$6>G13,1,0)) -> 0.5 | BN13: =SUM(BG13:BM13) -> 3.5 | BO13: =IF(BN13=3.5,0.5,IF(BN13>3.5,1,0)) -> 0.5 | BQ13: =IF($A$7=A13,0.5,IF($A$7>A13,1,0)) -> 0.5 | BR13: =IF($B$7=B13,0.5,IF($B$7>B13,1,0)) -> 0.5 | BS13: =IF($C$7=C13,0.5,IF($C$7>C13,1,0)) -> 0.5 | BT13: =IF($D$7=D13,0.5,IF($D$7>D13,1,0)) -> 0.5 | BU13: =IF($E$7=E13,0.5,IF($E$7>E13,1,0)) -> 0.5 | BV13: =IF($F$7=F13,0.5,IF($F$7>F13,1,0)) -> 0.5 | BW13: =IF($G$7=G13,0.5,IF($G$7>G13,1,0)) -> 0.5 | BX13: =SUM(BQ13:BW13) -> 3.5 | BY13: =IF(BX13=3.5,0.5,IF(BX13>3.5,1,0)) -> 0.5 | CA13: =IF($A$8=A13,0.5,IF($A$8>A13,1,0)) -> 0.5 | CB13: =IF($B$8=B13,0.5,IF($B$8>B13,1,0)) -> 0.5 | CC13: =IF($C$8=C13,0.5,IF($C$8>C13,1,0)) -> 0.5 | CD13: =IF($D$8=D13,0.5,IF($D$8>D13,1,0)) -> 0.5 | CE13: =IF($E$8=E13,0.5,IF($E$8>E13,1,0)) -> 0.5 | CF13: =IF($F$8=F13,0.5,IF($F$8>F13,1,0)) -> 0.5 | CG13: =IF($G$8=G13,0.5,IF($G$8>G13,1,0)) -> 0.5 | CH13: =SUM(CA13:CG13) -> 3.5 | CI13: =IF(CH13=3.5,0.5,IF(CH13>3.5,1,0)) -> 0.5 | CK13: =IF($A$9=A13,0.5,IF($A$9>A13,1,0)) -> 0.5 | CL13: =IF($B$9=B13,0.5,IF($B$9>B13,1,0)) -> 0.5 | CM13: =IF($C$9=C13,0.5,IF($C$9>C13,1,0)) -> 0.5 | CN13: =IF($D$9=D13,0.5,IF($D$9>D13,1,0)) -> 0.5 | CO13: =IF($E$9=E13,0.5,IF($E$9>E13,1,0)) -> 0.5 | CP13: =IF($F$9=F13,0.5,IF($F$9>F13,1,0)) -> 0.5 | CQ13: =IF($G$9=G13,0.5,IF($G$9>G13,1,0)) -> 0.5 | CR13: =SUM(CK13:CQ13) -> 3.5 | CS13: =IF(CR13=3.5,0.5,IF(CR13>3.5,1,0)) -> 0.5 | CU13: =IF($A$10=A13,0.5,IF($A$10>A13,1,0)) -> 0.5 | CV13: =IF($B$10=B13,0.5,IF($B$10>B13,1,0)) -> 0.5 | CW13: =IF($C$10=C13,0.5,IF($C$10>C13,1,0)) -> 0.5 | CX13: =IF($D$10=D13,0.5,IF($D$10>D13,1,0)) -> 0.5 | CY13: =IF($E$10=E13,0.5,IF($E$10>E13,1,0)) -> 0.5 | CZ13: =IF($F$10=F13,0.5,IF($F$10>F13,1,0)) -> 0.5 | DA13: =IF($G$10=G13,0.5,IF($G$10>G13,1,0)) -> 0.5 | DB13: =SUM(CU13:DA13) -> 3.5 | DC13: =IF(DB13=3.5,0.5,IF(DB13>3.5,1,0)) -> 0.5 | DE13: =IF($A$11=A13,0.5,IF($A$11>A13,1,0)) -> 0.5 | DF13: =IF($B$11=B13,0.5,IF($B$11>B13,1,0)) -> 0.5 | DG13: =IF($C$11=C13,0.5,IF($C$11>C13,1,0)) -> 0.5 | DH13: =IF($D$11=D13,0.5,IF($D$11>D13,1,0)) -> 0.5 | DI13: =IF($E$11=E13,0.5,IF($E11>$E$13,1,0)) -> 0.5 | DJ13: =IF($F$11=F13,0.5,IF($F$11>F13,1,0)) -> 0.5 | DK13: =IF($G$11=G13,0.5,IF($G$11>G13,1,0)) -> 0.5 | DL13: =SUM(DE13:DK13) -> 3.5 | DM13: =IF(DL13=3.5,0.5,IF(DL13>3.5,1,0)) -> 0.5 | DO13: =IF($A$12=A13,0.5,IF($A$12>A13,1,0)) -> 0.5 | DP13: =IF($B$12=B13,0.5,IF($B$12>B13,1,0)) -> 0.5 | DQ13: =IF($C$12=C13,0.5,IF($C$12>C13,1,0)) -> 0.5 | DR13: =IF($D$12=D13,0.5,IF($D$12>D13,1,0)) -> 0.5 | DS13: =IF($E$12=E13,0.5,IF($E$12>E13,1,0)) -> 0.5 | DT13: =IF($F$12=F13,0.5,IF($F$12>F13,1,0)) -> 0.5 | DU13: =IF($G$12=G13,0.5,IF($G$12>G13,1,0)) -> 0.5 | DV13: =SUM(DO13:DU13) -> 3.5 | DW13: =IF(DV13=3.5,0.5,IF(DV13>3.5,1,0)) -> 0.5
A14: =KeyIn!N19 -> 0 | B14: =KeyIn!T19 -> 0 | C14: =KeyIn!Z19 -> 0 | D14: 0 | E14: 0 | F14: 0 | G14: 0 | I14: =IF($A$1=A14,0.5,IF($A$1>A14,1,0)) -> 0.5 | J14: =IF($B$1=B14,0.5,IF($B$1>B14,1,0)) -> 0.5 | K14: =IF($C$1=C14,0.5,IF($C$1>C14,1,0)) -> 0.5 | L14: =IF($D$1=D14,0.5,IF($D$1>D14,1,0)) -> 0.5 | M14: =IF($E$1=E14,0.5,IF($E$1>E14,1,0)) -> 0.5 | N14: =IF($F$1=F14,0.5,IF($F$1>F14,1,0)) -> 0.5 | O14: =IF($G$1=G14,0.5,IF($G$1>G14,1,0)) -> 0.5 | P14: =SUM(I14:O14) -> 3.5 | Q14: =IF(P14=3.5,0.5,IF(P14>3.5,1,0)) -> 0.5 | S14: =IF($A$2=A14,0.5,IF($A$2>A14,1,0)) -> 0.5 | T14: =IF($B$2=B14,0.5,IF($B$2>B14,1,0)) -> 0.5 | U14: =IF($C$2=C14,0.5,IF($C$2>C14,1,0)) -> 0.5 | V14: =IF($D$2=D14,0.5,IF($D$2>D14,1,0)) -> 0.5 | W14: =IF($E$2=E14,0.5,IF($E$2>E14,1,0)) -> 0.5 | X14: =IF($F$2=F14,0.5,IF($F$2>F14,1,0)) -> 0.5 | Y14: =IF($G$2=G14,0.5,IF($G$2>G14,1,0)) -> 0.5 | Z14: =SUM(S14:Y14) -> 3.5 | AA14: =IF(Z14=3.5,0.5,IF(Z14>3.5,1,0)) -> 0.5 | AC14: =IF($A$3=A14,0.5,IF($A$3>A14,1,0)) -> 0.5 | AD14: =IF($B$3=B14,0.5,IF($B$3>B14,1,0)) -> 0.5 | AE14: =IF($C$3=C14,0.5,IF($C$3>C14,1,0)) -> 0.5 | AF14: =IF($D$3=D14,0.5,IF($D$3>D14,1,0)) -> 0.5 | AG14: =IF($E$3=E14,0.5,IF($E$3>E14,1,0)) -> 0.5 | AH14: =IF($F$3=F14,0.5,IF($F$3>F14,1,0)) -> 0.5 | AI14: =IF($G$3=G14,0.5,IF($G$3>G14,1,0)) -> 0.5 | AJ14: =SUM(AC14:AI14) -> 3.5 | AK14: =IF(AJ14=3.5,0.5,IF(AJ14>3.5,1,0)) -> 0.5 | AM14: =IF($A$4=A14,0.5,IF($A$4>A14,1,0)) -> 0.5 | AN14: =IF($B$4=B14,0.5,IF($B$4>B14,1,0)) -> 0.5 | AO14: =IF($C$4=C14,0.5,IF($C$4>C14,1,0)) -> 0.5 | AP14: =IF($D$4=D14,0.5,IF($D$4>D14,1,0)) -> 0.5 | AQ14: =IF($E$4=E14,0.5,IF($E$4>E14,1,0)) -> 0.5 | AR14: =IF($F$4=F14,0.5,IF($F$4>F14,1,0)) -> 0.5 | AS14: =IF($G$4=G14,0.5,IF($G$4>G14,1,0)) -> 0.5 | AT14: =SUM(AM14:AS14) -> 3.5 | AU14: =IF(AT14=3.5,0.5,IF(AT14>3.5,1,0)) -> 0.5 | AW14: =IF($A$5=A14,0.5,IF($A$5>A14,1,0)) -> 0.5 | AX14: =IF($B$5=B14,0.5,IF($B$5>B14,1,0)) -> 0.5 | AY14: =IF($C$5=C14,0.5,IF($C$5>C14,1,0)) -> 0.5 | AZ14: =IF($D$5=D14,0.5,IF($D$5>D14,1,0)) -> 0.5 | BA14: =IF($E$5=E14,0.5,IF($E$5>E14,1,0)) -> 0.5 | BB14: =IF($F$5=F14,0.5,IF($F$5>F14,1,0)) -> 0.5 | BC14: =IF($G$5=G14,0.5,IF($G$5>G14,1,0)) -> 0.5 | BD14: =SUM(AW14:BC14) -> 3.5 | BE14: =IF(BD14=3.5,0.5,IF(BD14>3.5,1,0)) -> 0.5 | BG14: =IF($A$6=A14,0.5,IF($A$6>A14,1,0)) -> 0.5 | BH14: =IF($B$6=B14,0.5,IF($B$6>B14,1,0)) -> 0.5 | BI14: =IF($C$6=C14,0.5,IF($C$6>C14,1,0)) -> 0.5 | BJ14: =IF($D$6=D14,0.5,IF($D$6>D14,1,0)) -> 0.5 | BK14: =IF($E$6=E14,0.5,IF($E$6>E14,1,0)) -> 0.5 | BL14: =IF($F$6=F14,0.5,IF($F$6>F14,1,0)) -> 0.5 | BM14: =IF($G$6=G14,0.5,IF($G$6>G14,1,0)) -> 0.5 | BN14: =SUM(BG14:BM14) -> 3.5 | BO14: =IF(BN14=3.5,0.5,IF(BN14>3.5,1,0)) -> 0.5 | BQ14: =IF($A$7=A14,0.5,IF($A$7>A14,1,0)) -> 0.5 | BR14: =IF($B$7=B14,0.5,IF($B$7>B14,1,0)) -> 0.5 | BS14: =IF($C$7=C14,0.5,IF($C$7>C14,1,0)) -> 0.5 | BT14: =IF($D$7=D14,0.5,IF($D$7>D14,1,0)) -> 0.5 | BU14: =IF($E$7=E14,0.5,IF($E$7>E14,1,0)) -> 0.5 | BV14: =IF($F$7=F14,0.5,IF($F$7>F14,1,0)) -> 0.5 | BW14: =IF($G$7=G14,0.5,IF($G$7>G14,1,0)) -> 0.5 | BX14: =SUM(BQ14:BW14) -> 3.5 | BY14: =IF(BX14=3.5,0.5,IF(BX14>3.5,1,0)) -> 0.5 | CA14: =IF($A$8=A14,0.5,IF($A$8>A14,1,0)) -> 0.5 | CB14: =IF($B$8=B14,0.5,IF($B$8>B14,1,0)) -> 0.5 | CC14: =IF($C$8=C14,0.5,IF($C$8>C14,1,0)) -> 0.5 | CD14: =IF($D$8=D14,0.5,IF($D$8>D14,1,0)) -> 0.5 | CE14: =IF($E$8=E14,0.5,IF($E$8>E14,1,0)) -> 0.5 | CF14: =IF($F$8=F14,0.5,IF($F$8>F14,1,0)) -> 0.5 | CG14: =IF($G$8=G14,0.5,IF($G$8>G14,1,0)) -> 0.5 | CH14: =SUM(CA14:CG14) -> 3.5 | CI14: =IF(CH14=3.5,0.5,IF(CH14>3.5,1,0)) -> 0.5 | CK14: =IF($A$9=A14,0.5,IF($A$9>A14,1,0)) -> 0.5 | CL14: =IF($B$9=B14,0.5,IF($B$9>B14,1,0)) -> 0.5 | CM14: =IF($C$9=C14,0.5,IF($C$9>C14,1,0)) -> 0.5 | CN14: =IF($D$9=D14,0.5,IF($D$9>D14,1,0)) -> 0.5 | CO14: =IF($E$9=E14,0.5,IF($E$9>E14,1,0)) -> 0.5 | CP14: =IF($F$9=F14,0.5,IF($F$9>F14,1,0)) -> 0.5 | CQ14: =IF($G$9=G14,0.5,IF($G$9>G14,1,0)) -> 0.5 | CR14: =SUM(CK14:CQ14) -> 3.5 | CS14: =IF(CR14=3.5,0.5,IF(CR14>3.5,1,0)) -> 0.5 | CU14: =IF($A$10=A14,0.5,IF($A$10>A14,1,0)) -> 0.5 | CV14: =IF($B$10=B14,0.5,IF($B$10>B14,1,0)) -> 0.5 | CW14: =IF($C$10=C14,0.5,IF($C$10>C14,1,0)) -> 0.5 | CX14: =IF($D$10=D14,0.5,IF($D$10>D14,1,0)) -> 0.5 | CY14: =IF($E$10=E14,0.5,IF($E$10>E14,1,0)) -> 0.5 | CZ14: =IF($F$10=F14,0.5,IF($F$10>F14,1,0)) -> 0.5 | DA14: =IF($G$10=G14,0.5,IF($G$10>G14,1,0)) -> 0.5 | DB14: =SUM(CU14:DA14) -> 3.5 | DC14: =IF(DB14=3.5,0.5,IF(DB14>3.5,1,0)) -> 0.5 | DE14: =IF($A$11=A14,0.5,IF($A$11>A14,1,0)) -> 0.5 | DF14: =IF($B$11=B14,0.5,IF($B$11>B14,1,0)) -> 0.5 | DG14: =IF($C$11=C14,0.5,IF($C$11>C14,1,0)) -> 0.5 | DH14: =IF($D$11=D14,0.5,IF($D$11>D14,1,0)) -> 0.5 | DI14: =IF($E$11=E14,0.5,IF($E11>$E$14,1,0)) -> 0.5 | DJ14: =IF($F$11=F14,0.5,IF($F$11>F14,1,0)) -> 0.5 | DK14: =IF($G$11=G14,0.5,IF($G$11>G14,1,0)) -> 0.5 | DL14: =SUM(DE14:DK14) -> 3.5 | DM14: =IF(DL14=3.5,0.5,IF(DL14>3.5,1,0)) -> 0.5 | DO14: =IF($A$12=A14,0.5,IF($A$12>A14,1,0)) -> 0.5 | DP14: =IF($B$12=B14,0.5,IF($B$12>B14,1,0)) -> 0.5 | DQ14: =IF($C$12=C14,0.5,IF($C$12>C14,1,0)) -> 0.5 | DR14: =IF($D$12=D14,0.5,IF($D$12>D14,1,0)) -> 0.5 | DS14: =IF($E$12=E14,0.5,IF($E$12>E14,1,0)) -> 0.5 | DT14: =IF($F$12=F14,0.5,IF($F$12>F14,1,0)) -> 0.5 | DU14: =IF($G$12=G14,0.5,IF($G$12>G14,1,0)) -> 0.5 | DV14: =SUM(DO14:DU14) -> 3.5 | DW14: =IF(DV14=3.5,0.5,IF(DV14>3.5,1,0)) -> 0.5 | DY14: =IF($A$13=A14,0.5,IF($A$13>A14,1,0)) -> 0.5 | DZ14: =IF($B$13=B14,0.5,IF($B$13>B14,1,0)) -> 0.5 | EA14: =IF($C$13=C14,0.5,IF($C$13>C14,1,0)) -> 0.5 | EB14: =IF($D$13=D14,0.5,IF($D$13>D14,1,0)) -> 0.5 | EC14: =IF($E$13=E14,0.5,IF($E$13>E14,1,0)) -> 0.5 | ED14: =IF($F$13=F14,0.5,IF($F$13>F14,1,0)) -> 0.5 | EE14: =IF($G$13=G14,0.5,IF($G$13>G14,1,0)) -> 0.5 | EF14: =SUM(DY14:EE14) -> 3.5 | EG14: =IF(EF14=3.5,0.5,IF(EF14>3.5,1,0)) -> 0.5
A15: =KeyIn!N20 -> 0 | B15: =KeyIn!T20 -> 0 | C15: =KeyIn!Z20 -> 0 | D15: 0 | E15: 0 | F15: 0 | G15: 0 | I15: =IF($A$1=A15,0.5,IF($A$1>A15,1,0)) -> 0.5 | J15: =IF($B$1=B15,0.5,IF($B$1>B15,1,0)) -> 0.5 | K15: =IF($C$1=C15,0.5,IF($C$1>C15,1,0)) -> 0.5 | L15: =IF($D$1=D15,0.5,IF($D$1>D15,1,0)) -> 0.5 | M15: =IF($E$1=E15,0.5,IF($E$1>E15,1,0)) -> 0.5 | N15: =IF($F$1=F15,0.5,IF($F$1>F15,1,0)) -> 0.5 | O15: =IF($G$1=G15,0.5,IF($G$1>G15,1,0)) -> 0.5 | P15: =SUM(I15:O15) -> 3.5 | Q15: =IF(P15=3.5,0.5,IF(P15>3.5,1,0)) -> 0.5 | S15: =IF($A$2=A15,0.5,IF($A$2>A15,1,0)) -> 0.5 | T15: =IF($B$2=B15,0.5,IF($B$2>B15,1,0)) -> 0.5 | U15: =IF($C$2=C15,0.5,IF($C$2>C15,1,0)) -> 0.5 | V15: =IF($D$2=D15,0.5,IF($D$2>D15,1,0)) -> 0.5 | W15: =IF($E$2=E15,0.5,IF($E$2>E15,1,0)) -> 0.5 | X15: =IF($F$2=F15,0.5,IF($F$2>F15,1,0)) -> 0.5 | Y15: =IF($G$2=G15,0.5,IF($G$2>G15,1,0)) -> 0.5 | Z15: =SUM(S15:Y15) -> 3.5 | AA15: =IF(Z15=3.5,0.5,IF(Z15>3.5,1,0)) -> 0.5 | AC15: =IF($A$3=A15,0.5,IF($A$3>A15,1,0)) -> 0.5 | AD15: =IF($B$3=B15,0.5,IF($B$3>B15,1,0)) -> 0.5 | AE15: =IF($C$3=C15,0.5,IF($C$3>C15,1,0)) -> 0.5 | AF15: =IF($D$3=D15,0.5,IF($D$3>D15,1,0)) -> 0.5 | AG15: =IF($E$3=E15,0.5,IF($E$3>E15,1,0)) -> 0.5 | AH15: =IF($F$3=F15,0.5,IF($F$3>F15,1,0)) -> 0.5 | AI15: =IF($G$3=G15,0.5,IF($G$3>G15,1,0)) -> 0.5 | AJ15: =SUM(AC15:AI15) -> 3.5 | AK15: =IF(AJ15=3.5,0.5,IF(AJ15>3.5,1,0)) -> 0.5 | AM15: =IF($A$4=A15,0.5,IF($A$4>A15,1,0)) -> 0.5 | AN15: =IF($B$4=B15,0.5,IF($B$4>B15,1,0)) -> 0.5 | AO15: =IF($C$4=C15,0.5,IF($C$4>C15,1,0)) -> 0.5 | AP15: =IF($D$4=D15,0.5,IF($D$4>D15,1,0)) -> 0.5 | AQ15: =IF($E$4=E15,0.5,IF($E$4>E15,1,0)) -> 0.5 | AR15: =IF($F$4=F15,0.5,IF($F$4>F15,1,0)) -> 0.5 | AS15: =IF($G$4=G15,0.5,IF($G$4>G15,1,0)) -> 0.5 | AT15: =SUM(AM15:AS15) -> 3.5 | AU15: =IF(AT15=3.5,0.5,IF(AT15>3.5,1,0)) -> 0.5 | AW15: =IF($A$5=A15,0.5,IF($A$5>A15,1,0)) -> 0.5 | AX15: =IF($B$5=B15,0.5,IF($B$5>B15,1,0)) -> 0.5 | AY15: =IF($C$5=C15,0.5,IF($C$5>C15,1,0)) -> 0.5 | AZ15: =IF($D$5=D15,0.5,IF($D$5>D15,1,0)) -> 0.5 | BA15: =IF($E$5=E15,0.5,IF($E$5>E15,1,0)) -> 0.5 | BB15: =IF($F$5=F15,0.5,IF($F$5>F15,1,0)) -> 0.5 | BC15: =IF($G$5=G15,0.5,IF($G$5>G15,1,0)) -> 0.5 | BD15: =SUM(AW15:BC15) -> 3.5 | BE15: =IF(BD15=3.5,0.5,IF(BD15>3.5,1,0)) -> 0.5 | BG15: =IF($A$6=A15,0.5,IF($A$6>A15,1,0)) -> 0.5 | BH15: =IF($B$6=B15,0.5,IF($B$6>B15,1,0)) -> 0.5 | BI15: =IF($C$6=C15,0.5,IF($C$6>C15,1,0)) -> 0.5 | BJ15: =IF($D$6=D15,0.5,IF($D$6>D15,1,0)) -> 0.5 | BK15: =IF($E$6=E15,0.5,IF($E$6>E15,1,0)) -> 0.5 | BL15: =IF($F$6=F15,0.5,IF($F$6>F15,1,0)) -> 0.5 | BM15: =IF($G$6=G15,0.5,IF($G$6>G15,1,0)) -> 0.5 | BN15: =SUM(BG15:BM15) -> 3.5 | BO15: =IF(BN15=3.5,0.5,IF(BN15>3.5,1,0)) -> 0.5 | BQ15: =IF($A$7=A15,0.5,IF($A$7>A15,1,0)) -> 0.5 | BR15: =IF($B$7=B15,0.5,IF($B$7>B15,1,0)) -> 0.5 | BS15: =IF($C$7=C15,0.5,IF($C$7>C15,1,0)) -> 0.5 | BT15: =IF($D$7=D15,0.5,IF($D$7>D15,1,0)) -> 0.5 | BU15: =IF($E$7=E15,0.5,IF($E$7>E15,1,0)) -> 0.5 | BV15: =IF($F$7=F15,0.5,IF($F$7>F15,1,0)) -> 0.5 | BW15: =IF($G$7=G15,0.5,IF($G$7>G15,1,0)) -> 0.5 | BX15: =SUM(BQ15:BW15) -> 3.5 | BY15: =IF(BX15=3.5,0.5,IF(BX15>3.5,1,0)) -> 0.5 | CA15: =IF($A$8=A15,0.5,IF($A$8>A15,1,0)) -> 0.5 | CB15: =IF($B$8=B15,0.5,IF($B$8>B15,1,0)) -> 0.5 | CC15: =IF($C$8=C15,0.5,IF($C$8>C15,1,0)) -> 0.5 | CD15: =IF($D$8=D15,0.5,IF($D$8>D15,1,0)) -> 0.5 | CE15: =IF($E$8=E15,0.5,IF($E$8>E15,1,0)) -> 0.5 | CF15: =IF($F$8=F15,0.5,IF($F$8>F15,1,0)) -> 0.5 | CG15: =IF($G$8=G15,0.5,IF($G$8>G15,1,0)) -> 0.5 | CH15: =SUM(CA15:CG15) -> 3.5 | CI15: =IF(CH15=3.5,0.5,IF(CH15>3.5,1,0)) -> 0.5 | CK15: =IF($A$9=A15,0.5,IF($A$9>A15,1,0)) -> 0.5 | CL15: =IF($B$9=B15,0.5,IF($B$9>B15,1,0)) -> 0.5 | CM15: =IF($C$9=C15,0.5,IF($C$9>C15,1,0)) -> 0.5 | CN15: =IF($D$9=D15,0.5,IF($D$9>D15,1,0)) -> 0.5 | CO15: =IF($E$9=E15,0.5,IF($E$9>E15,1,0)) -> 0.5 | CP15: =IF($F$9=F15,0.5,IF($F$9>F15,1,0)) -> 0.5 | CQ15: =IF($G$9=G15,0.5,IF($G$9>G15,1,0)) -> 0.5 | CR15: =SUM(CK15:CQ15) -> 3.5 | CS15: =IF(CR15=3.5,0.5,IF(CR15>3.5,1,0)) -> 0.5 | CU15: =IF($A$10=A15,0.5,IF($A$10>A15,1,0)) -> 0.5 | CV15: =IF($B$10=B15,0.5,IF($B$10>B15,1,0)) -> 0.5 | CW15: =IF($C$10=C15,0.5,IF($C$10>C15,1,0)) -> 0.5 | CX15: =IF($D$10=D15,0.5,IF($D$10>D15,1,0)) -> 0.5 | CY15: =IF($E$10=E15,0.5,IF($E$10>E15,1,0)) -> 0.5 | CZ15: =IF($F$10=F15,0.5,IF($F$10>F15,1,0)) -> 0.5 | DA15: =IF($G$10=G15,0.5,IF($G$10>G15,1,0)) -> 0.5 | DB15: =SUM(CU15:DA15) -> 3.5 | DC15: =IF(DB15=3.5,0.5,IF(DB15>3.5,1,0)) -> 0.5 | DE15: =IF($A$11=A15,0.5,IF($A$11>A15,1,0)) -> 0.5 | DF15: =IF($B$11=B15,0.5,IF($B$11>B15,1,0)) -> 0.5 | DG15: =IF($C$11=C15,0.5,IF($C$11>C15,1,0)) -> 0.5 | DH15: =IF($D$11=D15,0.5,IF($D$11>D15,1,0)) -> 0.5 | DI15: =IF($E$11=E15,0.5,IF($E11>$E$15,1,0)) -> 0.5 | DJ15: =IF($F$11=F15,0.5,IF($F$11>F15,1,0)) -> 0.5 | DK15: =IF($G$11=G15,0.5,IF($G$11>G15,1,0)) -> 0.5 | DL15: =SUM(DE15:DK15) -> 3.5 | DM15: =IF(DL15=3.5,0.5,IF(DL15>3.5,1,0)) -> 0.5 | DO15: =IF($A$12=A15,0.5,IF($A$12>A15,1,0)) -> 0.5 | DP15: =IF($B$12=B15,0.5,IF($B$12>B15,1,0)) -> 0.5 | DQ15: =IF($C$12=C15,0.5,IF($C$12>C15,1,0)) -> 0.5 | DR15: =IF($D$12=D15,0.5,IF($D$12>D15,1,0)) -> 0.5 | DS15: =IF($E$12=E15,0.5,IF($E$12>E15,1,0)) -> 0.5 | DT15: =IF($F$12=F15,0.5,IF($F$12>F15,1,0)) -> 0.5 | DU15: =IF($G$12=G15,0.5,IF($G$12>G15,1,0)) -> 0.5 | DV15: =SUM(DO15:DU15) -> 3.5 | DW15: =IF(DV15=3.5,0.5,IF(DV15>3.5,1,0)) -> 0.5 | DY15: =IF($A$13=A15,0.5,IF($A$13>A15,1,0)) -> 0.5 | DZ15: =IF($B$13=B15,0.5,IF($B$13>B15,1,0)) -> 0.5 | EA15: =IF($C$13=C15,0.5,IF($C$13>C15,1,0)) -> 0.5 | EB15: =IF($D$13=D15,0.5,IF($D$13>D15,1,0)) -> 0.5 | EC15: =IF($E$13=E15,0.5,IF($E$13>E15,1,0)) -> 0.5 | ED15: =IF($F$13=F15,0.5,IF($F$13>F15,1,0)) -> 0.5 | EE15: =IF($G$13=G15,0.5,IF($G$13>G15,1,0)) -> 0.5 | EF15: =SUM(DY15:EE15) -> 3.5 | EG15: =IF(EF15=3.5,0.5,IF(EF15>3.5,1,0)) -> 0.5 | EI15: =IF($A$14=A15,0.5,IF($A$14>A15,1,0)) -> 0.5 | EJ15: =IF($B$14=B15,0.5,IF($B$14>B15,1,0)) -> 0.5 | EK15: =IF($C$14=C15,0.5,IF($C$14>C15,1,0)) -> 0.5 | EL15: =IF($D$14=D15,0.5,IF($D$14>D15,1,0)) -> 0.5 | EM15: =IF($E$14=E15,0.5,IF($E$14>E15,1,0)) -> 0.5 | EN15: =IF($F$14=F15,0.5,IF($F$14>F15,1,0)) -> 0.5 | EO15: =IF($G$14=G15,0.5,IF($G$14>G15,1,0)) -> 0.5 | EP15: =SUM(EI15:EO15) -> 3.5 | EQ15: =IF(EP15=3.5,0.5,IF(EP15>3.5,1,0)) -> 0.5
