Workbook
Name list1: #REF!
Name list1: #REF!
Name LIST2: '(1) 成績輸入'!$K$92:$K$94
Name LIST3: '(1) 成績輸入'!$K$92:$K$99
Name list4: '(1) 成績輸入'!$K$91:$K$99
Name 名次: '[1]成績輸入~'!$K$67:$K$69
Name 名次: '[1]成績輸入~'!$K$67:$K$69
Name 名次: '(1) 成績輸入'!$K$69:$K$71

Sheet 注意事項
C4: 席次法系統：閃鈴教室製作 (五人總分版) 1.0
C6: 注意事項
C7: 1.裁判成績，如有到小數點兩位(如： 80.46)，成績總表只會顯示一位(如：80.5)，但判決內容不影響。
C8: 2.此版本，使用office 2007製作，再別的版本可能會有錯誤，請再驗證。(2003不能使用)
C9: 3.此版本為2014 Formsoa扯鈴大賽版本，非現在Formosa之版本。
C10: 4.如系統有誤，或其它問題，歡迎告知。
C12: 其它賽會使用
C13: 1.為推廣更好的評分系統，本系統無償提供所有賽會使用。
C14: 2.本系統由閃鈴教室製作，如賽會需要使用，需在章程或成績表上註記「使用之版本」。( 席次法系統：閃鈴教室製作 (五人總分版) 1.0)
C15: 3.本單位不能承單系統出錯之責任，煩請比賽單位自行驗證成績。
C16: 4.系統有誤，勿必告知。
C18: 連絡方式：fb粉絲專頁：閃鈴教室 扯鈴教學 Diabolo Classroom 或 tancle.taiwan@gmail.com 李坦闊

Sheet (1) 成績輸入
B1: 盃賽名稱： | C1: 鈴屆好兄弟扯鈴大賽
B2: 比賽項目： | C2: 扯鈴 | N2: 請填入紅色框框內， 其它部分請勿更動。
B3: 比賽組別： | C3: 賣萌小動物 男女混合組
B4: 比賽時間： | C4: 0.4375
B5: 公告時間： | C5: 0.48611111
A7: no. | B7: 選手 | D7: 裁判評分 | K7: 手動輸入最終名次 | N7: 第一輪 | O7: 第二輪 | R7: 裁判群 | S7: 裁判一： | T7: 擄夫
B8: 學校/團隊 | C8: 姓名 | N8: 席次法名次 | O8: 總平均分名次 | S8: 裁判二： | T8: 哆拉逼夢
B9: Team | C9: name | D9: 一 | E9: 二 | F9: 三 | G9: 四 | H9: 五 | I9: 六 | J9: 七 | S9: 裁判三： | T9: 伊折銳耳
A10: 1 | C10: 拉拉熊 | D10: 88 | E10: 85 | F10: 90 | G10: 81 | K10: 第一名 | N10: ='席次法運算(勿動)'!ABX2 -> 1 | O10: ='席次法運算(勿動)'!ACG2 -> 3 | S10: 裁判四： | T10: 你踩
A11: 2 | C11: 凱蒂 | D11: 86 | E11: 84 | F11: 90 | G11: 99 | K11: 第二名 | N11: ='席次法運算(勿動)'!ABX3 -> 2 | O11: ='席次法運算(勿動)'!ACG3 -> 1 | S11: 裁判五：
A12: 3 | C12: 皮卡丘 | D12: 84 | E12: 83 | F12: 89 | G12: 80 | K12: 第三名 | N12: ='席次法運算(勿動)'!ABX4 -> 3 | O12: ='席次法運算(勿動)'!ACG4 -> 5 | S12: 裁判六：
A13: 4 | C13: 海綿 | D13: 82 | E13: 82 | F13: 89 | G13: 92 | N13: ='席次法運算(勿動)'!ABX5 -> 4 | O13: ='席次法運算(勿動)'!ACG5 -> 2 | S13: 裁判七：
A14: 5 | C14: 吉胖喵 | D14: 80 | E14: 81 | F14: 89 | G14: 90 | N14: ='席次法運算(勿動)'!ABX6 -> 5 | O14: ='席次法運算(勿動)'!ACG6 -> 4 | S14: 記錄員： | T14: 畢卡鎖
A15: 6 | N15: ='席次法運算(勿動)'!ABX7 -> - | O15: ='席次法運算(勿動)'!ACG7 -> 6
A16: 7 | N16: ='席次法運算(勿動)'!ABX8 -> - | O16: ='席次法運算(勿動)'!ACG8 -> 6
A17: 8 | N17: ='席次法運算(勿動)'!ABX9 -> - | O17: ='席次法運算(勿動)'!ACG9 -> 6
A18: 9 | N18: ='席次法運算(勿動)'!ABX10 -> - | O18: ='席次法運算(勿動)'!ACG10 -> 6
A19: 10 | N19: ='席次法運算(勿動)'!ABX11 -> - | O19: ='席次法運算(勿動)'!ACG11 -> 6
A20: 11 | N20: ='席次法運算(勿動)'!ABX12 -> - | O20: ='席次法運算(勿動)'!ACG12 -> 6
A21: 12 | N21: ='席次法運算(勿動)'!ABX13 -> - | O21: ='席次法運算(勿動)'!ACG13 -> 6
A22: 13 | N22: ='席次法運算(勿動)'!ABX14 -> - | O22: ='席次法運算(勿動)'!ACG14 -> 6
A23: 14 | N23: ='席次法運算(勿動)'!ABX15 -> - | O23: ='席次法運算(勿動)'!ACG15 -> 6
A24: 15 | N24: ='席次法運算(勿動)'!ABX16 -> - | O24: ='席次法運算(勿動)'!ACG16 -> 6
A25: 16 | N25: ='席次法運算(勿動)'!ABX17 -> - | O25: ='席次法運算(勿動)'!ACG17 -> 6
A26: 17 | N26: ='席次法運算(勿動)'!ABX18 -> - | O26: ='席次法運算(勿動)'!ACG18 -> 6
... A89: 80 | N89: ='席次法運算(勿動)'!ABX81 -> - | O89: ='席次法運算(勿動)'!ACG81 -> 6
K91: 錄取決賽
K92: 第一名
K93: 第二名
K94: 第三名
K95: 第四名
K96: 第五名
K97: 第六名
K98: 第七名
K99: 第八名

Sheet (2) 印出成績總表 
B1: ='(1) 成績輸入'!C1 -> 鈴屆好兄弟扯鈴大賽 | M1: 席次法系統：閃鈴教室製作 (五人總分版) 1.0
M2: 裁判 | N2: 裁判一： | P2: ='(1) 成績輸入'!T7 -> 擄夫 | T2: 記錄員： | U2: ='(1) 成績輸入'!T14 -> 畢卡鎖
N3: 裁判二： | P3: ='(1) 成績輸入'!T8 -> 哆拉逼夢 | T3: 公 告： | W3: ='(1) 成績輸入'!C5 -> 0.48611111
B4: 比賽項目： | C4: ='(1) 成績輸入'!C2 -> 扯鈴 | E4: ='(1) 成績輸入'!C4 -> 0.4375 | N4: 裁判三： | P4: ='(1) 成績輸入'!T9 -> 伊折銳耳 | T4: 裁判長簽名：
B5: 比賽組別： | C5: ='(1) 成績輸入'!C3 -> 賣萌小動物 男女混合組 | N5: 裁判四： | P5: ='(1) 成績輸入'!T10 -> 你踩
N6: 裁判五： | P6: ='(1) 成績輸入'!T11 -> 0
N7: 裁判六： | P7: ='(1) 成績輸入'!T12 -> 0
N8: 裁判七： | P8: ='(1) 成績輸入'!T13 -> 0
A11: no. | B11: 學校名稱 | C11: 姓名 | D11: 裁判名次(第一輪) | K11: 席次法 | M11: 裁判評分(第二輪) | T11: 總平 均分 | W11: 最終名次
D13: 一 | E13: 二 | F13: 三 | G13: 四 | H13: 五 | I13: 六 | J13: 七 | K13: 積分 | L13: 排序 | M13: 一 | N13: 二 | O13: 三 | P13: 四 | Q13: 五 | R13: 六 | S13: 七
A14: 1 | B14: ='(1) 成績輸入'!B10 -> 0 | C14: ='(1) 成績輸入'!C10 -> 拉拉熊 | D14: ='席次法運算(勿動)'!ABP2 -> 1 | E14: ='席次法運算(勿動)'!ABQ2 -> 1 | F14: ='席次法運算(勿動)'!ABR2 -> 1 | G14: ='席次法運算(勿動)'!ABS2 -> 4 | H14: ='席次法運算(勿動)'!ABT2 -> - | I14: ='席次法運算(勿動)'!ABU2 -> - | J14: ='席次法運算(勿動)'!ABV2 -> - | K14: ='席次法運算(勿動)'!ABW2 -> 4 | ... T14: ='席次法運算(勿動)'!ACF2 -> 86 | W14: ='(1) 成績輸入'!K10 -> 第一名
A15: 2 | B15: ='(1) 成績輸入'!B11 -> 0 | C15: ='(1) 成績輸入'!C11 -> 凱蒂 | D15: ='席次法運算(勿動)'!ABP3 -> 2 | E15: ='席次法運算(勿動)'!ABQ3 -> 2 | F15: ='席次法運算(勿動)'!ABR3 -> 1 | G15: ='席次法運算(勿動)'!ABS3 -> 1 | H15: ='席次法運算(勿動)'!ABT3 -> - | I15: ='席次法運算(勿動)'!ABU3 -> - | J15: ='席次法運算(勿動)'!ABV3 -> - | K15: ='席次法運算(勿動)'!ABW3 -> 3 | ... T15: ='席次法運算(勿動)'!ACF3 -> 89.75 | W15: ='(1) 成績輸入'!K11 -> 第二名
A16: 3 | B16: ='(1) 成績輸入'!B12 -> 0 | C16: ='(1) 成績輸入'!C12 -> 皮卡丘 | D16: ='席次法運算(勿動)'!ABP4 -> 3 | E16: ='席次法運算(勿動)'!ABQ4 -> 3 | F16: ='席次法運算(勿動)'!ABR4 -> 3 | G16: ='席次法運算(勿動)'!ABS4 -> 5 | H16: ='席次法運算(勿動)'!ABT4 -> - | I16: ='席次法運算(勿動)'!ABU4 -> - | J16: ='席次法運算(勿動)'!ABV4 -> - | K16: ='席次法運算(勿動)'!ABW4 -> 2 | ... T16: ='席次法運算(勿動)'!ACF4 -> 84 | W16: ='(1) 成績輸入'!K12 -> 第三名
A17: 4 | B17: ='(1) 成績輸入'!B13 -> 0 | C17: ='(1) 成績輸入'!C13 -> 海綿 | D17: ='席次法運算(勿動)'!ABP5 -> 4 | E17: ='席次法運算(勿動)'!ABQ5 -> 4 | F17: ='席次法運算(勿動)'!ABR5 -> 3 | G17: ='席次法運算(勿動)'!ABS5 -> 2 | H17: ='席次法運算(勿動)'!ABT5 -> - | I17: ='席次法運算(勿動)'!ABU5 -> - | J17: ='席次法運算(勿動)'!ABV5 -> - | K17: ='席次法運算(勿動)'!ABW5 -> 1 | ... T17: ='席次法運算(勿動)'!ACF5 -> 86.25 | W17: ='(1) 成績輸入'!K13 -> 0
A18: 5 | B18: ='(1) 成績輸入'!B14 -> 0 | C18: ='(1) 成績輸入'!C14 -> 吉胖喵 | D18: ='席次法運算(勿動)'!ABP6 -> 5 | E18: ='席次法運算(勿動)'!ABQ6 -> 5 | F18: ='席次法運算(勿動)'!ABR6 -> 3 | G18: ='席次法運算(勿動)'!ABS6 -> 3 | H18: ='席次法運算(勿動)'!ABT6 -> - | I18: ='席次法運算(勿動)'!ABU6 -> - | J18: ='席次法運算(勿動)'!ABV6 -> - | K18: ='席次法運算(勿動)'!ABW6 -> 0 | ... T18: ='席次法運算(勿動)'!ACF6 -> 85 | W18: ='(1) 成績輸入'!K14 -> 0
A19: 6 | B19: ='(1) 成績輸入'!B15 -> 0 | C19: ='(1) 成績輸入'!C15 -> 0 | D19: ='席次法運算(勿動)'!ABP7 -> - | E19: ='席次法運算(勿動)'!ABQ7 -> - | F19: ='席次法運算(勿動)'!ABR7 -> - | G19: ='席次法運算(勿動)'!ABS7 -> - | H19: ='席次法運算(勿動)'!ABT7 -> - | I19: ='席次法運算(勿動)'!ABU7 -> - | J19: ='席次法運算(勿動)'!ABV7 -> - | K19: ='席次法運算(勿動)'!ABW7 -> - | ... T19: ='席次法運算(勿動)'!ACF7 -> - | W19: ='(1) 成績輸入'!K15 -> 0
A20: 7 | B20: ='(1) 成績輸入'!B16 -> 0 | C20: ='(1) 成績輸入'!C16 -> 0 | D20: ='席次法運算(勿動)'!ABP8 -> - | E20: ='席次法運算(勿動)'!ABQ8 -> - | F20: ='席次法運算(勿動)'!ABR8 -> - | G20: ='席次法運算(勿動)'!ABS8 -> - | H20: ='席次法運算(勿動)'!ABT8 -> - | I20: ='席次法運算(勿動)'!ABU8 -> - | J20: ='席次法運算(勿動)'!ABV8 -> - | K20: ='席次法運算(勿動)'!ABW8 -> - | ... T20: ='席次法運算(勿動)'!ACF8 -> - | W20: ='(1) 成績輸入'!K16 -> 0
A21: 8 | B21: ='(1) 成績輸入'!B17 -> 0 | C21: ='(1) 成績輸入'!C17 -> 0 | D21: ='席次法運算(勿動)'!ABP9 -> - | E21: ='席次法運算(勿動)'!ABQ9 -> - | F21: ='席次法運算(勿動)'!ABR9 -> - | G21: ='席次法運算(勿動)'!ABS9 -> - | H21: ='席次法運算(勿動)'!ABT9 -> - | I21: ='席次法運算(勿動)'!ABU9 -> - | J21: ='席次法運算(勿動)'!ABV9 -> - | K21: ='席次法運算(勿動)'!ABW9 -> - | ... T21: ='席次法運算(勿動)'!ACF9 -> - | W21: ='(1) 成績輸入'!K17 -> 0
A22: 9 | B22: ='(1) 成績輸入'!B18 -> 0 | C22: ='(1) 成績輸入'!C18 -> 0 | D22: ='席次法運算(勿動)'!ABP10 -> - | E22: ='席次法運算(勿動)'!ABQ10 -> - | F22: ='席次法運算(勿動)'!ABR10 -> - | G22: ='席次法運算(勿動)'!ABS10 -> - | H22: ='席次法運算(勿動)'!ABT10 -> - | I22: ='席次法運算(勿動)'!ABU10 -> - | J22: ='席次法運算(勿動)'!ABV10 -> - | K22: ='席次法運算(勿動)'!ABW10 -> - | ... T22: ='席次法運算(勿動)'!ACF10 -> - | W22: ='(1) 成績輸入'!K18 -> 0
A23: 10 | B23: ='(1) 成績輸入'!B19 -> 0 | C23: ='(1) 成績輸入'!C19 -> 0 | D23: ='席次法運算(勿動)'!ABP11 -> - | E23: ='席次法運算(勿動)'!ABQ11 -> - | F23: ='席次法運算(勿動)'!ABR11 -> - | G23: ='席次法運算(勿動)'!ABS11 -> - | H23: ='席次法運算(勿動)'!ABT11 -> - | I23: ='席次法運算(勿動)'!ABU11 -> - | J23: ='席次法運算(勿動)'!ABV11 -> - | K23: ='席次法運算(勿動)'!ABW11 -> - | ... T23: ='席次法運算(勿動)'!ACF11 -> - | W23: ='(1) 成績輸入'!K19 -> 0
A24: 11 | B24: ='(1) 成績輸入'!B20 -> 0 | C24: ='(1) 成績輸入'!C20 -> 0 | D24: ='席次法運算(勿動)'!ABP12 -> - | E24: ='席次法運算(勿動)'!ABQ12 -> - | F24: ='席次法運算(勿動)'!ABR12 -> - | G24: ='席次法運算(勿動)'!ABS12 -> - | H24: ='席次法運算(勿動)'!ABT12 -> - | I24: ='席次法運算(勿動)'!ABU12 -> - | J24: ='席次法運算(勿動)'!ABV12 -> - | K24: ='席次法運算(勿動)'!ABW12 -> - | ... T24: ='席次法運算(勿動)'!ACF12 -> - | W24: ='(1) 成績輸入'!K20 -> 0
A25: 12 | B25: ='(1) 成績輸入'!B21 -> 0 | C25: ='(1) 成績輸入'!C21 -> 0 | D25: ='席次法運算(勿動)'!ABP13 -> - | E25: ='席次法運算(勿動)'!ABQ13 -> - | F25: ='席次法運算(勿動)'!ABR13 -> - | G25: ='席次法運算(勿動)'!ABS13 -> - | H25: ='席次法運算(勿動)'!ABT13 -> - | I25: ='席次法運算(勿動)'!ABU13 -> - | J25: ='席次法運算(勿動)'!ABV13 -> - | K25: ='席次法運算(勿動)'!ABW13 -> - | ... T25: ='席次法運算(勿動)'!ACF13 -> - | W25: ='(1) 成績輸入'!K21 -> 0
... A93: 80 | B93: ='(1) 成績輸入'!B89 -> 0 | C93: ='(1) 成績輸入'!C89 -> 0 | D93: ='席次法運算(勿動)'!ABP81 -> - | E93: ='席次法運算(勿動)'!ABQ81 -> - | F93: ='席次法運算(勿動)'!ABR81 -> - | G93: ='席次法運算(勿動)'!ABS81 -> - | H93: ='席次法運算(勿動)'!ABT81 -> - | I93: ='席次法運算(勿動)'!ABU81 -> - | J93: ='席次法運算(勿動)'!ABV81 -> - | K93: ='席次法運算(勿動)'!ABW81 -> - | ... T93: ='席次法運算(勿動)'!ACF81 -> - | W93: ='(1) 成績輸入'!K89 -> 0

Sheet (3) 裁判評分表
B1: ='(1) 成績輸入'!C1 -> 鈴屆好兄弟扯鈴大賽 | H1: 裁判評分表
B3: 比賽項目： | C3: ='(1) 成績輸入'!C2 -> 扯鈴 | F3: 比賽組別： | H3: ='(1) 成績輸入'!C3 -> 賣萌小動物 男女混合組
A6: no. | B6: 學校名稱 | C6: 姓名 | D6: 總分 | F6: 註記 | K6: 實施扣分
A7: 1 | B7: ='(1) 成績輸入'!B10 -> 0 | C7: ='(1) 成績輸入'!C10 -> 拉拉熊
A8: 2 | B8: ='(1) 成績輸入'!B11 -> 0 | C8: ='(1) 成績輸入'!C11 -> 凱蒂
A9: 3 | B9: ='(1) 成績輸入'!B12 -> 0 | C9: ='(1) 成績輸入'!C12 -> 皮卡丘
A10: 4 | B10: ='(1) 成績輸入'!B13 -> 0 | C10: ='(1) 成績輸入'!C13 -> 海綿
A11: 5 | B11: ='(1) 成績輸入'!B14 -> 0 | C11: ='(1) 成績輸入'!C14 -> 吉胖喵
A12: 6 | B12: ='(1) 成績輸入'!B15 -> 0 | C12: ='(1) 成績輸入'!C15 -> 0
A13: 7 | B13: ='(1) 成績輸入'!B16 -> 0 | C13: ='(1) 成績輸入'!C16 -> 0
A14: 8 | B14: ='(1) 成績輸入'!B17 -> 0 | C14: ='(1) 成績輸入'!C17 -> 0
A15: 9 | B15: ='(1) 成績輸入'!B18 -> 0 | C15: ='(1) 成績輸入'!C18 -> 0
A16: 10 | B16: ='(1) 成績輸入'!B19 -> 0 | C16: ='(1) 成績輸入'!C19 -> 0
A17: 11 | B17: ='(1) 成績輸入'!B20 -> 0 | C17: ='(1) 成績輸入'!C20 -> 0
A18: 12 | B18: ='(1) 成績輸入'!B21 -> 0 | C18: ='(1) 成績輸入'!C21 -> 0
... A21: 15 | B21: ='(1) 成績輸入'!B24 -> 0 | C21: ='(1) 成績輸入'!C24 -> 0
B22: 第( )席裁判 | F22: 裁判簽名：
B23: ='(1) 成績輸入'!$C$3 -> 賣萌小動物 男女混合組 | D23: 第2頁
A24: no. | B24: 學校名稱 | C24: 姓名 | D24: 總分 | F24: 註記 | K24: 實施扣分
A25: 16 | B25: ='(1) 成績輸入'!B25 -> 0 | C25: ='(1) 成績輸入'!C25 -> 0
A26: 17 | B26: ='(1) 成績輸入'!B26 -> 0 | C26: ='(1) 成績輸入'!C26 -> 0
A27: 18 | B27: ='(1) 成績輸入'!B27 -> 0 | C27: ='(1) 成績輸入'!C27 -> 0
A28: 19 | B28: ='(1) 成績輸入'!B28 -> 0 | C28: ='(1) 成績輸入'!C28 -> 0
A29: 20 | B29: ='(1) 成績輸入'!B29 -> 0 | C29: ='(1) 成績輸入'!C29 -> 0
A30: 21 | B30: ='(1) 成績輸入'!B30 -> 0 | C30: ='(1) 成績輸入'!C30 -> 0
A31: 22 | B31: ='(1) 成績輸入'!B31 -> 0 | C31: ='(1) 成績輸入'!C31 -> 0
A32: 23 | B32: ='(1) 成績輸入'!B32 -> 0 | C32: ='(1) 成績輸入'!C32 -> 0
A33: 24 | B33: ='(1) 成績輸入'!B33 -> 0 | C33: ='(1) 成績輸入'!C33 -> 0
A34: 25 | B34: ='(1) 成績輸入'!B34 -> 0 | C34: ='(1) 成績輸入'!C34 -> 0
A35: 26 | B35: ='(1) 成績輸入'!B35 -> 0 | C35: ='(1) 成績輸入'!C35 -> 0
A36: 27 | B36: ='(1) 成績輸入'!B36 -> 0 | C36: ='(1) 成績輸入'!C36 -> 0
... A39: 30 | B39: ='(1) 成績輸入'!B39 -> 0 | C39: ='(1) 成績輸入'!C39 -> 0
B40: 第( )席裁判 | F40: 裁判簽名：
B41: ='(1) 成績輸入'!$C$3 -> 賣萌小動物 男女混合組 | D41: 第3頁
A42: no. | B42: 學校名稱 | C42: 姓名 | D42: 總分 | F42: 註記 | K42: 實施扣分
A43: 31 | B43: ='(1) 成績輸入'!B40 -> 0 | C43: ='(1) 成績輸入'!C40 -> 0
A44: 32 | B44: ='(1) 成績輸入'!B41 -> 0 | C44: ='(1) 成績輸入'!C41 -> 0
A45: 33 | B45: ='(1) 成績輸入'!B42 -> 0 | C45: ='(1) 成績輸入'!C42 -> 0
A46: 34 | B46: ='(1) 成績輸入'!B43 -> 0 | C46: ='(1) 成績輸入'!C43 -> 0
A47: 35 | B47: ='(1) 成績輸入'!B44 -> 0 | C47: ='(1) 成績輸入'!C44 -> 0
...

Sheet 席次法運算(勿動)
B1: 一 | C1: 二 | D1: 三 | E1: 四 | F1: 五 | G1: 六 | H1: 七 | I1: 積分 | J1: 席次積分(扣去空白) | K1: 名次 | L1: 參賽人數 | M1: 總平均分 | O1: 1一 | P1: 1二 | Q1: 1三 | R1: 1四 | S1: 1五 | T1: 1六 | U1: 1七 | V1: 1積 | X1: 2一 | Y1: 2二 | Z1: 2三 | AA1: 2四 | AB1: 2五 | AC1: 2六 | AD1: 2七 | AE1: 2積 | AG1: 3一 | AH1: 3二 | AI1: 3三 | AJ1: 3四 | AK1: 3五 | AL1: 3六 | AM1: 3七 | AN1: 3積 | AP1: 4一 | AQ1: 4二 | AR1: 4三 | AS1: 4四 | AT1: 4五 | AU1: 4六 | AV1: 4七 | AW1: 4積 | AY1: 5一 | AZ1: 5二 | BA1: 5三 | BB1: 5四 | BC1: 5五 | BD1: 5六 | BE1: 5七 | BF1: 5積 | BH1: 6一 | BI1: 6二 | BJ1: 6三 | BK1: 6四 | BL1: 6五 | BM1: 6六 | BN1: 6七 | BO1: 6積 | BQ1: 7一 | BR1: 7二 | BS1: 7三 | BT1: 7四 | BU1: 7五 | BV1: 7六 | BW1: 7七 | BX1: 7積 | BZ1: 8一 | CA1: 8二 | CB1: 8三 | CC1: 8四 | CD1: 8五 | CE1: 8六 | CF1: 8七 | CG1: 8積 | CI1: 9一 | CJ1: 9二 | CK1: 9三 | CL1: 9四 | CM1: 9五 | CN1: 9六 | CO1: 9七 | CP1: 9積 | CR1: 10一 | CS1: 10二 | CT1: 10三 | CU1: 10四 | CV1: 10五 | CW1: 10六 | CX1: 10七 | CY1: 10積 | DA1: 11一 | DB1: 11二 | DC1: 11三 | DD1: 11四 | DE1: 11五 | DF1: 11六 | DG1: 11七 | DH1: 11積 | DJ1: 12一 | DK1: 12二 | DL1: 12三 | DM1: 12四 | DN1: 12五 | DO1: 12六 | DP1: 12七 | DQ1: 12積 | DS1: 13一 | DT1: 13二 | DU1: 13三 | DV1: 13四 | DW1: 13五 | DX1: 13六 | DY1: 13七 | DZ1: 13積 | EB1: 14一 | EC1: 14二 | ED1: 14三 | EE1: 14四 | EF1: 14五 | EG1: 14六 | EH1: 14七 | EI1: 14積 | EK1: 15一 | EL1: 15二 | EM1: 15三 | EN1: 15四 | EO1: 15五 | EP1: 15六 | EQ1: 15七 | ER1: 15積 | ET1: 16一 | EU1: 16二 | EV1: 16三 | EW1: 16四 | EX1: 16五 | EY1: 16六 | EZ1: 16七 | FA1: 16積 | FC1: 17一 | FD1: 17二 | FE1: 17三 | FF1: 17四 | FG1: 17五 | FH1: 17六 | FI1: 17七 | FJ1: 17積 | FL1: 18一 | FM1: 18二 | FN1: 18三 | FO1: 18四 | FP1: 18五 | FQ1: 18六 | FR1: 18七 | FS1: 18積 | FU1: 19一 | FV1: 19二 | FW1: 19三 | FX1: 19四 | FY1: 19五 | FZ1: 19六 | GA1: 19七 | GB1: 19積 | GD1: 20一 | GE1: 20二 | GF1: 20三 | GG1: 20四 | GH1: 20五 | GI1: 20六 | GJ1: 20七 | GK1: 20積 | GM1: 21一 | GN1: 21二 | GO1: 21三 | GP1: 21四 | GQ1: 21五 | GR1: 21六 | GS1: 21七 | GT1: 21積 | GV1: 22一 | GW1: 22二 | GX1: 22三 | GY1: 22四 | GZ1: 22五 | HA1: 22六 | HB1: 22七 | HC1: 22積 | HE1: 23一 | HF1: 23二 | HG1: 23三 | HH1: 23四 | HI1: 23五 | HJ1: 23六 | HK1: 23七 | HL1: 23積 | HN1: 24一 | HO1: 24二 | HP1: 24三 | HQ1: 24四 | HR1: 24五 | HS1: 24六 | HT1: 24七 | HU1: 24積 | HW1: 25一 | HX1: 25二 | HY1: 25三 | HZ1: 25四 | IA1: 25五 | IB1: 25六 | IC1: 25七 | ID1: 25積 | IF1: 26一 | IG1: 26二 | IH1: 26三 | II1: 26四 | IJ1: 26五 | IK1: 26六 | IL1: 26七 | IM1: 26積 | IO1: 27一 | IP1: 27二 | IQ1: 27三 | IR1: 27四 | IS1: 27五 | IT1: 27六 | IU1: 27七 | IV1: 27積 | IX1: 28一 | IY1: 28二 | IZ1: 28三 | JA1: 28四 | JB1: 28五 | JC1: 28六 | JD1: 28七 | JE1: 28積 | JG1: 29一 | JH1: 29二 | JI1: 29三 | JJ1: 29四 | JK1: 29五 | JL1: 29六 | JM1: 29七 | JN1: 29積 | JP1: 30一 | JQ1: 30二 | JR1: 30三 | JS1: 30四 | JT1: 30五 | JU1: 30六 | JV1: 30七 | JW1: 30積 | JY1: 31一 | JZ1: 31二 | KA1: 31三 | KB1: 31四 | KC1: 31五 | KD1: 31六 | KE1: 31七 | KF1: 31積 | KH1: 32一 | KI1: 32二 | KJ1: 32三 | KK1: 32四 | KL1: 32五 | KM1: 32六 | KN1: 32七 | KO1: 32積 | KQ1: 33一 | KR1: 33二 | KS1: 33三 | KT1: 33四 | KU1: 33五 | KV1: 33六 | KW1: 33七 | KX1: 33積 | KZ1: 34一 | LA1: 34二 | LB1: 34三 | LC1: 34四 | LD1: 34五 | LE1: 34六 | LF1: 34七 | LG1: 34積 | LI1: 35一 | LJ1: 35二 | LK1: 35三 | LL1: 35四 | LM1: 35五 | LN1: 35六 | LO1: 35七 | LP1: 35積 | LR1: 36一 | LS1: 36二 | LT1: 36三 | LU1: 36四 | LV1: 36五 | LW1: 36六 | LX1: 36七 | LY1: 36積 | MA1: 37一 | MB1: 37二 | MC1: 37三 | MD1: 37四 | ME1: 37五 | MF1: 37六 | MG1: 37七 | MH1: 37積 | MJ1: 38一 | MK1: 38二 | ML1: 38三 | MM1: 38四 | MN1: 38五 | MO1: 38六 | MP1: 38七 | MQ1: 38積 | MS1: 39一 | MT1: 39二 | MU1: 39三 | MV1: 39四 | MW1: 39五 | MX1: 39六 | MY1: 39七 | MZ1: 39積 | NB1: 40一 | NC1: 40二 | ND1: 40三 | NE1: 40四 | NF1: 40五 | NG1: 40六 | NH1: 40七 | NI1: 40積 | NK1: 41一 | NL1: 41二 | NM1: 41三 | NN1: 41四 | NO1: 41五 | NP1: 41六 | NQ1: 41七 | NR1: 41積 | NT1: 42一 | NU1: 42二 | NV1: 42三 | NW1: 42四 | NX1: 42五 | NY1: 42六 | NZ1: 42七 | OA1: 42積 | OC1: 43一 | OD1: 43二 | OE1: 43三 | OF1: 43四 | OG1: 43五 | OH1: 43六 | OI1: 43七 | OJ1: 43積 | OL1: 44一 | OM1: 44二 | ON1: 44三 | OO1: 44四 | OP1: 44五 | OQ1: 44六 | OR1: 44七 | OS1: 44積 | OU1: 45一 | OV1: 45二 | OW1: 45三 | OX1: 45四 | OY1: 45五 | OZ1: 45六 | PA1: 45七 | PB1: 45積 | PD1: 46一 | PE1: 46二 | PF1: 46三 | PG1: 46四 | PH1: 46五 | PI1: 46六 | PJ1: 46七 | PK1: 46積 | PM1: 47一 | PN1: 47二 | PO1: 47三 | PP1: 47四 | PQ1: 47五 | PR1: 47六 | PS1: 47七 | PT1: 47積 | PV1: 48一 | PW1: 48二 | PX1: 48三 | PY1: 48四 | PZ1: 48五 | QA1: 48六 | QB1: 48七 | QC1: 48積 | QE1: 49一 | QF1: 49二 | QG1: 49三 | QH1: 49四 | QI1: 49五 | QJ1: 49六 | QK1: 49七 | QL1: 49積 | QN1: 50一 | QO1: 50二 | QP1: 50三 | QQ1: 50四 | QR1: 50五 | QS1: 50六 | QT1: 50七 | QU1: 50積 | QW1: 51一 | QX1: 51二 | QY1: 51三 | QZ1: 51四 | RA1: 51五 | RB1: 51六 | RC1: 51七 | RD1: 51積 | RF1: 52一 | RG1: 52二 | RH1: 52三 | RI1: 52四 | RJ1: 52五 | RK1: 52六 | RL1: 52七 | RM1: 52積 | RO1: 53一 | RP1: 53二 | RQ1: 53三 | RR1: 53四 | RS1: 53五 | RT1: 53六 | RU1: 53七 | RV1: 53積 | RX1: 54一 | RY1: 54二 | RZ1: 54三 | SA1: 54四 | SB1: 54五 | SC1: 54六 | SD1: 54七 | SE1: 54積 | SG1: 55一 | SH1: 55二 | SI1: 55三 | SJ1: 55四 | SK1: 55五 | SL1: 55六 | SM1: 55七 | SN1: 55積 | SP1: 56一 | SQ1: 56二 | SR1: 56三 | SS1: 56四 | ST1: 56五 | SU1: 56六 | SV1: 56七 | SW1: 56積 | SY1: 57一 | SZ1: 57二 | TA1: 57三 | TB1: 57四 | TC1: 57五 | TD1: 57六 | TE1: 57七 | TF1: 57積 | TH1: 58一 | TI1: 58二 | TJ1: 58三 | TK1: 58四 | TL1: 58五 | TM1: 58六 | TN1: 58七 | TO1: 58積 | TQ1: 59一 | TR1: 59二 | TS1: 59三 | TT1: 59四 | TU1: 59五 | TV1: 59六 | TW1: 59七 | TX1: 59積 | TZ1: 60一 | UA1: 60二 | UB1: 60三 | UC1: 60四 | UD1: 60五 | UE1: 60六 | UF1: 60七 | UG1: 60積 | UI1: 61一 | UJ1: 61二 | UK1: 61三 | UL1: 61四 | UM1: 61五 | UN1: 61六 | UO1: 61七 | UP1: 61積 | UR1: 62一 | US1: 62二 | UT1: 62三 | UU1: 62四 | UV1: 62五 | UW1: 62六 | UX1: 62七 | UY1: 62積 | VA1: 63一 | VB1: 63二 | VC1: 63三 | VD1: 63四 | VE1: 63五 | VF1: 63六 | VG1: 63七 | VH1: 63積 | VJ1: 64一 | VK1: 64二 | VL1: 64三 | VM1: 64四 | VN1: 64五 | VO1: 64六 | VP1: 64七 | VQ1: 64積 | VS1: 65一 | VT1: 65二 | VU1: 65三 | VV1: 65四 | VW1: 65五 | VX1: 65六 | VY1: 65七 | VZ1: 65積 | WB1: 66一 | WC1: 66二 | WD1: 66三 | WE1: 66四 | WF1: 66五 | WG1: 66六 | WH1: 66七 | WI1: 66積 | WK1: 67一 | WL1: 67二 | WM1: 67三 | WN1: 67四 | WO1: 67五 | WP1: 67六 | WQ1: 67七 | WR1: 67積 | WT1: 68一 | WU1: 68二 | WV1: 68三 | WW1: 68四 | WX1: 68五 | WY1: 68六 | WZ1: 68七 | XA1: 68積 | XC1: 69一 | XD1: 69二 | XE1: 69三 | XF1: 69四 | XG1: 69五 | XH1: 69六 | XI1: 69七 | XJ1: 69積 | XL1: 70一 | XM1: 70二 | XN1: 70三 | XO1: 70四 | XP1: 70五 | XQ1: 70六 | XR1: 70七 | XS1: 70積 | XU1: 71一 | XV1: 71二 | XW1: 71三 | XX1: 71四 | XY1: 71五 | XZ1: 71六 | YA1: 71七 | YB1: 71積 | YD1: 72一 | YE1: 72二 | YF1: 72三 | YG1: 72四 | YH1: 72五 | YI1: 72六 | YJ1: 72七 | YK1: 72積 | YM1: 73一 | YN1: 73二 | YO1: 73三 | YP1: 73四 | YQ1: 73五 | YR1: 73六 | YS1: 73七 | YT1: 73積 | YV1: 74一 | YW1: 74二 | YX1: 74三 | YY1: 74四 | YZ1: 74五 | ZA1: 74六 | ZB1: 74七 | ZC1: 74積 | ZE1: 75一 | ZF1: 75二 | ZG1: 75三 | ZH1: 75四 | ZI1: 75五 | ZJ1: 75六 | ZK1: 75七 | ZL1: 75積 | ZN1: 76一 | ZO1: 76二 | ZP1: 76三 | ZQ1: 76四 | ZR1: 76五 | ZS1: 76六 | ZT1: 76七 | ZU1: 76積 | ZW1: 77一 | ZX1: 77二 | ZY1: 77三 | ZZ1: 77四 | AAA1: 77五 | AAB1: 77六 | AAC1: 77七 | AAD1: 77積 | AAF1: 78一 | AAG1: 78二 | AAH1: 78三 | AAI1: 78四 | AAJ1: 78五 | AAK1: 78六 | AAL1: 78七 | AAM1: 78積 | AAO1: 79一 | AAP1: 79二 | AAQ1: 79三 | AAR1: 79四 | AAS1: 79五 | AAT1: 79六 | AAU1: 79七 | AAV1: 79積 | AAX1: 80一 | AAY1: 80二 | AAZ1: 80三 | ABA1: 80四 | ABB1: 80五 | ABC1: 80六 | ABD1: 80七 | ABE1: 80積 | ABG1: 裁判名次 | ABH1: R一 | ABI1: R二 | ABJ1: R三 | ABK1: R四 | ABL1: R五 | ABM1: R六 | ABN1: R七 | ABO1: 扣去未到 | ABP1: R一 | ABQ1: R二 | ABR1: R三 | ABS1: R四 | ABT1: R五 | ABU1: R六 | ABV1: R七 | ABW1: 積分 | ABX1: 名次 | ABY1: O一 | ABZ1: O二 | ACA1: O三 | ACB1: O四 | ACC1: O五 | ACD1: O六 | ACE1: O七 | ACF1: 總平均分
A2: 1 | B2: ='(1) 成績輸入'!D10 -> 88 | C2: ='(1) 成績輸入'!E10 -> 85 | D2: ='(1) 成績輸入'!F10 -> 90 | E2: ='(1) 成績輸入'!G10 -> 81 | F2: ='(1) 成績輸入'!H10 -> 0 | G2: ='(1) 成績輸入'!I10 -> 0 | H2: ='(1) 成績輸入'!J10 -> 0 | I2: =V82 -> 79 | J2: =I2-$L$83 -> 4 | K2: =RANK(I2,$I$2:$I$81) -> 1 | L2: =IF(SUM(B2:H2)>0,1,0) -> 1 | M2: =SUM(B2:H2)/$B$83 -> 86 | O2: =IF(B$2=B2,0.5,IF(B$2>B2,1,0)) -> 0.5 | P2: =IF(C$2=C2,0.5,IF(C$2>C2,1,0)) -> 0.5 | Q2: =IF(D$2=D2,0.5,IF(D$2>D2,1,0)) -> 0.5 | R2: =IF(E$2=E2,0.5,IF(E$2>E2,1,0)) -> 0.5 | S2: =IF(F$2=F2,0.5,IF(F$2>F2,1,0)) -> 0.5 | T2: =IF(G$2=G2,0.5,IF(G$2>G2,1,0)) -> 0.5 | U2: =IF(H$2=H2,0.5,IF(H$2>H2,1,0)) -> 0.5 | V2: =IF(SUM(O2:U2)=$K$82,0.5,IF(SUM(O2:U2)>$K$82,1,0)) -> 0.5 | X2: =IF(B$3=B2,0.5,IF(B$3>B2,1,0)) -> 0 | Y2: =IF(C$3=C2,0.5,IF(C$3>C2,1,0)) -> 0 | Z2: =IF(D$3=D2,0.5,IF(D$3>D2,1,0)) -> 0.5 | AA2: =IF(E$3=E2,0.5,IF(E$3>E2,1,0)) -> 1 | AB2: =IF(F$3=F2,0.5,IF(F$3>F2,1,0)) -> 0.5 | AC2: =IF(G$3=G2,0.5,IF(G$3>G2,1,0)) -> 0.5 | AD2: =IF(H$3=H2,0.5,IF(H$3>H2,1,0)) -> 0.5 | AE2: =IF(SUM(X2:AD2)=$K$82,0.5,IF(SUM(X2:AD2)>$K$82,1,0)) -> 0 | AG2: =IF(B$4=B2,0.5,IF(B$4>B2,1,0)) -> 0 | AH2: =IF(C$4=C2,0.5,IF(C$4>C2,1,0)) -> 0 | AI2: =IF(D$4=D2,0.5,IF(D$4>D2,1,0)) -> 0 | AJ2: =IF(E$4=E2,0.5,IF(E$4>E2,1,0)) -> 0 | AK2: =IF(F$4=F2,0.5,IF(F$4>F2,1,0)) -> 0.5 | AL2: =IF(G$4=G2,0.5,IF(G$4>G2,1,0)) -> 0.5 | AM2: =IF(H$4=H2,0.5,IF(H$4>H2,1,0)) -> 0.5 | AN2: =IF(SUM(AG2:AM2)=$K$82,0.5,IF(SUM(AG2:AM2)>$K$82,1,0)) -> 0 | AP2: =IF(B$5=B2,0.5,IF(B$5>B2,1,0)) -> 0 | AQ2: =IF(C$5=C2,0.5,IF(C$5>C2,1,0)) -> 0 | AR2: =IF(D$5=D2,0.5,IF(D$5>D2,1,0)) -> 0 | AS2: =IF(E$5=E2,0.5,IF(E$5>E2,1,0)) -> 1 | AT2: =IF(F$5=F2,0.5,IF(F$5>F2,1,0)) -> 0.5 | AU2: =IF(G$5=G2,0.5,IF(G$5>G2,1,0)) -> 0.5 | AV2: =IF(H$5=H2,0.5,IF(H$5>H2,1,0)) -> 0.5 | AW2: =IF(SUM(AP2:AV2)=$K$82,0.5,IF(SUM(AP2:AV2)>$K$82,1,0)) -> 0 | AY2: =IF(B$6=B2,0.5,IF(B$6>B2,1,0)) -> 0 | AZ2: =IF(C$6=C2,0.5,IF(C$6>C2,1,0)) -> 0 | BA2: =IF(D$6=D2,0.5,IF(D$6>D2,1,0)) -> 0 | BB2: =IF(E$6=E2,0.5,IF(E$6>E2,1,0)) -> 1 | BC2: =IF(F$6=F2,0.5,IF(F$6>F2,1,0)) -> 0.5 | BD2: =IF(G$6=G2,0.5,IF(G$6>G2,1,0)) -> 0.5 | BE2: =IF(H$6=H2,0.5,IF(H$6>H2,1,0)) -> 0.5 | BF2: =IF(SUM(AY2:BE2)=$K$82,0.5,IF(SUM(AY2:BE2)>$K$82,1,0)) -> 0 | BH2: =IF(B$7=B2,0.5,IF(B$7>B2,1,0)) -> 0 | BI2: =IF(C$7=C2,0.5,IF(C$7>C2,1,0)) -> 0 | BJ2: =IF(D$7=D2,0.5,IF(D$7>D2,1,0)) -> 0 | BK2: =IF(E$7=E2,0.5,IF(E$7>E2,1,0)) -> 0 | BL2: =IF(F$7=F2,0.5,IF(F$7>F2,1,0)) -> 0.5 | BM2: =IF(G$7=G2,0.5,IF(G$7>G2,1,0)) -> 0.5 | BN2: =IF(H$7=H2,0.5,IF(H$7>H2,1,0)) -> 0.5 | BO2: =IF(SUM(BH2:BN2)=$K$82,0.5,IF(SUM(BH2:BN2)>$K$82,1,0)) -> 0 | BQ2: =IF(B$8=B2,0.5,IF(B$8>B2,1,0)) -> 0 | BR2: =IF(C$8=C2,0.5,IF(C$8>C2,1,0)) -> 0 | BS2: =IF(D$8=D2,0.5,IF(D$8>D2,1,0)) -> 0 | BT2: =IF(E$8=E2,0.5,IF(E$8>E2,1,0)) -> 0 | BU2: =IF(F$8=F2,0.5,IF(F$8>F2,1,0)) -> 0.5 | BV2: =IF(G$8=G2,0.5,IF(G$8>G2,1,0)) -> 0.5 | BW2: =IF(H$8=H2,0.5,IF(H$8>H2,1,0)) -> 0.5 | BX2: =IF(SUM(BQ2:BW2)=$K$82,0.5,IF(SUM(BQ2:BW2)>$K$82,1,0)) -> 0 | BZ2: =IF(B$9=B2,0.5,IF(B$9>B2,1,0)) -> 0 | CA2: =IF(C$9=C2,0.5,IF(C$9>C2,1,0)) -> 0 | CB2: =IF(D$9=D2,0.5,IF(D$9>D2,1,0)) -> 0 | CC2: =IF(E$9=E2,0.5,IF(E$9>E2,1,0)) -> 0 | CD2: =IF(F$9=F2,0.5,IF(F$9>F2,1,0)) -> 0.5 | CE2: =IF(G$9=G2,0.5,IF(G$9>G2,1,0)) -> 0.5 | CF2: =IF(H$9=H2,0.5,IF(H$9>H2,1,0)) -> 0.5 | CG2: =IF(SUM(BZ2:CF2)=$K$82,0.5,IF(SUM(BZ2:CF2)>$K$82,1,0)) -> 0 | CI2: =IF(B$10=B2,0.5,IF(B$10>B2,1,0)) -> 0 | CJ2: =IF(C$10=C2,0.5,IF(C$10>C2,1,0)) -> 0 | CK2: =IF(D$10=D2,0.5,IF(D$10>D2,1,0)) -> 0 | CL2: =IF(E$10=E2,0.5,IF(E$10>E2,1,0)) -> 0 | CM2: =IF(F$10=F2,0.5,IF(F$10>F2,1,0)) -> 0.5 | CN2: =IF(G$10=G2,0.5,IF(G$10>G2,1,0)) -> 0.5 | CO2: =IF(H$10=H2,0.5,IF(H$10>H2,1,0)) -> 0.5 | CP2: =IF(SUM(CI2:CO2)=$K$82,0.5,IF(SUM(CI2:CO2)>$K$82,1,0)) -> 0 | CR2: =IF(B$11=B2,0.5,IF(B$11>B2,1,0)) -> 0 | CS2: =IF(C$11=C2,0.5,IF(C$11>C2,1,0)) -> 0 | CT2: =IF(D$11=D2,0.5,IF(D$11>D2,1,0)) -> 0 | CU2: =IF(E$11=E2,0.5,IF(E$11>E2,1,0)) -> 0 | CV2: =IF(F$11=F2,0.5,IF(F$11>F2,1,0)) -> 0.5 | CW2: =IF(G$11=G2,0.5,IF(G$11>G2,1,0)) -> 0.5 | CX2: =IF(H$11=H2,0.5,IF(H$11>H2,1,0)) -> 0.5 | CY2: =IF(SUM(CR2:CX2)=$K$82,0.5,IF(SUM(CR2:CX2)>$K$82,1,0)) -> 0 | DA2: =IF(B$12=B2,0.5,IF(B$12>B2,1,0)) -> 0 | DB2: =IF(C$12=C2,0.5,IF(C$12>C2,1,0)) -> 0 | DC2: =IF(D$12=D2,0.5,IF(D$12>D2,1,0)) -> 0 | DD2: =IF(E$12=E2,0.5,IF(E$12>E2,1,0)) -> 0 | DE2: =IF(F$12=F2,0.5,IF(F$12>F2,1,0)) -> 0.5 | DF2: =IF(G$12=G2,0.5,IF(G$12>G2,1,0)) -> 0.5 | DG2: =IF(H$12=H2,0.5,IF(H$12>H2,1,0)) -> 0.5 | DH2: =IF(SUM(DA2:DG2)=$K$82,0.5,IF(SUM(DA2:DG2)>$K$82,1,0)) -> 0 | DJ2: =IF(B$13=B2,0.5,IF(B$13>B2,1,0)) -> 0 | DK2: =IF(C$13=C2,0.5,IF(C$13>C2,1,0)) -> 0 | DL2: =IF(D$13=D2,0.5,IF(D$13>D2,1,0)) -> 0 | DM2: =IF(E$13=E2,0.5,IF(E$13>E2,1,0)) -> 0 | DN2: =IF(F$13=F2,0.5,IF(F$13>F2,1,0)) -> 0.5 | DO2: =IF(G$13=G2,0.5,IF(G$13>G2,1,0)) -> 0.5 | DP2: =IF(H$13=H2,0.5,IF(H$13>H2,1,0)) -> 0.5 | DQ2: =IF(SUM(DJ2:DP2)=$K$82,0.5,IF(SUM(DJ2:DP2)>$K$82,1,0)) -> 0 | DS2: =IF(B$14=B2,0.5,IF(B$14>B2,1,0)) -> 0 | DT2: =IF(C$14=C2,0.5,IF(C$14>C2,1,0)) -> 0 | DU2: =IF(D$14=D2,0.5,IF(D$14>D2,1,0)) -> 0 | DV2: =IF(E$14=E2,0.5,IF(E$14>E2,1,0)) -> 0 | DW2: =IF(F$14=F2,0.5,IF(F$14>F2,1,0)) -> 0.5 | DX2: =IF(G$14=G2,0.5,IF(G$14>G2,1,0)) -> 0.5 | DY2: =IF(H$14=H2,0.5,IF(H$14>H2,1,0)) -> 0.5 | DZ2: =IF(SUM(DS2:DY2)=$K$82,0.5,IF(SUM(DS2:DY2)>$K$82,1,0)) -> 0 | EB2: =IF(B$15=B2,0.5,IF(B$15>B2,1,0)) -> 0 | EC2: =IF(C$15=C2,0.5,IF(C$15>C2,1,0)) -> 0 | ED2: =IF(D$15=D2,0.5,IF(D$15>D2,1,0)) -> 0 | EE2: =IF(E$15=E2,0.5,IF(E$15>E2,1,0)) -> 0 | EF2: =IF(F$15=F2,0.5,IF(F$15>F2,1,0)) -> 0.5 | EG2: =IF(G$15=G2,0.5,IF(G$15>G2,1,0)) -> 0.5 | EH2: =IF(H$15=H2,0.5,IF(H$15>H2,1,0)) -> 0.5 | EI2: =IF(SUM(EB2:EH2)=$K$82,0.5,IF(SUM(EB2:EH2)>$K$82,1,0)) -> 0 | EK2: =IF(B$16=B2,0.5,IF(B$16>B2,1,0)) -> 0 | EL2: =IF(C$16=C2,0.5,IF(C$16>C2,1,0)) -> 0 | EM2: =IF(D$16=D2,0.5,IF(D$16>D2,1,0)) -> 0 | EN2: =IF(E$16=E2,0.5,IF(E$16>E2,1,0)) -> 0 | EO2: =IF(F$16=F2,0.5,IF(F$16>F2,1,0)) -> 0.5 | EP2: =IF(G$16=G2,0.5,IF(G$16>G2,1,0)) -> 0.5 | EQ2: =IF(H$16=H2,0.5,IF(H$16>H2,1,0)) -> 0.5 | ER2: =IF(SUM(EK2:EQ2)=$K$82,0.5,IF(SUM(EK2:EQ2)>$K$82,1,0)) -> 0 | ET2: =IF(B$17=B2,0.5,IF(B$17>B2,1,0)) -> 0 | EU2: =IF(C$17=C2,0.5,IF(C$17>C2,1,0)) -> 0 | EV2: =IF(D$17=D2,0.5,IF(D$17>D2,1,0)) -> 0 | EW2: =IF(E$17=E2,0.5,IF(E$17>E2,1,0)) -> 0 | EX2: =IF(F$17=F2,0.5,IF(F$17>F2,1,0)) -> 0.5 | EY2: =IF(G$17=G2,0.5,IF(G$17>G2,1,0)) -> 0.5 | EZ2: =IF(H$17=H2,0.5,IF(H$17>H2,1,0)) -> 0.5 | FA2: =IF(SUM(ET2:EZ2)=$K$82,0.5,IF(SUM(ET2:EZ2)>$K$82,1,0)) -> 0 | FC2: =IF(B$18=B2,0.5,IF(B$18>B2,1,0)) -> 0 | FD2: =IF(C$18=C2,0.5,IF(C$18>C2,1,0)) -> 0 | FE2: =IF(D$18=D2,0.5,IF(D$18>D2,1,0)) -> 0 | FF2: =IF(E$18=E2,0.5,IF(E$18>E2,1,0)) -> 0 | FG2: =IF(F$18=F2,0.5,IF(F$18>F2,1,0)) -> 0.5 | FH2: =IF(G$18=G2,0.5,IF(G$18>G2,1,0)) -> 0.5 | FI2: =IF(H$18=H2,0.5,IF(H$18>H2,1,0)) -> 0.5 | FJ2: =IF(SUM(FC2:FI2)=$K$82,0.5,IF(SUM(FC2:FI2)>$K$82,1,0)) -> 0 | FL2: =IF(B$19=B2,0.5,IF(B$19>B2,1,0)) -> 0 | FM2: =IF(C$19=C2,0.5,IF(C$19>C2,1,0)) -> 0 | FN2: =IF(D$19=D2,0.5,IF(D$19>D2,1,0)) -> 0 | FO2: =IF(E$19=E2,0.5,IF(E$19>E2,1,0)) -> 0 | FP2: =IF(F$19=F2,0.5,IF(F$19>F2,1,0)) -> 0.5 | FQ2: =IF(G$19=G2,0.5,IF(G$19>G2,1,0)) -> 0.5 | FR2: =IF(H$19=H2,0.5,IF(H$19>H2,1,0)) -> 0.5 | FS2: =IF(SUM(FL2:FR2)=$K$82,0.5,IF(SUM(FL2:FR2)>$K$82,1,0)) -> 0 | FU2: =IF(B$20=B2,0.5,IF(B$20>B2,1,0)) -> 0 | FV2: =IF(C$20=C2,0.5,IF(C$20>C2,1,0)) -> 0 | FW2: =IF(D$20=D2,0.5,IF(D$20>D2,1,0)) -> 0 | FX2: =IF(E$20=E2,0.5,IF(E$20>E2,1,0)) -> 0 | FY2: =IF(F$20=F2,0.5,IF(F$20>F2,1,0)) -> 0.5 | FZ2: =IF(G$20=G2,0.5,IF(G$20>G2,1,0)) -> 0.5 | GA2: =IF(H$20=H2,0.5,IF(H$20>H2,1,0)) -> 0.5 | GB2: =IF(SUM(FU2:GA2)=$K$82,0.5,IF(SUM(FU2:GA2)>$K$82,1,0)) -> 0 | GD2: =IF(B$21=B2,0.5,IF(B$21>B2,1,0)) -> 0 | GE2: =IF(C$21=C2,0.5,IF(C$21>C2,1,0)) -> 0 | GF2: =IF(D$21=D2,0.5,IF(D$21>D2,1,0)) -> 0 | GG2: =IF(E$21=E2,0.5,IF(E$21>E2,1,0)) -> 0 | GH2: =IF(F$21=F2,0.5,IF(F$21>F2,1,0)) -> 0.5 | GI2: =IF(G$21=G2,0.5,IF(G$21>G2,1,0)) -> 0.5 | GJ2: =IF(H$21=H2,0.5,IF(H$21>H2,1,0)) -> 0.5 | GK2: =IF(SUM(GD2:GJ2)=$K$82,0.5,IF(SUM(GD2:GJ2)>$K$82,1,0)) -> 0 | GM2: =IF(B$22=B2,0.5,IF(B$22>B2,1,0)) -> 0 | GN2: =IF(C$22=C2,0.5,IF(C$22>C2,1,0)) -> 0 | GO2: =IF(D$22=D2,0.5,IF(D$22>D2,1,0)) -> 0 | GP2: =IF(E$22=E2,0.5,IF(E$22>E2,1,0)) -> 0 | GQ2: =IF(F$22=F2,0.5,IF(F$22>F2,1,0)) -> 0.5 | GR2: =IF(G$22=G2,0.5,IF(G$22>G2,1,0)) -> 0.5 | GS2: =IF(H$22=H2,0.5,IF(H$22>H2,1,0)) -> 0.5 | GT2: =IF(SUM(GM2:GS2)=$K$82,0.5,IF(SUM(GM2:GS2)>$K$82,1,0)) -> 0 | GV2: =IF(B$23=B2,0.5,IF(B$23>B2,1,0)) -> 0 | GW2: =IF(C$23=C2,0.5,IF(C$23>C2,1,0)) -> 0 | GX2: =IF(D$23=D2,0.5,IF(D$23>D2,1,0)) -> 0 | GY2: =IF(E$23=E2,0.5,IF(E$23>E2,1,0)) -> 0 | GZ2: =IF(F$23=F2,0.5,IF(F$23>F2,1,0)) -> 0.5 | HA2: =IF(G$23=G2,0.5,IF(G$23>G2,1,0)) -> 0.5 | HB2: =IF(H$23=H2,0.5,IF(H$23>H2,1,0)) -> 0.5 | HC2: =IF(SUM(GV2:HB2)=$K$82,0.5,IF(SUM(GV2:HB2)>$K$82,1,0)) -> 0 | HE2: =IF(B$24=B2,0.5,IF(B$24>B2,1,0)) -> 0 | HF2: =IF(C$24=C2,0.5,IF(C$24>C2,1,0)) -> 0 | HG2: =IF(D$24=D2,0.5,IF(D$24>D2,1,0)) -> 0 | HH2: =IF(E$24=E2,0.5,IF(E$24>E2,1,0)) -> 0 | HI2: =IF(F$24=F2,0.5,IF(F$24>F2,1,0)) -> 0.5 | HJ2: =IF(G$24=G2,0.5,IF(G$24>G2,1,0)) -> 0.5 | HK2: =IF(H$24=H2,0.5,IF(H$24>H2,1,0)) -> 0.5 | HL2: =IF(SUM(HE2:HK2)=$K$82,0.5,IF(SUM(HE2:HK2)>$K$82,1,0)) -> 0 | HN2: =IF(B$25=B2,0.5,IF(B$25>B2,1,0)) -> 0 | HO2: =IF(C$25=C2,0.5,IF(C$25>C2,1,0)) -> 0 | HP2: =IF(D$25=D2,0.5,IF(D$25>D2,1,0)) -> 0 | HQ2: =IF(E$25=E2,0.5,IF(E$25>E2,1,0)) -> 0 | HR2: =IF(F$25=F2,0.5,IF(F$25>F2,1,0)) -> 0.5 | HS2: =IF(G$25=G2,0.5,IF(G$25>G2,1,0)) -> 0.5 | HT2: =IF(H$25=H2,0.5,IF(H$25>H2,1,0)) -> 0.5 | HU2: =IF(SUM(HN2:HT2)=$K$82,0.5,IF(SUM(HN2:HT2)>$K$82,1,0)) -> 0 | HW2: =IF(B$26=B2,0.5,IF(B$26>B2,1,0)) -> 0 | HX2: =IF(C$26=C2,0.5,IF(C$26>C2,1,0)) -> 0 | HY2: =IF(D$26=D2,0.5,IF(D$26>D2,1,0)) -> 0 | HZ2: =IF(E$26=E2,0.5,IF(E$26>E2,1,0)) -> 0 | IA2: =IF(F$26=F2,0.5,IF(F$26>F2,1,0)) -> 0.5 | IB2: =IF(G$26=G2,0.5,IF(G$26>G2,1,0)) -> 0.5 | IC2: =IF(H$26=H2,0.5,IF(H$26>H2,1,0)) -> 0.5 | ID2: =IF(SUM(HW2:IC2)=$K$82,0.5,IF(SUM(HW2:IC2)>$K$82,1,0)) -> 0 | IF2: =IF(B$27=B2,0.5,IF(B$27>B2,1,0)) -> 0 | IG2: =IF(C$27=C2,0.5,IF(C$27>C2,1,0)) -> 0 | IH2: =IF(D$27=D2,0.5,IF(D$27>D2,1,0)) -> 0 | II2: =IF(E$27=E2,0.5,IF(E$27>E2,1,0)) -> 0 | IJ2: =IF(F$27=F2,0.5,IF(F$27>F2,1,0)) -> 0.5 | IK2: =IF(G$27=G2,0.5,IF(G$27>G2,1,0)) -> 0.5 | IL2: =IF(H$27=H2,0.5,IF(H$27>H2,1,0)) -> 0.5 | IM2: =IF(SUM(IF2:IL2)=$K$82,0.5,IF(SUM(IF2:IL2)>$K$82,1,0)) -> 0 | IO2: =IF(B$28=B2,0.5,IF(B$28>B2,1,0)) -> 0 | IP2: =IF(C$28=C2,0.5,IF(C$28>C2,1,0)) -> 0 | IQ2: =IF(D$28=D2,0.5,IF(D$28>D2,1,0)) -> 0 | IR2: =IF(E$28=E2,0.5,IF(E$28>E2,1,0)) -> 0 | IS2: =IF(F$28=F2,0.5,IF(F$28>F2,1,0)) -> 0.5 | IT2: =IF(G$28=G2,0.5,IF(G$28>G2,1,0)) -> 0.5 | IU2: =IF(H$28=H2,0.5,IF(H$28>H2,1,0)) -> 0.5 | IV2: =IF(SUM(IO2:IU2)=$K$82,0.5,IF(SUM(IO2:IU2)>$K$82,1,0)) -> 0 | IX2: =IF(B$29=B2,0.5,IF(B$29>B2,1,0)) -> 0 | IY2: =IF(C$29=C2,0.5,IF(C$29>C2,1,0)) -> 0 | IZ2: =IF(D$29=D2,0.5,IF(D$29>D2,1,0)) -> 0 | JA2: =IF(E$29=E2,0.5,IF(E$29>E2,1,0)) -> 0 | JB2: =IF(F$29=F2,0.5,IF(F$29>F2,1,0)) -> 0.5 | JC2: =IF(G$29=G2,0.5,IF(G$29>G2,1,0)) -> 0.5 | JD2: =IF(H$29=H2,0.5,IF(H$29>H2,1,0)) -> 0.5 | JE2: =IF(SUM(IX2:JD2)=$K$82,0.5,IF(SUM(IX2:JD2)>$K$82,1,0)) -> 0 | JG2: =IF(B$30=B2,0.5,IF(B$30>B2,1,0)) -> 0 | JH2: =IF(C$30=C2,0.5,IF(C$30>C2,1,0)) -> 0 | JI2: =IF(D$30=D2,0.5,IF(D$30>D2,1,0)) -> 0 | JJ2: =IF(E$30=E2,0.5,IF(E$30>E2,1,0)) -> 0 | JK2: =IF(F$30=F2,0.5,IF(F$30>F2,1,0)) -> 0.5 | JL2: =IF(G$30=G2,0.5,IF(G$30>G2,1,0)) -> 0.5 | JM2: =IF(H$30=H2,0.5,IF(H$30>H2,1,0)) -> 0.5 | JN2: =IF(SUM(JG2:JM2)=$K$82,0.5,IF(SUM(JG2:JM2)>$K$82,1,0)) -> 0 | JP2: =IF(B$31=B2,0.5,IF(B$31>B2,1,0)) -> 0 | JQ2: =IF(C$31=C2,0.5,IF(C$31>C2,1,0)) -> 0 | JR2: =IF(D$31=D2,0.5,IF(D$31>D2,1,0)) -> 0 | JS2: =IF(E$31=E2,0.5,IF(E$31>E2,1,0)) -> 0 | JT2: =IF(F$31=F2,0.5,IF(F$31>F2,1,0)) -> 0.5 | JU2: =IF(G$31=G2,0.5,IF(G$31>G2,1,0)) -> 0.5 | JV2: =IF(H$31=H2,0.5,IF(H$31>H2,1,0)) -> 0.5 | JW2: =IF(SUM(JP2:JV2)=$K$82,0.5,IF(SUM(JP2:JV2)>$K$82,1,0)) -> 0 | JY2: =IF(B$32=B2,0.5,IF(B$32>B2,1,0)) -> 0 | JZ2: =IF(C$32=C2,0.5,IF(C$32>C2,1,0)) -> 0 | KA2: =IF(D$32=D2,0.5,IF(D$32>D2,1,0)) -> 0 | KB2: =IF(E$32=E2,0.5,IF(E$32>E2,1,0)) -> 0 | KC2: =IF(F$32=F2,0.5,IF(F$32>F2,1,0)) -> 0.5 | KD2: =IF(G$32=G2,0.5,IF(G$32>G2,1,0)) -> 0.5 | KE2: =IF(H$32=H2,0.5,IF(H$32>H2,1,0)) -> 0.5 | KF2: =IF(SUM(JY2:KE2)=$K$82,0.5,IF(SUM(JY2:KE2)>$K$82,1,0)) -> 0 | KH2: =IF(B$33=B2,0.5,IF(B$33>B2,1,0)) -> 0 | KI2: =IF(C$33=C2,0.5,IF(C$33>C2,1,0)) -> 0 | KJ2: =IF(D$33=D2,0.5,IF(D$33>D2,1,0)) -> 0 | KK2: =IF(E$33=E2,0.5,IF(E$33>E2,1,0)) -> 0 | KL2: =IF(F$33=F2,0.5,IF(F$33>F2,1,0)) -> 0.5 | KM2: =IF(G$33=G2,0.5,IF(G$33>G2,1,0)) -> 0.5 | KN2: =IF(H$33=H2,0.5,IF(H$33>H2,1,0)) -> 0.5 | KO2: =IF(SUM(KH2:KN2)=$K$82,0.5,IF(SUM(KH2:KN2)>$K$82,1,0)) -> 0 | KQ2: =IF(B$34=B2,0.5,IF(B$34>B2,1,0)) -> 0 | KR2: =IF(C$34=C2,0.5,IF(C$34>C2,1,0)) -> 0 | KS2: =IF(D$34=D2,0.5,IF(D$34>D2,1,0)) -> 0 | KT2: =IF(E$34=E2,0.5,IF(E$34>E2,1,0)) -> 0 | KU2: =IF(F$34=F2,0.5,IF(F$34>F2,1,0)) -> 0.5 | KV2: =IF(G$34=G2,0.5,IF(G$34>G2,1,0)) -> 0.5 | KW2: =IF(H$34=H2,0.5,IF(H$34>H2,1,0)) -> 0.5 | KX2: =IF(SUM(KQ2:KW2)=$K$82,0.5,IF(SUM(KQ2:KW2)>$K$82,1,0)) -> 0 | KZ2: =IF(B$35=B2,0.5,IF(B$35>B2,1,0)) -> 0 | LA2: =IF(C$35=C2,0.5,IF(C$35>C2,1,0)) -> 0 | LB2: =IF(D$35=D2,0.5,IF(D$35>D2,1,0)) -> 0 | LC2: =IF(E$35=E2,0.5,IF(E$35>E2,1,0)) -> 0 | LD2: =IF(F$35=F2,0.5,IF(F$35>F2,1,0)) -> 0.5 | LE2: =IF(G$35=G2,0.5,IF(G$35>G2,1,0)) -> 0.5 | LF2: =IF(H$35=H2,0.5,IF(H$35>H2,1,0)) -> 0.5 | LG2: =IF(SUM(KZ2:LF2)=$K$82,0.5,IF(SUM(KZ2:LF2)>$K$82,1,0)) -> 0 | LI2: =IF(B$36=B2,0.5,IF(B$36>B2,1,0)) -> 0 | LJ2: =IF(C$36=C2,0.5,IF(C$36>C2,1,0)) -> 0 | LK2: =IF(D$36=D2,0.5,IF(D$36>D2,1,0)) -> 0 | LL2: =IF(E$36=E2,0.5,IF(E$36>E2,1,0)) -> 0 | LM2: =IF(F$36=F2,0.5,IF(F$36>F2,1,0)) -> 0.5 | LN2: =IF(G$36=G2,0.5,IF(G$36>G2,1,0)) -> 0.5 | LO2: =IF(H$36=H2,0.5,IF(H$36>H2,1,0)) -> 0.5 | LP2: =IF(SUM(LI2:LO2)=$K$82,0.5,IF(SUM(LI2:LO2)>$K$82,1,0)) -> 0 | LR2: =IF(B$37=B2,0.5,IF(B$37>B2,1,0)) -> 0 | LS2: =IF(C$37=C2,0.5,IF(C$37>C2,1,0)) -> 0 | LT2: =IF(D$37=D2,0.5,IF(D$37>D2,1,0)) -> 0 | LU2: =IF(E$37=E2,0.5,IF(E$37>E2,1,0)) -> 0 | LV2: =IF(F$37=F2,0.5,IF(F$37>F2,1,0)) -> 0.5 | LW2: =IF(G$37=G2,0.5,IF(G$37>G2,1,0)) -> 0.5 | LX2: =IF(H$37=H2,0.5,IF(H$37>H2,1,0)) -> 0.5 | LY2: =IF(SUM(LR2:LX2)=$K$82,0.5,IF(SUM(LR2:LX2)>$K$82,1,0)) -> 0 | MA2: =IF(B$38=B2,0.5,IF(B$38>B2,1,0)) -> 0 | MB2: =IF(C$38=C2,0.5,IF(C$38>C2,1,0)) -> 0 | MC2: =IF(D$38=D2,0.5,IF(D$38>D2,1,0)) -> 0 | MD2: =IF(E$38=E2,0.5,IF(E$38>E2,1,0)) -> 0 | ME2: =IF(F$38=F2,0.5,IF(F$38>F2,1,0)) -> 0.5 | MF2: =IF(G$38=G2,0.5,IF(G$38>G2,1,0)) -> 0.5 | MG2: =IF(H$38=H2,0.5,IF(H$38>H2,1,0)) -> 0.5 | MH2: =IF(SUM(MA2:MG2)=$K$82,0.5,IF(SUM(MA2:MG2)>$K$82,1,0)) -> 0 | MJ2: =IF(B$39=B2,0.5,IF(B$39>B2,1,0)) -> 0 | MK2: =IF(C$39=C2,0.5,IF(C$39>C2,1,0)) -> 0 | ML2: =IF(D$39=D2,0.5,IF(D$39>D2,1,0)) -> 0 | MM2: =IF(E$39=E2,0.5,IF(E$39>E2,1,0)) -> 0 | MN2: =IF(F$39=F2,0.5,IF(F$39>F2,1,0)) -> 0.5 | MO2: =IF(G$39=G2,0.5,IF(G$39>G2,1,0)) -> 0.5 | MP2: =IF(H$39=H2,0.5,IF(H$39>H2,1,0)) -> 0.5 | MQ2: =IF(SUM(MJ2:MP2)=$K$82,0.5,IF(SUM(MJ2:MP2)>$K$82,1,0)) -> 0 | MS2: =IF(B$40=B2,0.5,IF(B$40>B2,1,0)) -> 0 | MT2: =IF(C$40=C2,0.5,IF(C$40>C2,1,0)) -> 0 | MU2: =IF(D$40=D2,0.5,IF(D$40>D2,1,0)) -> 0 | MV2: =IF(E$40=E2,0.5,IF(E$40>E2,1,0)) -> 0 | MW2: =IF(F$40=F2,0.5,IF(F$40>F2,1,0)) -> 0.5 | MX2: =IF(G$40=G2,0.5,IF(G$40>G2,1,0)) -> 0.5 | MY2: =IF(H$40=H2,0.5,IF(H$40>H2,1,0)) -> 0.5 | MZ2: =IF(SUM(MS2:MY2)=$K$82,0.5,IF(SUM(MS2:MY2)>$K$82,1,0)) -> 0 | NB2: =IF(B$41=B2,0.5,IF(B$41>B2,1,0)) -> 0 | NC2: =IF(C$41=C2,0.5,IF(C$41>C2,1,0)) -> 0 | ND2: =IF(D$41=D2,0.5,IF(D$41>D2,1,0)) -> 0 | NE2: =IF(E$41=E2,0.5,IF(E$41>E2,1,0)) -> 0 | NF2: =IF(F$41=F2,0.5,IF(F$41>F2,1,0)) -> 0.5 | NG2: =IF(G$41=G2,0.5,IF(G$41>G2,1,0)) -> 0.5 | NH2: =IF(H$41=H2,0.5,IF(H$41>H2,1,0)) -> 0.5 | NI2: =IF(SUM(NB2:NH2)=$K$82,0.5,IF(SUM(NB2:NH2)>$K$82,1,0)) -> 0 | NK2: =IF(B$42=B2,0.5,IF(B$42>B2,1,0)) -> 0 | NL2: =IF(C$42=C2,0.5,IF(C$42>C2,1,0)) -> 0 | NM2: =IF(D$42=D2,0.5,IF(D$42>D2,1,0)) -> 0 | NN2: =IF(E$42=E2,0.5,IF(E$42>E2,1,0)) -> 0 | NO2: =IF(F$42=F2,0.5,IF(F$42>F2,1,0)) -> 0.5 | NP2: =IF(G$42=G2,0.5,IF(G$42>G2,1,0)) -> 0.5 | NQ2: =IF(H$42=H2,0.5,IF(H$42>H2,1,0)) -> 0.5 | NR2: =IF(SUM(NK2:NQ2)=$K$82,0.5,IF(SUM(NK2:NQ2)>$K$82,1,0)) -> 0 | NT2: =IF(B$43=B2,0.5,IF(B$43>B2,1,0)) -> 0 | NU2: =IF(C$43=C2,0.5,IF(C$43>C2,1,0)) -> 0 | NV2: =IF(D$43=D2,0.5,IF(D$43>D2,1,0)) -> 0 | NW2: =IF(E$43=E2,0.5,IF(E$43>E2,1,0)) -> 0 | NX2: =IF(F$43=F2,0.5,IF(F$43>F2,1,0)) -> 0.5 | NY2: =IF(G$43=G2,0.5,IF(G$43>G2,1,0)) -> 0.5 | NZ2: =IF(H$43=H2,0.5,IF(H$43>H2,1,0)) -> 0.5 | OA2: =IF(SUM(NT2:NZ2)=$K$82,0.5,IF(SUM(NT2:NZ2)>$K$82,1,0)) -> 0 | OC2: =IF(B$44=B2,0.5,IF(B$44>B2,1,0)) -> 0 | OD2: =IF(C$44=C2,0.5,IF(C$44>C2,1,0)) -> 0 | OE2: =IF(D$44=D2,0.5,IF(D$44>D2,1,0)) -> 0 | OF2: =IF(E$44=E2,0.5,IF(E$44>E2,1,0)) -> 0 | OG2: =IF(F$44=F2,0.5,IF(F$44>F2,1,0)) -> 0.5 | OH2: =IF(G$44=G2,0.5,IF(G$44>G2,1,0)) -> 0.5 | OI2: =IF(H$44=H2,0.5,IF(H$44>H2,1,0)) -> 0.5 | OJ2: =IF(SUM(OC2:OI2)=$K$82,0.5,IF(SUM(OC2:OI2)>$K$82,1,0)) -> 0 | OL2: =IF(B$45=B2,0.5,IF(B$45>B2,1,0)) -> 0 | OM2: =IF(C$45=C2,0.5,IF(C$45>C2,1,0)) -> 0 | ON2: =IF(D$45=D2,0.5,IF(D$45>D2,1,0)) -> 0 | OO2: =IF(E$45=E2,0.5,IF(E$45>E2,1,0)) -> 0 | OP2: =IF(F$45=F2,0.5,IF(F$45>F2,1,0)) -> 0.5 | OQ2: =IF(G$45=G2,0.5,IF(G$45>G2,1,0)) -> 0.5 | OR2: =IF(H$45=H2,0.5,IF(H$45>H2,1,0)) -> 0.5 | OS2: =IF(SUM(OL2:OR2)=$K$82,0.5,IF(SUM(OL2:OR2)>$K$82,1,0)) -> 0 | OU2: =IF(B$46=B2,0.5,IF(B$46>B2,1,0)) -> 0 | OV2: =IF(C$46=C2,0.5,IF(C$46>C2,1,0)) -> 0 | OW2: =IF(D$46=D2,0.5,IF(D$46>D2,1,0)) -> 0 | OX2: =IF(E$46=E2,0.5,IF(E$46>E2,1,0)) -> 0 | OY2: =IF(F$46=F2,0.5,IF(F$46>F2,1,0)) -> 0.5 | OZ2: =IF(G$46=G2,0.5,IF(G$46>G2,1,0)) -> 0.5 | PA2: =IF(H$46=H2,0.5,IF(H$46>H2,1,0)) -> 0.5 | PB2: =IF(SUM(OU2:PA2)=$K$82,0.5,IF(SUM(OU2:PA2)>$K$82,1,0)) -> 0 | PD2: =IF(B$47=B2,0.5,IF(B$47>B2,1,0)) -> 0 | PE2: =IF(C$47=C2,0.5,IF(C$47>C2,1,0)) -> 0 | PF2: =IF(D$47=D2,0.5,IF(D$47>D2,1,0)) -> 0 | PG2: =IF(E$47=E2,0.5,IF(E$47>E2,1,0)) -> 0 | PH2: =IF(F$47=F2,0.5,IF(F$47>F2,1,0)) -> 0.5 | PI2: =IF(G$47=G2,0.5,IF(G$47>G2,1,0)) -> 0.5 | PJ2: =IF(H$47=H2,0.5,IF(H$47>H2,1,0)) -> 0.5 | PK2: =IF(SUM(PD2:PJ2)=$K$82,0.5,IF(SUM(PD2:PJ2)>$K$82,1,0)) -> 0 | PM2: =IF(B$48=B2,0.5,IF(B$48>B2,1,0)) -> 0 | PN2: =IF(C$48=C2,0.5,IF(C$48>C2,1,0)) -> 0 | PO2: =IF(D$48=D2,0.5,IF(D$48>D2,1,0)) -> 0 | PP2: =IF(E$48=E2,0.5,IF(E$48>E2,1,0)) -> 0 | PQ2: =IF(F$48=F2,0.5,IF(F$48>F2,1,0)) -> 0.5 | PR2: =IF(G$48=G2,0.5,IF(G$48>G2,1,0)) -> 0.5 | PS2: =IF(H$48=H2,0.5,IF(H$48>H2,1,0)) -> 0.5 | PT2: =IF(SUM(PM2:PS2)=$K$82,0.5,IF(SUM(PM2:PS2)>$K$82,1,0)) -> 0 | PV2: =IF(B$49=B2,0.5,IF(B$49>B2,1,0)) -> 0 | PW2: =IF(C$49=C2,0.5,IF(C$49>C2,1,0)) -> 0 | PX2: =IF(D$49=D2,0.5,IF(D$49>D2,1,0)) -> 0 | PY2: =IF(E$49=E2,0.5,IF(E$49>E2,1,0)) -> 0 | PZ2: =IF(F$49=F2,0.5,IF(F$49>F2,1,0)) -> 0.5 | QA2: =IF(G$49=G2,0.5,IF(G$49>G2,1,0)) -> 0.5 | QB2: =IF(H$49=H2,0.5,IF(H$49>H2,1,0)) -> 0.5 | QC2: =IF(SUM(PV2:QB2)=$K$82,0.5,IF(SUM(PV2:QB2)>$K$82,1,0)) -> 0 | QE2: =IF(B$50=B2,0.5,IF(B$50>B2,1,0)) -> 0 | QF2: =IF(C$50=C2,0.5,IF(C$50>C2,1,0)) -> 0 | QG2: =IF(D$50=D2,0.5,IF(D$50>D2,1,0)) -> 0 | QH2: =IF(E$50=E2,0.5,IF(E$50>E2,1,0)) -> 0 | QI2: =IF(F$50=F2,0.5,IF(F$50>F2,1,0)) -> 0.5 | QJ2: =IF(G$50=G2,0.5,IF(G$50>G2,1,0)) -> 0.5 | QK2: =IF(H$50=H2,0.5,IF(H$50>H2,1,0)) -> 0.5 | QL2: =IF(SUM(QE2:QK2)=$K$82,0.5,IF(SUM(QE2:QK2)>$K$82,1,0)) -> 0 | QN2: =IF(B$51=B2,0.5,IF(B$51>B2,1,0)) -> 0 | QO2: =IF(C$51=C2,0.5,IF(C$51>C2,1,0)) -> 0 | QP2: =IF(D$51=D2,0.5,IF(D$51>D2,1,0)) -> 0 | QQ2: =IF(E$51=E2,0.5,IF(E$51>E2,1,0)) -> 0 | QR2: =IF(F$51=F2,0.5,IF(F$51>F2,1,0)) -> 0.5 | QS2: =IF(G$51=G2,0.5,IF(G$51>G2,1,0)) -> 0.5 | QT2: =IF(H$51=H2,0.5,IF(H$51>H2,1,0)) -> 0.5 | QU2: =IF(SUM(QN2:QT2)=$K$82,0.5,IF(SUM(QN2:QT2)>$K$82,1,0)) -> 0 | QW2: =IF(B$52=B2,0.5,IF(B$52>B2,1,0)) -> 0 | QX2: =IF(C$52=C2,0.5,IF(C$52>C2,1,0)) -> 0 | QY2: =IF(D$52=D2,0.5,IF(D$52>D2,1,0)) -> 0 | QZ2: =IF(E$52=E2,0.5,IF(E$52>E2,1,0)) -> 0 | RA2: =IF(F$52=F2,0.5,IF(F$52>F2,1,0)) -> 0.5 | RB2: =IF(G$52=G2,0.5,IF(G$52>G2,1,0)) -> 0.5 | RC2: =IF(H$52=H2,0.5,IF(H$52>H2,1,0)) -> 0.5 | RD2: =IF(SUM(QW2:RC2)=$K$82,0.5,IF(SUM(QW2:RC2)>$K$82,1,0)) -> 0 | RF2: =IF(B$53=B2,0.5,IF(B$53>B2,1,0)) -> 0 | RG2: =IF(C$53=C2,0.5,IF(C$53>C2,1,0)) -> 0 | RH2: =IF(D$53=D2,0.5,IF(D$53>D2,1,0)) -> 0 | RI2: =IF(E$53=E2,0.5,IF(E$53>E2,1,0)) -> 0 | RJ2: =IF(F$53=F2,0.5,IF(F$53>F2,1,0)) -> 0.5 | RK2: =IF(G$53=G2,0.5,IF(G$53>G2,1,0)) -> 0.5 | RL2: =IF(H$53=H2,0.5,IF(H$53>H2,1,0)) -> 0.5 | RM2: =IF(SUM(RF2:RL2)=$K$82,0.5,IF(SUM(RF2:RL2)>$K$82,1,0)) -> 0 | RO2: =IF(B$54=B2,0.5,IF(B$54>B2,1,0)) -> 0 | RP2: =IF(C$54=C2,0.5,IF(C$54>C2,1,0)) -> 0 | RQ2: =IF(D$54=D2,0.5,IF(D$54>D2,1,0)) -> 0 | RR2: =IF(E$54=E2,0.5,IF(E$54>E2,1,0)) -> 0 | RS2: =IF(F$54=F2,0.5,IF(F$54>F2,1,0)) -> 0.5 | RT2: =IF(G$54=G2,0.5,IF(G$54>G2,1,0)) -> 0.5 | RU2: =IF(H$54=H2,0.5,IF(H$54>H2,1,0)) -> 0.5 | RV2: =IF(SUM(RO2:RU2)=$K$82,0.5,IF(SUM(RO2:RU2)>$K$82,1,0)) -> 0 | RX2: =IF(B$55=B2,0.5,IF(B$55>B2,1,0)) -> 0 | RY2: =IF(C$55=C2,0.5,IF(C$55>C2,1,0)) -> 0 | RZ2: =IF(D$55=D2,0.5,IF(D$55>D2,1,0)) -> 0 | SA2: =IF(E$55=E2,0.5,IF(E$55>E2,1,0)) -> 0 | SB2: =IF(F$55=F2,0.5,IF(F$55>F2,1,0)) -> 0.5 | SC2: =IF(G$55=G2,0.5,IF(G$55>G2,1,0)) -> 0.5 | SD2: =IF(H$55=H2,0.5,IF(H$55>H2,1,0)) -> 0.5 | SE2: =IF(SUM(RX2:SD2)=$K$82,0.5,IF(SUM(RX2:SD2)>$K$82,1,0)) -> 0 | SG2: =IF(B$56=B2,0.5,IF(B$56>B2,1,0)) -> 0 | SH2: =IF(C$56=C2,0.5,IF(C$56>C2,1,0)) -> 0 | SI2: =IF(D$56=D2,0.5,IF(D$56>D2,1,0)) -> 0 | SJ2: =IF(E$56=E2,0.5,IF(E$56>E2,1,0)) -> 0 | SK2: =IF(F$56=F2,0.5,IF(F$56>F2,1,0)) -> 0.5 | SL2: =IF(G$56=G2,0.5,IF(G$56>G2,1,0)) -> 0.5 | SM2: =IF(H$56=H2,0.5,IF(H$56>H2,1,0)) -> 0.5 | SN2: =IF(SUM(SG2:SM2)=$K$82,0.5,IF(SUM(SG2:SM2)>$K$82,1,0)) -> 0 | SP2: =IF(B$57=B2,0.5,IF(B$57>B2,1,0)) -> 0 | SQ2: =IF(C$57=C2,0.5,IF(C$57>C2,1,0)) -> 0 | SR2: =IF(D$57=D2,0.5,IF(D$57>D2,1,0)) -> 0 | SS2: =IF(E$57=E2,0.5,IF(E$57>E2,1,0)) -> 0 | ST2: =IF(F$57=F2,0.5,IF(F$57>F2,1,0)) -> 0.5 | SU2: =IF(G$57=G2,0.5,IF(G$57>G2,1,0)) -> 0.5 | SV2: =IF(H$57=H2,0.5,IF(H$57>H2,1,0)) -> 0.5 | SW2: =IF(SUM(SP2:SV2)=$K$82,0.5,IF(SUM(SP2:SV2)>$K$82,1,0)) -> 0 | SY2: =IF(B$58=B2,0.5,IF(B$58>B2,1,0)) -> 0 | SZ2: =IF(C$58=C2,0.5,IF(C$58>C2,1,0)) -> 0 | TA2: =IF(D$58=D2,0.5,IF(D$58>D2,1,0)) -> 0 | TB2: =IF(E$58=E2,0.5,IF(E$58>E2,1,0)) -> 0 | TC2: =IF(F$58=F2,0.5,IF(F$58>F2,1,0)) -> 0.5 | TD2: =IF(G$58=G2,0.5,IF(G$58>G2,1,0)) -> 0.5 | TE2: =IF(H$58=H2,0.5,IF(H$58>H2,1,0)) -> 0.5 | TF2: =IF(SUM(SY2:TE2)=$K$82,0.5,IF(SUM(SY2:TE2)>$K$82,1,0)) -> 0 | TH2: =IF(B$59=B2,0.5,IF(B$59>B2,1,0)) -> 0 | TI2: =IF(C$59=C2,0.5,IF(C$59>C2,1,0)) -> 0 | TJ2: =IF(D$59=D2,0.5,IF(D$59>D2,1,0)) -> 0 | TK2: =IF(E$59=E2,0.5,IF(E$59>E2,1,0)) -> 0 | TL2: =IF(F$59=F2,0.5,IF(F$59>F2,1,0)) -> 0.5 | TM2: =IF(G$59=G2,0.5,IF(G$59>G2,1,0)) -> 0.5 | TN2: =IF(H$59=H2,0.5,IF(H$59>H2,1,0)) -> 0.5 | TO2: =IF(SUM(TH2:TN2)=$K$82,0.5,IF(SUM(TH2:TN2)>$K$82,1,0)) -> 0 | TQ2: =IF(B$60=B2,0.5,IF(B$60>B2,1,0)) -> 0 | TR2: =IF(C$60=C2,0.5,IF(C$60>C2,1,0)) -> 0 | TS2: =IF(D$60=D2,0.5,IF(D$60>D2,1,0)) -> 0 | TT2: =IF(E$60=E2,0.5,IF(E$60>E2,1,0)) -> 0 | TU2: =IF(F$60=F2,0.5,IF(F$60>F2,1,0)) -> 0.5 | TV2: =IF(G$60=G2,0.5,IF(G$60>G2,1,0)) -> 0.5 | TW2: =IF(H$60=H2,0.5,IF(H$60>H2,1,0)) -> 0.5 | TX2: =IF(SUM(TQ2:TW2)=$K$82,0.5,IF(SUM(TQ2:TW2)>$K$82,1,0)) -> 0 | TZ2: =IF(B$61=B2,0.5,IF(B$61>B2,1,0)) -> 0 | UA2: =IF(C$61=C2,0.5,IF(C$61>C2,1,0)) -> 0 | UB2: =IF(D$61=D2,0.5,IF(D$61>D2,1,0)) -> 0 | UC2: =IF(E$61=E2,0.5,IF(E$61>E2,1,0)) -> 0 | UD2: =IF(F$61=F2,0.5,IF(F$61>F2,1,0)) -> 0.5 | UE2: =IF(G$61=G2,0.5,IF(G$61>G2,1,0)) -> 0.5 | UF2: =IF(H$61=H2,0.5,IF(H$61>H2,1,0)) -> 0.5 | UG2: =IF(SUM(TZ2:UF2)=$K$82,0.5,IF(SUM(TZ2:UF2)>$K$82,1,0)) -> 0 | UI2: =IF(B$62=B2,0.5,IF(B$62>B2,1,0)) -> 0 | UJ2: =IF(C$62=C2,0.5,IF(C$62>C2,1,0)) -> 0 | UK2: =IF(D$62=D2,0.5,IF(D$62>D2,1,0)) -> 0 | UL2: =IF(E$62=E2,0.5,IF(E$62>E2,1,0)) -> 0 | UM2: =IF(F$62=F2,0.5,IF(F$62>F2,1,0)) -> 0.5 | UN2: =IF(G$62=G2,0.5,IF(G$62>G2,1,0)) -> 0.5 | UO2: =IF(H$62=H2,0.5,IF(H$62>H2,1,0)) -> 0.5 | UP2: =IF(SUM(UI2:UO2)=$K$82,0.5,IF(SUM(UI2:UO2)>$K$82,1,0)) -> 0 | UR2: =IF(B$63=B2,0.5,IF(B$63>B2,1,0)) -> 0 | US2: =IF(C$63=C2,0.5,IF(C$63>C2,1,0)) -> 0 | UT2: =IF(D$63=D2,0.5,IF(D$63>D2,1,0)) -> 0 | UU2: =IF(E$63=E2,0.5,IF(E$63>E2,1,0)) -> 0 | UV2: =IF(F$63=F2,0.5,IF(F$63>F2,1,0)) -> 0.5 | UW2: =IF(G$63=G2,0.5,IF(G$63>G2,1,0)) -> 0.5 | UX2: =IF(H$63=H2,0.5,IF(H$63>H2,1,0)) -> 0.5 | UY2: =IF(SUM(UR2:UX2)=$K$82,0.5,IF(SUM(UR2:UX2)>$K$82,1,0)) -> 0 | VA2: =IF(B$64=B2,0.5,IF(B$64>B2,1,0)) -> 0 | VB2: =IF(C$64=C2,0.5,IF(C$64>C2,1,0)) -> 0 | VC2: =IF(D$64=D2,0.5,IF(D$64>D2,1,0)) -> 0 | VD2: =IF(E$64=E2,0.5,IF(E$64>E2,1,0)) -> 0 | VE2: =IF(F$64=F2,0.5,IF(F$64>F2,1,0)) -> 0.5 | VF2: =IF(G$64=G2,0.5,IF(G$64>G2,1,0)) -> 0.5 | VG2: =IF(H$64=H2,0.5,IF(H$64>H2,1,0)) -> 0.5 | VH2: =IF(SUM(VA2:VG2)=$K$82,0.5,IF(SUM(VA2:VG2)>$K$82,1,0)) -> 0 | VJ2: =IF(B$65=B2,0.5,IF(B$65>B2,1,0)) -> 0 | VK2: =IF(C$65=C2,0.5,IF(C$65>C2,1,0)) -> 0 | VL2: =IF(D$65=D2,0.5,IF(D$65>D2,1,0)) -> 0 | VM2: =IF(E$65=E2,0.5,IF(E$65>E2,1,0)) -> 0 | VN2: =IF(F$65=F2,0.5,IF(F$65>F2,1,0)) -> 0.5 | VO2: =IF(G$65=G2,0.5,IF(G$65>G2,1,0)) -> 0.5 | VP2: =IF(H$65=H2,0.5,IF(H$65>H2,1,0)) -> 0.5 | VQ2: =IF(SUM(VJ2:VP2)=$K$82,0.5,IF(SUM(VJ2:VP2)>$K$82,1,0)) -> 0 | VS2: =IF(B$66=B2,0.5,IF(B$66>B2,1,0)) -> 0 | VT2: =IF(C$66=C2,0.5,IF(C$66>C2,1,0)) -> 0 | VU2: =IF(D$66=D2,0.5,IF(D$66>D2,1,0)) -> 0 | VV2: =IF(E$66=E2,0.5,IF(E$66>E2,1,0)) -> 0 | VW2: =IF(F$66=F2,0.5,IF(F$66>F2,1,0)) -> 0.5 | VX2: =IF(G$66=G2,0.5,IF(G$66>G2,1,0)) -> 0.5 | VY2: =IF(H$66=H2,0.5,IF(H$66>H2,1,0)) -> 0.5 | VZ2: =IF(SUM(VS2:VY2)=$K$82,0.5,IF(SUM(VS2:VY2)>$K$82,1,0)) -> 0 | WB2: =IF(B$67=B2,0.5,IF(B$67>B2,1,0)) -> 0 | WC2: =IF(C$67=C2,0.5,IF(C$67>C2,1,0)) -> 0 | WD2: =IF(D$67=D2,0.5,IF(D$67>D2,1,0)) -> 0 | WE2: =IF(E$67=E2,0.5,IF(E$67>E2,1,0)) -> 0 | WF2: =IF(F$67=F2,0.5,IF(F$67>F2,1,0)) -> 0.5 | WG2: =IF(G$67=G2,0.5,IF(G$67>G2,1,0)) -> 0.5 | WH2: =IF(H$67=H2,0.5,IF(H$67>H2,1,0)) -> 0.5 | WI2: =IF(SUM(WB2:WH2)=$K$82,0.5,IF(SUM(WB2:WH2)>$K$82,1,0)) -> 0 | WK2: =IF(B$68=B2,0.5,IF(B$68>B2,1,0)) -> 0 | WL2: =IF(C$68=C2,0.5,IF(C$68>C2,1,0)) -> 0 | WM2: =IF(D$68=D2,0.5,IF(D$68>D2,1,0)) -> 0 | WN2: =IF(E$68=E2,0.5,IF(E$68>E2,1,0)) -> 0 | WO2: =IF(F$68=F2,0.5,IF(F$68>F2,1,0)) -> 0.5 | WP2: =IF(G$68=G2,0.5,IF(G$68>G2,1,0)) -> 0.5 | WQ2: =IF(H$68=H2,0.5,IF(H$68>H2,1,0)) -> 0.5 | WR2: =IF(SUM(WK2:WQ2)=$K$82,0.5,IF(SUM(WK2:WQ2)>$K$82,1,0)) -> 0 | WT2: =IF(B$69=B2,0.5,IF(B$69>B2,1,0)) -> 0 | WU2: =IF(C$69=C2,0.5,IF(C$69>C2,1,0)) -> 0 | WV2: =IF(D$69=D2,0.5,IF(D$69>D2,1,0)) -> 0 | WW2: =IF(E$69=E2,0.5,IF(E$69>E2,1,0)) -> 0 | WX2: =IF(F$69=F2,0.5,IF(F$69>F2,1,0)) -> 0.5 | WY2: =IF(G$69=G2,0.5,IF(G$69>G2,1,0)) -> 0.5 | WZ2: =IF(H$69=H2,0.5,IF(H$69>H2,1,0)) -> 0.5 | XA2: =IF(SUM(WT2:WZ2)=$K$82,0.5,IF(SUM(WT2:WZ2)>$K$82,1,0)) -> 0 | XC2: =IF(B$70=B2,0.5,IF(B$70>B2,1,0)) -> 0 | XD2: =IF(C$70=C2,0.5,IF(C$70>C2,1,0)) -> 0 | XE2: =IF(D$70=D2,0.5,IF(D$70>D2,1,0)) -> 0 | XF2: =IF(E$70=E2,0.5,IF(E$70>E2,1,0)) -> 0 | XG2: =IF(F$70=F2,0.5,IF(F$70>F2,1,0)) -> 0.5 | XH2: =IF(G$70=G2,0.5,IF(G$70>G2,1,0)) -> 0.5 | XI2: =IF(H$70=H2,0.5,IF(H$70>H2,1,0)) -> 0.5 | XJ2: =IF(SUM(XC2:XI2)=$K$82,0.5,IF(SUM(XC2:XI2)>$K$82,1,0)) -> 0 | XL2: =IF(B$71=B2,0.5,IF(B$71>B2,1,0)) -> 0 | XM2: =IF(C$71=C2,0.5,IF(C$71>C2,1,0)) -> 0 | XN2: =IF(D$71=D2,0.5,IF(D$71>D2,1,0)) -> 0 | XO2: =IF(E$71=E2,0.5,IF(E$71>E2,1,0)) -> 0 | XP2: =IF(F$71=F2,0.5,IF(F$71>F2,1,0)) -> 0.5 | XQ2: =IF(G$71=G2,0.5,IF(G$71>G2,1,0)) -> 0.5 | XR2: =IF(H$71=H2,0.5,IF(H$71>H2,1,0)) -> 0.5 | XS2: =IF(SUM(XL2:XR2)=$K$82,0.5,IF(SUM(XL2:XR2)>$K$82,1,0)) -> 0 | XU2: =IF(B$72=B2,0.5,IF(B$72>B2,1,0)) -> 0 | XV2: =IF(C$72=C2,0.5,IF(C$72>C2,1,0)) -> 0 | XW2: =IF(D$72=D2,0.5,IF(D$72>D2,1,0)) -> 0 | XX2: =IF(E$72=E2,0.5,IF(E$72>E2,1,0)) -> 0 | XY2: =IF(F$72=F2,0.5,IF(F$72>F2,1,0)) -> 0.5 | XZ2: =IF(G$72=G2,0.5,IF(G$72>G2,1,0)) -> 0.5 | YA2: =IF(H$72=H2,0.5,IF(H$72>H2,1,0)) -> 0.5 | YB2: =IF(SUM(XU2:YA2)=$K$82,0.5,IF(SUM(XU2:YA2)>$K$82,1,0)) -> 0 | YD2: =IF(B$73=B2,0.5,IF(B$73>B2,1,0)) -> 0 | YE2: =IF(C$73=C2,0.5,IF(C$73>C2,1,0)) -> 0 | YF2: =IF(D$73=D2,0.5,IF(D$73>D2,1,0)) -> 0 | YG2: =IF(E$73=E2,0.5,IF(E$73>E2,1,0)) -> 0 | YH2: =IF(F$73=F2,0.5,IF(F$73>F2,1,0)) -> 0.5 | YI2: =IF(G$73=G2,0.5,IF(G$73>G2,1,0)) -> 0.5 | YJ2: =IF(H$73=H2,0.5,IF(H$73>H2,1,0)) -> 0.5 | YK2: =IF(SUM(YD2:YJ2)=$K$82,0.5,IF(SUM(YD2:YJ2)>$K$82,1,0)) -> 0 | YM2: =IF(B$74=B2,0.5,IF(B$74>B2,1,0)) -> 0 | YN2: =IF(C$74=C2,0.5,IF(C$74>C2,1,0)) -> 0 | YO2: =IF(D$74=D2,0.5,IF(D$74>D2,1,0)) -> 0 | YP2: =IF(E$74=E2,0.5,IF(E$74>E2,1,0)) -> 0 | YQ2: =IF(F$74=F2,0.5,IF(F$74>F2,1,0)) -> 0.5 | YR2: =IF(G$74=G2,0.5,IF(G$74>G2,1,0)) -> 0.5 | YS2: =IF(H$74=H2,0.5,IF(H$74>H2,1,0)) -> 0.5 | YT2: =IF(SUM(YM2:YS2)=$K$82,0.5,IF(SUM(YM2:YS2)>$K$82,1,0)) -> 0 | YV2: =IF(B$75=B2,0.5,IF(B$75>B2,1,0)) -> 0 | YW2: =IF(C$75=C2,0.5,IF(C$75>C2,1,0)) -> 0 | YX2: =IF(D$75=D2,0.5,IF(D$75>D2,1,0)) -> 0 | YY2: =IF(E$75=E2,0.5,IF(E$75>E2,1,0)) -> 0 | YZ2: =IF(F$75=F2,0.5,IF(F$75>F2,1,0)) -> 0.5 | ZA2: =IF(G$75=G2,0.5,IF(G$75>G2,1,0)) -> 0.5 | ZB2: =IF(H$75=H2,0.5,IF(H$75>H2,1,0)) -> 0.5 | ZC2: =IF(SUM(YV2:ZB2)=$K$82,0.5,IF(SUM(YV2:ZB2)>$K$82,1,0)) -> 0 | ZE2: =IF(B$76=B2,0.5,IF(B$76>B2,1,0)) -> 0 | ZF2: =IF(C$76=C2,0.5,IF(C$76>C2,1,0)) -> 0 | ZG2: =IF(D$76=D2,0.5,IF(D$76>D2,1,0)) -> 0 | ZH2: =IF(E$76=E2,0.5,IF(E$76>E2,1,0)) -> 0 | ZI2: =IF(F$76=F2,0.5,IF(F$76>F2,1,0)) -> 0.5 | ZJ2: =IF(G$76=G2,0.5,IF(G$76>G2,1,0)) -> 0.5 | ZK2: =IF(H$76=H2,0.5,IF(H$76>H2,1,0)) -> 0.5 | ZL2: =IF(SUM(ZE2:ZK2)=$K$82,0.5,IF(SUM(ZE2:ZK2)>$K$82,1,0)) -> 0 | ZN2: =IF(B$77=B2,0.5,IF(B$77>B2,1,0)) -> 0 | ZO2: =IF(C$77=C2,0.5,IF(C$77>C2,1,0)) -> 0 | ZP2: =IF(D$77=D2,0.5,IF(D$77>D2,1,0)) -> 0 | ZQ2: =IF(E$77=E2,0.5,IF(E$77>E2,1,0)) -> 0 | ZR2: =IF(F$77=F2,0.5,IF(F$77>F2,1,0)) -> 0.5 | ZS2: =IF(G$77=G2,0.5,IF(G$77>G2,1,0)) -> 0.5 | ZT2: =IF(H$77=H2,0.5,IF(H$77>H2,1,0)) -> 0.5 | ZU2: =IF(SUM(ZN2:ZT2)=$K$82,0.5,IF(SUM(ZN2:ZT2)>$K$82,1,0)) -> 0 | ZW2: =IF(B$78=B2,0.5,IF(B$78>B2,1,0)) -> 0 | ZX2: =IF(C$78=C2,0.5,IF(C$78>C2,1,0)) -> 0 | ZY2: =IF(D$78=D2,0.5,IF(D$78>D2,1,0)) -> 0 | ZZ2: =IF(E$78=E2,0.5,IF(E$78>E2,1,0)) -> 0 | AAA2: =IF(F$78=F2,0.5,IF(F$78>F2,1,0)) -> 0.5 | AAB2: =IF(G$78=G2,0.5,IF(G$78>G2,1,0)) -> 0.5 | AAC2: =IF(H$78=H2,0.5,IF(H$78>H2,1,0)) -> 0.5 | AAD2: =IF(SUM(ZW2:AAC2)=$K$82,0.5,IF(SUM(ZW2:AAC2)>$K$82,1,0)) -> 0 | AAF2: =IF(B$79=B2,0.5,IF(B$79>B2,1,0)) -> 0 | AAG2: =IF(C$79=C2,0.5,IF(C$79>C2,1,0)) -> 0 | AAH2: =IF(D$79=D2,0.5,IF(D$79>D2,1,0)) -> 0 | AAI2: =IF(E$79=E2,0.5,IF(E$79>E2,1,0)) -> 0 | AAJ2: =IF(F$79=F2,0.5,IF(F$79>F2,1,0)) -> 0.5 | AAK2: =IF(G$79=G2,0.5,IF(G$79>G2,1,0)) -> 0.5 | AAL2: =IF(H$79=H2,0.5,IF(H$79>H2,1,0)) -> 0.5 | AAM2: =IF(SUM(AAF2:AAL2)=$K$82,0.5,IF(SUM(AAF2:AAL2)>$K$82,1,0)) -> 0 | AAO2: =IF(B$80=B2,0.5,IF(B$80>B2,1,0)) -> 0 | AAP2: =IF(C$80=C2,0.5,IF(C$80>C2,1,0)) -> 0 | AAQ2: =IF(D$80=D2,0.5,IF(D$80>D2,1,0)) -> 0 | AAR2: =IF(E$80=E2,0.5,IF(E$80>E2,1,0)) -> 0 | AAS2: =IF(F$80=F2,0.5,IF(F$80>F2,1,0)) -> 0.5 | AAT2: =IF(G$80=G2,0.5,IF(G$80>G2,1,0)) -> 0.5 | AAU2: =IF(H$80=H2,0.5,IF(H$80>H2,1,0)) -> 0.5 | AAV2: =IF(SUM(AAO2:AAU2)=$K$82,0.5,IF(SUM(AAO2:AAU2)>$K$82,1,0)) -> 0 | AAX2: =IF(B$81=B2,0.5,IF(B$81>B2,1,0)) -> 0 | AAY2: =IF(C$81=C2,0.5,IF(C$81>C2,1,0)) -> 0 | AAZ2: =IF(D$81=D2,0.5,IF(D$81>D2,1,0)) -> 0 | ABA2: =IF(E$81=E2,0.5,IF(E$81>E2,1,0)) -> 0 | ABB2: =IF(F$81=F2,0.5,IF(F$81>F2,1,0)) -> 0.5 | ABC2: =IF(G$81=G2,0.5,IF(G$81>G2,1,0)) -> 0.5 | ABD2: =IF(H$81=H2,0.5,IF(H$81>H2,1,0)) -> 0.5 | ABE2: =IF(SUM(AAX2:ABD2)=$K$82,0.5,IF(SUM(AAX2:ABD2)>$K$82,1,0)) -> 0 | ABH2: =IF(B2>0,RANK(B2,$B$2:$B$81),"-") -> 1 | ABI2: =IF(C2>0,RANK(C2,$C$2:$C$81),"-") -> 1 | ABJ2: =IF(D2>0,RANK(D2,$D$2:$D$81),"-") -> 1 | ABK2: =IF(E2>0,RANK(E2,$E$2:$E$81),"-") -> 4 | ABL2: =IF(F2>0,RANK(F2,$F$2:$F$81),"-") -> - | ABM2: =IF(G2>0,RANK(G2,$G$2:$G$81),"-") -> - | ABN2: =IF(H2>0,RANK(H2,$H$2:$H$81),"-") -> - | ABP2: =ABH2 -> 1 | ABQ2: =ABI2 -> 1 | ABR2: =ABJ2 -> 1 | ABS2: =ABK2 -> 4 | ABT2: =ABL2 -> - | ABU2: =ABM2 -> - | ABV2: =ABN2 -> - | ABW2: =IF(I2=((79-$L$82)/2),"-",J2) -> 4 | ABX2: =IF(K2<($L$82+1),K2,"-") -> 1 | ABY2: =IF(B2=0,"-",B2) -> 88 | ABZ2: =IF(C2=0,"-",C2) -> 85 | ACA2: =IF(D2=0,"-",D2) -> 90 | ACB2: =IF(E2=0,"-",E2) -> 81 | ACC2: =IF(F2=0,"-",F2) -> - | ACD2: =IF(G2=0,"-",G2) -> - | ACE2: =IF(H2=0,"-",H2) -> - | ACF2: =IF(M2=0,"-",M2) -> 86 | ACG2: =RANK(M2,$M$2:$M$81) -> 3
